S28921326ABK27GA00011PS000100TWM   0000702000Y
S28921344ABK27GA00011QB000100UWM   0000542800Y
S28921344ABK27GA00011RS000100TWM   0000701800Y
S28921344XBK27GA00011P000100
S28921354XBK27GA00011Q000100
S28921355XBK27GA00011R000100
S28921356ABK27GA00011SS000100TWM   0000702000Y
S28921375ABK27GA00011TB000100UWM   0000542800Y
S28921375XBK27GA00011S000100
S28921375ABK27GA00011US000100TWM   0000701800Y
S28921382AAK27GA000191B000500SPY   0001425400Y
S28921384XBK27GA00011T000100
S28921384XBK27GA00011U000100
S28921386ABK27GA00011VS000100TWM   0000702000Y
S28921385A6K27GA0000BZB002000IMCL  0000349800Y
S28921389X2K27G600007B002000
S28921389X2K27G600009P002000
S28921392X3K27G60000AZ002000
S28921404ABK27GA00011WB000100UWM   0000542800Y
S28921405XBK27GA00011V000100
S28921405ABK27GA00011XS000100TWM   0000701800Y
S28921413X7K27GA00006U002000
S28921413X5K27GA00007F002000
S28921414XBK27GA00011W000100
S28921414XBK27GA00011X000100
S28921416XBK27GA00010X002000
S28921416ABK27GA00011YS000100TWM   0000702000Y
S28921422XCK27GA00004A002000
S28921430XCK27GA000052002000
S28921434X1K27GA0000B2002000
S28921438X1K27GA0000B3002000
S28921439X2K27G600009Y002000
S28921449A7K27GA00006VB002000LPNT  0000207100Y
S28921449X1K27GA0000B4002000
S28921450X2K27G600009Q002000
S28921460X2K27G60000A3002000
S28921460X2K27G600009Z002000
S28921492X2K27G600009S002000
S28921496X2K27G60000A1002000
S28921503A5K27GA00007GS002000FNM   0001431200Y
S28921505X2K27G60000A4002000
S28921517A7K27GA00006WB002000LMT   0000357100Y
S28921531ABK27GA00011ZS002000UTX   0001587900Y
S28921535ABK27GA000120B002000UTX   0000235100Y
S28921549ABK27GA000121S002000UTX   0001587100Y
S28921548ACK27GA000053B002000WYE   0000137700Y
S28921561ACK27GA000054S002000WYE   0000472800Y
S28921585A1K27GA0000B5B002000ABT   0000177800Y
S28921585A1K27GA0000B6B002000AFL   0000216700Y
S28921590A2K27G60000A9B002000BBT   0000106800Y
S28921598AAK27GA000192S002500SPY   0001426100Y
S28921602A1K27GA0000B7S002000AFL   0001576200Y
S28921625A2K27G60000AAB002000BMC   0000365700Y
S28921633X6K27GA0000BQ000500
S28921633A6K27GA0000C0B000500IWM   0000736300Y
S28921636X6K27GA0000C0000500
S28921636A6K27GA0000C0B000500IWM   0000736400Y
S28921643X6K27GA0000C0000500
S28921643A6K27GA0000C0B000500IWM   0000736800Y
S28921646ABK27GA000122B000100UWM   0000542800Y
S28921646XBK27GA00011Y000100
S28921646ABK27GA000123S000100TWM   0000701800Y
S28921653A2K27G60000ABS002000BMC   0000390400Y
S28921653X6K27GA0000C0000500
S28921653A6K27GA0000C0B000500IWM   0000736400Y
S28921656XBK27GA000122000100
S28921656XBK27GA000123000100
S28921658ABK27GA000124S000100TWM   0000702000Y
S28921657X6K27GA0000C0000500
S28921657A6K27GA0000C0B000500IWM   0000736800Y
S28921660ABK27GA000125B000100UWM   0000542800Y
S28921661ABK27GA000126S000100TWM   0000701800Y
S28921661XBK27GA000124000100
S28921663X6K27GA0000C0000500
S28921663A6K27GA0000C0B000500IWM   0000736400Y
S28921666XBK27GA000125000100
S28921666XBK27GA000126000100
S28921668ABK27GA000127S000100TWM   0000702000Y
S28921671X6K27GA0000C0000500
S28921671A6K27GA0000C0B000500IWM   0000736800Y
S28921673X6K27GA0000C0000500
S28921673A6K27GA0000C0B000500IWM   0000736400Y
S28921674ABK27GA000128B000100UWM   0000542800Y
S28921674XBK27GA000127000100
S28921675ABK27GA000129S000100TWM   0000701800Y
S28921676A2K27G60000ACB002000BNI   0001062500Y
S28921676XBK27GA000128000100
S28921676XBK27GA000129000100
S28921678ABK27GA00012AS000100TWM   0000702000Y
S28921683X6K27GA0000C0000500
S28921683A6K27GA0000C0B000500IWM   0000736800Y
S28921686ABK27GA00012BB000100UWM   0000542800Y
S28921686ABK27GA00012CS000100TWM   0000701800Y
S28921686XBK27GA00012A000100
S28921694A2K27G60000ADS002000BNI   0001128600Y
S28921693X6K27GA0000C0000500
S28921693A6K27GA0000C0B000500IWM   0000736400Y
S28921696XBK27GA00012B000100
S28921696XBK27GA00012C000100
S28921698ABK27GA00012DS000100TWM   0000702000Y
S28921697X6K27GA0000C0000500
S28921697A6K27GA0000C0B000500IWM   0000736800Y
S28921700ABK27GA00012EB000100UWM   0000542800Y
S28921700XBK27GA00012D000100
S28921701ABK27GA00012FS000100TWM   0000701800Y
S28921703X6K27GA0000C0000500
S28921703A6K27GA0000C0B000500IWM   0000736400Y
S28921706XBK27GA00012E000100
S28921706XBK27GA00012F000100
S28921708ABK27GA00012GS000100TWM   0000702000Y
S28921706A6K27GA0000C1B000100IWM   0000736300Y
S28921707X6K27GA0000C1000100
S28921707X6K27GA0000C0000500
S28921707A6K27GA0000C0B000500IWM   0000736800Y
S28921710ABK27GA00012HB000100UWM   0000542800Y
S28921710XBK27GA00012G000100
S28921710ABK27GA00012IS000100TWM   0000701800Y
S28921713X6K27GA0000C0000500
S28921713A6K27GA0000C0B000500IWM   0000736400Y
S28921715A2K27G60000AEB002000BP    0000739200Y
S28921716XBK27GA00012H000100
S28921716XBK27GA00012I000100
S28921718ABK27GA00012JS000100TWM   0000702000Y
S28921721X6K27GA0000C0000500
S28921721A6K27GA0000C0B000500IWM   0000736800Y
S28921722X6K27GA0000C0000500
S28921722A6K27GA0000C0B000500IWM   0000736400Y
S28921724ABK27GA00012KB000100UWM   0000542800Y
S28921724XBK27GA00012J000100
S28921724ABK27GA00012LS000100TWM   0000701800Y
S28921726XBK27GA00012K000100
S28921726XBK27GA00012L000100
S28921728ABK27GA00012MS000100TWM   0000702000Y
S28921734X6K27GA0000C0000500
S28921734A6K27GA0000C0B000500IWM   0000736800Y
S28921743X6K27GA0000C0000500
S28921743A6K27GA0000C0B000500IWM   0000736400Y
S28921753X6K27GA0000C0000500
S28921753A6K27GA0000C0B000500IWM   0000736800Y
S28921763X6K27GA0000C0000500
S28921763A6K27GA0000C0B000500IWM   0000736400Y
S28921773X6K27GA0000C0000500
S28921773A6K27GA0000C0B000500IWM   0000736800Y
S28921783X6K27GA0000C0000500
S28921783A6K27GA0000C0B000500IWM   0000736400Y
S28921793X6K27GA0000C0000500
S28921793A6K27GA0000C0B000500IWM   0000736800Y
S28921803X6K27GA0000C0000500
S28921803A6K27GA0000C0B000500IWM   0000736400Y
S28921823X6K27GA0000C0000500
S28921823A6K27GA0000C0B000500IWM   0000736800Y
S28921833X6K27GA0000C0000500
S28921833A6K27GA0000C0B000500IWM   0000736400Y
S28921843X6K27GA0000C0000500
S28921843A6K27GA0000C0B000500IWM   0000736800Y
S28921853X6K27GA0000C0000500
S28921853A6K27GA0000C0B000500IWM   0000736400Y
S28921863X6K27GA0000C0000500
S28921863A6K27GA0000C0B000500IWM   0000736800Y
S28921873X6K27GA0000C0000500
S28921873A6K27GA0000C0B000500IWM   0000736400Y
S28921883X6K27GA0000C0000500
S28921883A6K27GA0000C0B000500IWM   0000736800Y
S28921893X6K27GA0000C0000500
S28921893A6K27GA0000C0B000500IWM   0000736400Y
S28921903X6K27GA0000C0000500
S28921903A6K27GA0000C0B000500IWM   0000736800Y
S28921913X6K27GA0000C0000500
S28921913A6K27GA0000C0B000500IWM   0000736400Y
S28921923X6K27GA0000C0000500
S28921923A6K27GA0000C0B000500IWM   0000736800Y
S28921933X6K27GA0000C0000500
S28921933A6K27GA0000C0B000500IWM   0000736400Y
S28921943X6K27GA0000C0000500
S28921943A6K27GA0000C0B000500IWM   0000736800Y
S28921953X6K27GA0000C0000500
S28921953A6K27GA0000C0B000500IWM   0000736400Y
S28921963X6K27GA0000C0000500
S28921963A6K27GA0000C0B000500IWM   0000736800Y
S28921973X6K27GA0000C0000500
S28921973A6K27GA0000C0B000500IWM   0000736400Y
S28921983X6K27GA0000C0000500
S28921983A6K27GA0000C0B000500IWM   0000736800Y
S28921993X6K27GA0000C0000500
S28921993A6K27GA0000C0B000500IWM   0000736400Y
S28922003X6K27GA0000C0000500
S28922003A6K27GA0000C0B000500IWM   0000736800Y
S28922013X6K27GA0000C0000500
S28922013A6K27GA0000C0B000500IWM   0000736400Y
S28922023X6K27GA0000C0000500
S28922023A6K27GA0000C0B000500IWM   0000736800Y
S28922033X6K27GA0000C0000500
S28922033A6K27GA0000C0B000500IWM   0000736400Y
S28922035XAK27GA000191000500
S28922043X6K27GA0000C0000500
S28922043A6K27GA0000C0B000500IWM   0000736800Y
S28922055X6K27GA0000C0000500
S28922055A6K27GA0000C0B000500IWM   0000736400Y
S28922063X6K27GA0000C0000500
S28922063A6K27GA0000C0B000500IWM   0000736800Y
S28922073X6K27GA0000C0000500
S28922073A6K27GA0000C0B000500IWM   0000736400Y
S28922083X6K27GA0000C0000500
S28922083A6K27GA0000C0B000500IWM   0000736800Y
S28922093X6K27GA0000C0000500
S28922093A6K27GA0000C0B000500IWM   0000736400Y
S28922341X1K27GA00009R002000
S28922362XAK27GA000189002000
S28922378X7K27GA00006W002000
S28922381X9K27G60000RI002000
S28922405XBK27GA0000YW002000
S28922415A3K27G60000B4B002000CTSH  0000096200Y
S28922414ACK27GA000055B000737ZVZZT 0000000100Y
S28922415XCK27GA000055000737
S28922415ACK27GA000055B000737ZVZZT 0000000100Y
S28922416XBK27GA000120002000
S28922415XCK27GA000055000737
S28922433XBK27GA000121002000
S28922443X6K27GA0000C0000500
S28922443A6K27GA0000C2B000500IWM   0000736300Y
S28922453X6K27GA0000C2000500
S28922453A6K27GA0000C2B000500IWM   0000736400Y
S28922456X1K27GA0000B5002000
S28922463X6K27GA0000C2000500
S28922463A6K27GA0000C2B000500IWM   0000736800Y
S28922466X2K27G6000098002000
S28922466ABK27GA00012NB000100UWM   0000542800Y
S28922466XBK27GA00012M000100
S28922466ABK27GA00012OS000100TWM   0000701800Y
S28922473X6K27GA0000C2000500
S28922473A6K27GA0000C2B000500IWM   0000736400Y
S28922476XBK27GA00012N000100
S28922476XBK27GA00012O000100
S28922476A6K27GA0000C3B000100IWM   0000736300Y
S28922478ABK27GA00012PS000100TWM   0000702000Y
S28922476X6K27GA0000C3000100
S28922477X6K27GA0000C2000500
S28922477A6K27GA0000C2B000500IWM   0000736800Y
S28922480ABK27GA00012QB000100UWM   0000542800Y
S28922480XBK27GA00012P000100
S28922480ABK27GA00012RS000100TWM   0000701800Y
S28922483X6K27GA0000C2000500
S28922483A6K27GA0000C2B000500IWM   0000736400Y
S28922486XBK27GA00012Q000100
S28922486XBK27GA00012R000100
S28922488A2K27G60000AFB002000BMY   0000066400Y
S28922488ABK27GA00012SS000100TWM   0000702000Y
S28922493X6K27GA0000C2000500
S28922493A6K27GA0000C2B000500IWM   0000736800Y
S28922496ABK27GA00012TB000100UWM   0000542800Y
S28922496ABK27GA00012US000100TWM   0000701800Y
S28922496XBK27GA00012S000100
S28922500A5K27GA00007HS002000FNM   0001425600Y
S28922503X6K27GA0000C2000500
S28922503A6K27GA0000C2B000500IWM   0000736400Y
S28922506XBK27GA00012T000100
S28922506XBK27GA00012U000100
S28922508ABK27GA00012VS000100TWM   0000702000Y
S28922507X6K27GA0000C2000500
S28922507A6K27GA0000C2B000500IWM   0000736800Y
S28922510ABK27GA00012WB000100UWM   0000542800Y
S28922510ABK27GA00012XS000100TWM   0000701800Y
S28922511XBK27GA00012V000100
S28922511X5K27GA00007G002000
S28922512A2K27G60000AGB002000BRL   0000375200Y
S28922513X6K27GA0000C2000500
S28922513A6K27GA0000C2B000500IWM   0000736400Y
S28922516XBK27GA00012W000100
S28922516XBK27GA00012X000100
S28922516A6K27GA0000C4B000100IWM   0000736300Y
S28922518ABK27GA00012YS000100TWM   0000702000Y
S28922516X6K27GA0000C4000100
S28922517X6K27GA0000C2000500
S28922517A6K27GA0000C2B000500IWM   0000736800Y
S28922520ABK27GA00012ZB000100UWM   0000542800Y
S28922520XBK27GA00012Y000100
S28922520ABK27GA000130S000100TWM   0000701800Y
S28922523X6K27GA0000C2000500
S28922523A6K27GA0000C2B000500IWM   0000736400Y
S28922525XBK27GA0000YX002000
S28922526XBK27GA00012Z000100
S28922526XBK27GA000130000100
S28922526A6K27GA0000C5B000100IWM   0000736300Y
S28922528ABK27GA000131S000100TWM   0000702000Y
S28922526X6K27GA0000C5000100
S28922527X6K27GA0000C2000500
S28922527A6K27GA0000C2B000500IWM   0000736800Y
S28922530ABK27GA000132B000100UWM   0000542800Y
S28922530XBK27GA000131000100
S28922530ABK27GA000133S000100TWM   0000701800Y
S28922532XBK27GA00011Z002000
S28922533X6K27GA0000C2000500
S28922533A6K27GA0000C2B000500IWM   0000736400Y
S28922536XBK27GA000132000100
S28922536XBK27GA000133000100
S28922535ACK27GA000056B002000WYE   0000139700Y
S28922536A6K27GA0000C6B000100IWM   0000736300Y
S28922538ABK27GA000134S000100TWM   0000702000Y
S28922536X6K27GA0000C6000100
S28922537X6K27GA0000C2000500
S28922537A6K27GA0000C2B000500IWM   0000736800Y
S28922540ABK27GA000135B000100UWM   0000542800Y
S28922540XBK27GA000134000100
S28922540ABK27GA000136S000100TWM   0000701800Y
S28922542XCK27GA000053002000
S28922543X6K27GA0000C2000500
S28922543A6K27GA0000C2B000500IWM   0000736400Y
S28922546XBK27GA000135000100
S28922546XBK27GA000136000100
S28922548ABK27GA000137S000100TWM   0000702000Y
S28922548A1K27GA0000B8B002000AFL   0000219400Y
S28922551X6K27GA0000C2000500
S28922551A6K27GA0000C2B000500IWM   0000736800Y
S28922553X6K27GA0000C2000500
S28922553A6K27GA0000C2B000500IWM   0000736400Y
S28922563X6K27GA0000C2000500
S28922563A6K27GA0000C2B000500IWM   0000736800Y
S28922564X1K27GA0000B6002000
S28922572A1K27GA0000B9S002000AFL   0001571800Y
S28922573X6K27GA0000C2000500
S28922573A6K27GA0000C2B000500IWM   0000736400Y
S28922578X1K27GA0000B7002000
S28922588X2K27G6000099002000
S28922592X6K27GA0000C2000500
S28922592A6K27GA0000C2B000500IWM   0000736800Y
S28922597A2K27G60000AHS002000BA    0001628100Y
S28922603X6K27GA0000C2000500
S28922603A6K27GA0000C2B000500IWM   0000736400Y
S28922613X6K27GA0000C2000500
S28922613A6K27GA0000C2B000500IWM   0000736800Y
S28922616A2K27G60000AIS002000BBT   0001445300Y
S28922623X6K27GA0000C2000500
S28922623A6K27GA0000C2B000500IWM   0000736400Y
S28922633X6K27GA0000C2000500
S28922633A6K27GA0000C2B000500IWM   0000736800Y
S28922643X6K27GA0000C2000500
S28922643A6K27GA0000C2B000500IWM   0000736400Y
S28922647A7K27GA00006XB002000LMT   0000359300Y
S28922648A2K27G60000AJS002000BP    0000759500Y
S28922653X6K27GA0000C2000500
S28922653A6K27GA0000C2B000500IWM   0000736800Y
S28922657ABK27GA000138B002000UTX   0000236300Y
S28922663X6K27GA0000C2000500
S28922663A6K27GA0000C2B000500IWM   0000736400Y
S28922667A2K27G60000AKB002000BR    0000191600Y
S28922666ACK27GA000057B002000WMT   0000540700Y
S28922674A1K27GA0000BAB002000ABT   0000178400Y
S28922673X6K27GA0000C2000500
S28922673A6K27GA0000C2B000500IWM   0000736800Y
S28922683X6K27GA0000C2000500
S28922683A6K27GA0000C2B000500IWM   0000736400Y
S28922685A2K27G60000ALS002000BA    0001628900Y
S28922685A2K27G60000AMS002000BR    0000247400Y
S28922693A2K27G60000ANB002000BBT   0000106900Y
S28922693XAK27GA00018W003000
S28922693XAK27GA00018X003000
S28922693X6K27GA0000C2000500
S28922693A6K27GA0000C2B000500IWM   0000736800Y
S28922698AAK27GA000193S003000SPY   0001426600Y
S28922698AAK27GA000194S003000SPY   0001426600Y
S28922701A2K27G60000AOB002000BSX   0000119500Y
S28922703X6K27GA0000C2000500
S28922703A6K27GA0000C2B000500IWM   0000736400Y
S28922712A2K27G60000APS002000BBT   0001446100Y
S28922713X6K27GA0000C2000500
S28922713A6K27GA0000C2B000500IWM   0000736800Y
S28922722X6K27GA0000C2000500
S28922722A6K27GA0000C2B000500IWM   0000736400Y
S28922733X6K27GA0000C2000500
S28922733A6K27GA0000C2B000500IWM   0000736800Y
S28922737A2K27G60000AQB002000CAG   0000070200Y
S28922743A2K27G60000ARS002000CAG   0001410100Y
S28922742X6K27GA0000C2000500
S28922742A6K27GA0000C2B000500IWM   0000736400Y
S28922753A3K27G60000B5S002000CCL   0000402200Y
S28922752X6K27GA0000C2000500
S28922752A6K27GA0000C2B000500IWM   0000736800Y
S28922762A3K27G60000B6B002000CCU   0000336200Y
S28922763X6K27GA0000C2000500
S28922763A6K27GA0000C2B000500IWM   0000736400Y
S28922771A3K27G60000B7B002000CFC   0000037300Y
S28922773X6K27GA0000C2000500
S28922773A6K27GA0000C2B000500IWM   0000736800Y
S28922783X6K27GA0000C2000500
S28922783A6K27GA0000C2B000500IWM   0000736400Y
S28922793X6K27GA0000C2000500
S28922793A6K27GA0000C2B000500IWM   0000736800Y
S28922803X6K27GA0000C2000500
S28922803A6K27GA0000C2B000500IWM   0000736400Y
S28922813X6K27GA0000C2000500
S28922813A6K27GA0000C2B000500IWM   0000736800Y
S28922823X6K27GA0000C2000500
S28922823A6K27GA0000C2B000500IWM   0000736400Y
S28922842X6K27GA0000C2000500
S28922842A6K27GA0000C2B000500IWM   0000736800Y
S28922853X6K27GA0000C2000500
S28922853A6K27GA0000C2B000500IWM   0000736400Y
S28922863X6K27GA0000C2000500
S28922863A6K27GA0000C2B000500IWM   0000736800Y
S28922873X6K27GA0000C2000500
S28922873A6K27GA0000C2B000500IWM   0000736400Y
S28922883X6K27GA0000C2000500
S28922883A6K27GA0000C2B000500IWM   0000736800Y
S28922893X6K27GA0000C2000500
S28922893A6K27GA0000C2B000500IWM   0000736400Y
S28922903X6K27GA0000C2000500
S28922903A6K27GA0000C2B000500IWM   0000736800Y
S28922913X6K27GA0000C2000500
S28922913A6K27GA0000C2B000500IWM   0000736400Y
S28923232XAK27GA000193003000
S28923232X4K27GA0000IV000200
S28923232XAK27GA00015Y001000
S28923232XAK27GA000194003000
S28923232XAK27GA0000O2000500
S28923232AAK27GA0000O2S000500SPY   0001425900Y
S28923232XAK27GA0000FE000500
S28923232AAK27GA0000FEB000500SPY   0001425300Y
S28923233XAK27GA00018O003000
S28923233AAK27GA000195S001000SPY   0001425900Y
S28923233AAK27GA000196S003000SPY   0001426000Y
S28923233XAK27GA00018P003000
S28923233AAK27GA000197S003000SPY   0001426000Y
S28923234AAK27GA000198B000500SPY   0001425400Y
S28923235AAK27GA000199B003000SPY   0001425000Y
S28923235AAK27GA00019AB003000SPY   0001425000Y
S28923263X6K27GA0000C2000500
S28923263A6K27GA0000C7B000500IWM   0000736300Y
S28923272X6K27GA0000C7000500
S28923272A6K27GA0000C7B000500IWM   0000736400Y
S28923282X6K27GA0000C7000500
S28923282A6K27GA0000C7B000500IWM   0000736800Y
S28923286ABK27GA000139B000100UWM   0000542800Y
S28923286ABK27GA00013AS000100TWM   0000701800Y
S28923286XBK27GA000137000100
S28923293X6K27GA0000C7000500
S28923293A6K27GA0000C7B000500IWM   0000736400Y
S28923296XBK27GA000139000100
S28923296XBK27GA00013A000100
S28923298ABK27GA00013BS000100TWM   0000702000Y
S28923297X6K27GA0000C7000500
S28923297A6K27GA0000C7B000500IWM   0000736800Y
S28923300ABK27GA00013CB000100UWM   0000542800Y
S28923301ABK27GA00013DS000100TWM   0000701800Y
S28923301XBK27GA00013B000100
S28923303X6K27GA0000C7000500
S28923303A6K27GA0000C7B000500IWM   0000736400Y
S28923306XBK27GA00013C000100
S28923306XBK27GA00013D000100
S28923306A6K27GA0000C8B000100IWM   0000736300Y
S28923308ABK27GA00013ES000100TWM   0000702000Y
S28923306X6K27GA0000C8000100
S28923307X6K27GA0000C7000500
S28923307A6K27GA0000C7B000500IWM   0000736800Y
S28923310ABK27GA00013FB000100UWM   0000542800Y
S28923310XBK27GA00013E000100
S28923310ABK27GA00013GS000100TWM   0000701800Y
S28923313X6K27GA0000C7000500
S28923313A6K27GA0000C7B000500IWM   0000736400Y
S28923316XBK27GA00013G000100
S28923316XBK27GA00013F000100
S28923318ABK27GA00013HS000100TWM   0000702000Y
S28923323X6K27GA0000C7000500
S28923323A6K27GA0000C7B000500IWM   0000736800Y
S28923326ABK27GA00013IB000100UWM   0000542800Y
S28923326ABK27GA00013JS000100TWM   0000701800Y
S28923326XBK27GA00013H000100
S28923333A4K27GA0000IYS000200DIA   0001299000Y
S28923332X6K27GA0000C7000500
S28923332A6K27GA0000C7B000500IWM   0000736400Y
S28923336XBK27GA00013I000100
S28923336XBK27GA00013J000100
S28923336A6K27GA0000C9B000100IWM   0000736300Y
S28923338ABK27GA00013KS000100TWM   0000702000Y
S28923336X6K27GA0000C9000100
S28923337X6K27GA0000C7000500
S28923337A6K27GA0000C7B000500IWM   0000736800Y
S28923340ABK27GA00013LB000100UWM   0000542800Y
S28923340ABK27GA00013MS000100TWM   0000701800Y
S28923340XBK27GA00013K000100
S28923341X6K27GA0000C7000500
S28923341A6K27GA0000C7B000500IWM   0000736400Y
S28923342A6K27GA0000CAS002000IWM   0000737200Y
S28923344XBK27GA00013L000100
S28923344XBK27GA00013M000100
S28923346ABK27GA00013NS000100TWM   0000702000Y
S28923345A6K27GA0000CBS002000IWM   0000737300Y
S28923401X5K27GA00007H002000
S28923402X2K27G600007C002000
S28923410X5K27GA00006Z002000
S28923410XAK27GA00018C002000
S28923416X6K27GA0000AY002000
S28923417XAK27GA000179002000
S28923420X6K27GA0000AZ002000
S28923423X7K27GA00005P002000
S28923436X7K27GA00006X002000
S28923441XBK27GA000138002000
S28923441A1K27GA0000BBS002000AMGN  0000480000Y
S28923453XCK27GA000056002000
S28923460X1K27GA0000BA002000
S28923474X1K27GA0000B8002000
S28923479X2K27G60000AL002000
S28923495X2K27G60000AP002000
S28923503AAK27GA00019BB002000SHLD  0000772200Y
S28923512X1K27GA0000B9002000
S28923537X2K27G60000AH002000
S28923549A9K27G60000S4B002000PDLI  0000033400Y
S28923558X2K27G60000A9002000
S28923567X2K27G60000AR002000
S28923577X2K27G60000AI002000
S28923578A5K27GA00007IS002000FNM   0001421700Y
S28923590A7K27GA00006YB002000LMT   0000363100Y
S28923605ABK27GA00013OS002000TGT   0000621700Y
S28923609ABK27GA00013PS002000TGT   0000620900Y
S28923616ABK27GA00013QS002000UTX   0001581000Y
S28923625ABK27GA00013RB002000UTX   0000239100Y
S28923632ACK27GA000058B002000WYE   0000140100Y
S28923645ABK27GA00013SS002000UTX   0001580200Y
S28923666A1K27GA0000BCB002000AFL   0000220500Y
S28923667A1K27GA0000BDB002000ABT   0000180800Y
S28923685A1K27GA0000BES002000AFL   0001569100Y
S28923698A2K27G60000ASB002000AXP   0000417400Y
S28923702A2K27G60000ATB002000AXP   0000418200Y
S28923746A2K27G60000AUS002000BSX   0000152100Y
S28923768A2K27G60000AVB002000CA    0000228700Y
S28923771A3K27G60000B8S002000CFC   0000059600Y
S28923807A2K27G60000AWS002000CA    0000253200Y
S28923984XAK27GA0000O2000500
S28923984AAK27GA0000O2S000500SPY   0001426300Y
S28924156AAK27GA00019CS001000SPY   0001426100Y
S28924156XAK27GA0000FE000500
S28924156AAK27GA0000FEB000500SPY   0001425700Y
S28924161A4K27GA0000IZS000100DXD   0000500000Y
S28924161A3K27G60000B9B000100DDM   0000801300Y
S28924163AAK27GA00019DS000500SPY   0001426000Y
S28924163AAK27GA00019ES002500SPY   0001426000Y
S28924164XAK27GA00018T005000
S28924164XAK27GA000192002500
S28924164AAK27GA00019FS005000SPY   0001426200Y
S28924183XAK27GA000190001000
S28924183AAK27GA00019GB001000SPY   0001425500Y
S28924196X4K27GA0000DX000200
S28924196A4K27GA0000DXB000200DIA   0001298900Y
S28924196X4K27GA0000IY000200
S28924197XAK27GA000199003000
S28924197XAK27GA00019C001000
S28924197XAK27GA000196003000
S28924197XAK27GA000195001000
S28924197XAK27GA000197003000
S28924197XAK27GA00019A003000
S28924197AAK27GA00019HB003000SPY   0001425700Y
S28924197AAK27GA00019IS001000SPY   0001426200Y
S28924197AAK27GA00019JB003000SPY   0001425600Y
S28924198XAK27GA00019G001000
S28924198AAK27GA00019KB001000SPY   0001425600Y
S28924199AAK27GA00019LS001000SPY   0001426200Y
S28924199XAK27GA00019E002500
S28924199AAK27GA00019MS003000SPY   0001426600Y
S28924199AAK27GA00019NS001000SPY   0001426300Y
S28924200AAK27GA00019OS003000SPY   0001426600Y
S28924200A4K27GA0000J0S000200DIA   0001299300Y
S28924200XAK27GA00019D000500
S28924208X9K27G60000G3002000
S28924208A9K27G60000G3S002000QQQQ  0000496400Y
S28924209X6K27GA0000C7000500
S28924209A6K27GA0000C7B000500IWM   0000736800Y
S28924210X6K27GA0000CA002000
S28924212ABK27GA00013TB000100UWM   0000542800Y
S28924212XBK27GA00013N000100
S28924212ABK27GA00013US000100TWM   0000701800Y
S28924212XBK27GA00013T000100
S28924212XBK27GA00013U000100
S28924214ABK27GA00013VB000100UWM   0000542800Y
S28924213A6K27GA0000CCB000100IWM   0000736300Y
S28924214ABK27GA00013WS000100TWM   0000701800Y
S28924213X6K27GA0000CC000100
S28924213X6K27GA0000C7000500
S28924213A6K27GA0000C7B000500IWM   0000736400Y
S28924217X9K27G60000G3002000
S28924217A9K27G60000G3S002000QQQQ  0000496000Y
S28924217XAK27GA00019H003000
S28924217XAK27GA00019N001000
S28924217X4K27GA0000DX000200
S28924217A4K27GA0000DXB000200DIA   0001298600Y
S28924216X6K27GA0000C7000500
S28924216A6K27GA0000C7B000500IWM   0000736800Y
S28924217AAK27GA00019PS001000SPY   0001425900Y
S28924217XAK27GA00019K001000
S28924218XAK27GA00019L001000
S28924218XAK27GA00019O003000
S28924219X4K27GA0000IZ000100
S28924219X3K27G60000B9000100
S28924219XAK27GA00019M003000
S28924219AAK27GA00019QB003000SPY   0001425600Y
S28924219AAK27GA00019RB001000SPY   0001425500Y
S28924219AAK27GA00019SS003000SPY   0001426000Y
S28924220X9K27G60000F8003200
S28924220A9K27G60000F8S003200QQQQ  0000496500Y
S28924220AAK27GA00019TS003000SPY   0001426000Y
S28924223X6K27GA0000C7000500
S28924223A6K27GA0000C7B000500IWM   0000736400Y
S28924225X4K27GA0000J0000200
S28924226A4K27GA0000J1S000047DIA   0001299400Y
S28924227X6K27GA0000C7000500
S28924227A6K27GA0000C7B000500IWM   0000736800Y
S28924229X4K27GA0000J1000047
S28924234A4K27GA0000J2S000200DIA   0001299300Y
S28924234X6K27GA0000C7000500
S28924234A6K27GA0000C7B000500IWM   0000736400Y
S28924239X4K27GA0000DX000200
S28924239A4K27GA0000DXB000200DIA   0001298900Y
S28924241XAK27GA00019Q003000
S28924241XAK27GA00019J003000
S28924241A4K27GA0000J3S000100DXD   0000500000Y
S28924242A3K27G60000BAB000100DDM   0000801300Y
S28924244AAK27GA00019UB003000SPY   0001425000Y
S28924244AAK27GA00019VB003000SPY   0001425000Y
S28924243X6K27GA0000C7000500
S28924243A6K27GA0000C7B000500IWM   0000736800Y
S28924245XBK27GA00013V000100
S28924245XBK27GA00013W000100
S28924247ABK27GA00013XS000100TWM   0000701800Y
S28924247ABK27GA00013YB000100UWM   0000542800Y
S28924247X6K27GA0000C7000500
S28924247A6K27GA0000C7B000500IWM   0000736400Y
S28924249XAK27GA00019R001000
S28924254X9K27G60000F8003200
S28924254A9K27G60000F8S003200QQQQ  0000496000Y
S28924253X6K27GA0000C7000500
S28924253A6K27GA0000C7B000500IWM   0000736800Y
S28924255XBK27GA00013Y000100
S28924255XBK27GA00013X000100
S28924257ABK27GA00013ZB000100UWM   0000542800Y
S28924257ABK27GA000140S000100TWM   0000701800Y
S28924257X6K27GA0000C7000500
S28924257A6K27GA0000C7B000500IWM   0000736400Y
S28924259X6K27GA0000C7000500
S28924259A6K27GA0000C7B000500IWM   0000736800Y
S28924261XBK27GA00013Z000100
S28924261XBK27GA000140000100
S28924263ABK27GA000141B000100UWM   0000542800Y
S28924261A6K27GA0000CDB000100IWM   0000736300Y
S28924263ABK27GA000142S000100TWM   0000701800Y
S28924261X6K27GA0000CD000100
S28924262X6K27GA0000C7000500
S28924262A6K27GA0000C7B000500IWM   0000736400Y
S28924265X6K27GA0000C7000500
S28924265A6K27GA0000C7B000500IWM   0000736800Y
S28924267X6K27GA0000CB002000
S28924269X6K27GA0000C7000500
S28924269A6K27GA0000C7B000500IWM   0000736400Y
S28924274XBK27GA000141000100
S28924274XBK27GA000142000100
S28924273X6K27GA0000C7000500
S28924273A6K27GA0000C7B000500IWM   0000736800Y
S28924275AAK27GA00019WB001000SPY   0001425500Y
S28924276ABK27GA000143S000100TWM   0000702000Y
S28924284ABK27GA000144B000100UWM   0000542800Y
S28924284ABK27GA000145S000100TWM   0000701800Y
S28924284XBK27GA000143000100
S28924283X6K27GA0000C7000500
S28924283A6K27GA0000C7B000500IWM   0000736400Y
S28924287A6K27GA0000CES002000IWM   0000737300Y
S28924294XBK27GA000144000100
S28924295XBK27GA000145000100
S28924293X6K27GA0000C7000500
S28924293A6K27GA0000C7B000500IWM   0000736800Y
S28924295A6K27GA0000CFB000100IWM   0000736300Y
S28924295X6K27GA0000CF000100
S28924296ABK27GA000146S000100TWM   0000702000Y
S28924296X6K27GA0000C7000500
S28924296A6K27GA0000C7B000500IWM   0000736400Y
S28924304ABK27GA000147B000100UWM   0000542800Y
S28924304XBK27GA000146000100
S28924304XBK27GA000147000100
S28924304ABK27GA000148S000100TWM   0000701800Y
S28924304XBK27GA000148000100
S28924303X6K27GA0000C7000500
S28924303A6K27GA0000C7B000500IWM   0000736800Y
S28924306ABK27GA000149S000100TWM   0000702000Y
S28924311X6K27GA0000C7000500
S28924311A6K27GA0000C7B000500IWM   0000736400Y
S28924314ABK27GA00014AB000100UWM   0000542800Y
S28924314ABK27GA00014BS000100TWM   0000701800Y
S28924314XBK27GA000149000100
S28924313X6K27GA0000C7000500
S28924313A6K27GA0000C7B000500IWM   0000736800Y
S28924324XBK27GA00014A000100
S28924324XBK27GA00014B000100
S28924323X6K27GA0000C7000500
S28924323A6K27GA0000C7B000500IWM   0000736400Y
S28924326ABK27GA00014CS000100TWM   0000702000Y
S28924334ABK27GA00014DB000100UWM   0000542800Y
S28924334ABK27GA00014ES000100TWM   0000701800Y
S28924334XBK27GA00014C000100
S28924333X6K27GA0000C7000500
S28924333A6K27GA0000C7B000500IWM   0000736800Y
S28924344XBK27GA00014D000100
S28924344XBK27GA00014E000100
S28924343X6K27GA0000C7000500
S28924343A6K27GA0000C7B000500IWM   0000736400Y
S28924346ABK27GA00014FS000100TWM   0000702000Y
S28924353X6K27GA0000C7000500
S28924353A6K27GA0000C7B000500IWM   0000736800Y
S28924356X2K27G60000AF002000
S28924363X6K27GA0000C7000500
S28924363A6K27GA0000C7B000500IWM   0000736400Y
S28924373X6K27GA0000C7000500
S28924373A6K27GA0000C7B000500IWM   0000736800Y
S28924383X6K27GA0000C7000500
S28924383A6K27GA0000C7B000500IWM   0000736400Y
S28924392AAK27GA00019XB002000SPLS  0000068700Y
S28924393X5K27GA00007I002000
S28924393X6K27GA0000C7000500
S28924393A6K27GA0000C7B000500IWM   0000736800Y
S28924403X6K27GA0000C7000500
S28924403A6K27GA0000C7B000500IWM   0000736400Y
S28924410XBK27GA0000W6002000
S28924413A5K27GA00007JS002000FNM   0001416100Y
S28924413X6K27GA0000C7000500
S28924413A6K27GA0000C7B000500IWM   0000736800Y
S28924415XBK27GA00013Q002000
S28924421XCK27GA000058002000
S28924423X6K27GA0000C7000500
S28924423A6K27GA0000C7B000500IWM   0000736400Y
S28924428AAK27GA00019YB002000SNDK  0000241000Y
S28924430X1K27GA0000BC002000
S28924434X1K27GA0000BE002000
S28924433X6K27GA0000C7000500
S28924433A6K27GA0000C7B000500IWM   0000736800Y
S28924443X6K27GA0000C7000500
S28924443A6K27GA0000C7B000500IWM   0000736400Y
S28924451A5K27GA00007KB002000GM    0000180200Y
S28924453X2K27G60000AN002000
S28924453X6K27GA0000C7000500
S28924453A6K27GA0000C7B000500IWM   0000736800Y
S28924463X6K27GA0000C7000500
S28924463A6K27GA0000C7B000500IWM   0000736400Y
S28924465AAK27GA00019ZS000500SPY   0001426000Y
S28924473X6K27GA0000C7000500
S28924473A6K27GA0000C7B000500IWM   0000736800Y
S28924483X6K27GA0000C7000500
S28924483A6K27GA0000C7B000500IWM   0000736400Y
S28924486X2K27G60000AQ002000
S28924492X7K27GA00006Y002000
S28924493X6K27GA0000C7000500
S28924493A6K27GA0000C7B000500IWM   0000736800Y
S28924497A2K27G60000AXS002000BRL   0000423800Y
S28924503XBK27GA00013R002000
S28924503X6K27GA0000C7000500
S28924503A6K27GA0000C7B000500IWM   0000736400Y
S28924513XBK27GA00013S002000
S28924519A6K27GA0000CGB002000JNJ   0000643000Y
S28924525ACK27GA000059B002000WYE   0000142100Y
S28924526A6K27GA0000CHS002000JNJ   0000689700Y
S28924534X1K27GA0000BD002000
S28924541A7K27GA00006ZB002000KSS   0000457800Y
S28924548A1K27GA0000BFB002000AFL   0000223100Y
S28924550A7K27GA000070B002000LMT   0000365300Y
S28924560ABK27GA00014GB002000UTX   0000240300Y
S28924561A1K27GA0000BGS002000AFL   0001564700Y
S28924574A1K27GA0000BHB002000ABT   0000181500Y
S28924586A2K27G60000AYS002000BA    0001621900Y
S28924590A2K27G60000AZS002000BA    0001622700Y
S28924600A2K27G60000B0B002000BBT   0000109600Y
S28924607A2K27G60000B1S002000BBT   0001436900Y
S28924620A2K27G60000B2S002000BBT   0001436100Y
S28924646AAK27GA0001A0S002500SPY   0001426000Y
S28924656A2K27G60000B3B002000CAG   0000072300Y
S28924680A2K27G60000B4S002000CAG   0001399600Y
S28924689A2K27G60000B5S002000CAG   0001400400Y
S28924702A2K27G60000B6B002000CAH   0000544300Y
S28925093XAK27GA00019V003000
S28925093X4K27GA0000DX000200
S28925093A4K27GA0000DXB000200DIA   0001298600Y
S28925093XAK27GA00019U003000
S28925093XAK27GA00019I001000
S28925093AAK27GA0001A1B003000SPY   0001425600Y
S28925093AAK27GA0001A2B003000SPY   0001425600Y
S28925095X4K27GA0000J3000100
S28925095X3K27G60000BA000100
S28925096XAK27GA0001A0002500
S28925096AAK27GA0001A3S005000SPY   0001426100Y
S28925096AAK27GA0001A4S002500SPY   0001426100Y
S28925096XAK27GA00019Z000500
S28925096XAK27GA00019F005000
S28925103X6K27GA0000C7000500
S28925104A6K27GA0000CIB000500IWM   0000736300Y
S28925106ABK27GA00014HB000100UWM   0000542800Y
S28925106ABK27GA00014IS000100TWM   0000701800Y
S28925106XBK27GA00014F000100
S28925106X6K27GA0000CE002000
S28925107X6K27GA0000CI000500
S28925107A6K27GA0000CIB000500IWM   0000736400Y
S28925109XBK27GA00014H000100
S28925109XBK27GA00014I000100
S28925111ABK27GA00014JS000100TWM   0000702000Y
S28925109A6K27GA0000CJB000100IWM   0000736300Y
S28925110X6K27GA0000CJ000100
S28925110X6K27GA0000CI000500
S28925110A6K27GA0000CIB000500IWM   0000736800Y
S28925113ABK27GA00014KB000100UWM   0000542800Y
S28925113XBK27GA00014J000100
S28925113ABK27GA00014LS000100TWM   0000701800Y
S28925113XAK27GA00019W001000
S28925113X6K27GA0000CI000500
S28925113A6K27GA0000CIB000500IWM   0000736400Y
S28925124XBK27GA00014K000100
S28925124XBK27GA00014L000100
S28925123X6K27GA0000CI000500
S28925123A6K27GA0000CIB000500IWM   0000736800Y
S28925126ABK27GA00014MB000100UWM   0000542800Y
S28925125A6K27GA0000CKB000100IWM   0000736300Y
S28925125X6K27GA0000CK000100
S28925127ABK27GA00014NS000100TWM   0000701800Y
S28925132AAK27GA0001A5B001000SPY   0001425400Y
S28925133X6K27GA0000CI000500
S28925133A6K27GA0000CIB000500IWM   0000736400Y
S28925143X6K27GA0000CI000500
S28925143A6K27GA0000CIB000500IWM   0000736800Y
S28925144XBK27GA00014M000100
S28925144XBK27GA00014N000100
S28925146ABK27GA00014OB000100UWM   0000542800Y
S28925146ABK27GA00014PS000100TWM   0000701800Y
S28925153X6K27GA0000CI000500
S28925153A6K27GA0000CIB000500IWM   0000736400Y
S28925162X6K27GA0000CI000500
S28925162A6K27GA0000CIB000500IWM   0000736800Y
S28925164XBK27GA00014O000100
S28925164XBK27GA00014P000100
S28925166ABK27GA00014QB000100UWM   0000542800Y
S28925166ABK27GA00014RS000100TWM   0000701800Y
S28925172X6K27GA0000CI000500
S28925172A6K27GA0000CIB000500IWM   0000736400Y
S28925180X6K27GA0000CI000500
S28925180A6K27GA0000CIB000500IWM   0000736800Y
S28925183X6K27GA0000CI000500
S28925183A6K27GA0000CIB000500IWM   0000736400Y
S28925193X6K27GA0000CI000500
S28925193A6K27GA0000CIB000500IWM   0000736800Y
S28925194XBK27GA00014Q000100
S28925194XBK27GA00014R000100
S28925196ABK27GA00014SB000100UWM   0000542800Y
S28925196ABK27GA00014TS000100TWM   0000701800Y
S28925203X6K27GA0000CI000500
S28925203A6K27GA0000CIB000500IWM   0000736400Y
S28925214XBK27GA00014S000100
S28925212X6K27GA0000CI000500
S28925212A6K27GA0000CIB000500IWM   0000736800Y
S28925214XBK27GA00014T000100
S28925214A6K27GA0000CLB000100IWM   0000736300Y
S28925216ABK27GA00014US000100TWM   0000701800Y
S28925214X6K27GA0000CL000100
S28925216ABK27GA00014VB000100UWM   0000542800Y
S28925222X6K27GA0000CI000500
S28925222A6K27GA0000CIB000500IWM   0000736400Y
S28925228X6K27GA0000CI000500
S28925228A6K27GA0000CIB000500IWM   0000736800Y
S28925232X6K27GA0000CI000500
S28925232A6K27GA0000CIB000500IWM   0000736400Y
S28925244XBK27GA00014V000100
S28925244XBK27GA00014U000100
S28925242X6K27GA0000CI000500
S28925242A6K27GA0000CIB000500IWM   0000736800Y
S28925244A6K27GA0000CMB000100IWM   0000736300Y
S28925246ABK27GA00014WS000100TWM   0000702000Y
S28925245X6K27GA0000CM000100
S28925252X6K27GA0000CI000500
S28925252A6K27GA0000CIB000500IWM   0000736400Y
S28925254ABK27GA00014XB000100UWM   0000542800Y
S28925254XBK27GA00014W000100
S28925254ABK27GA00014YS000100TWM   0000701800Y
S28925262X6K27GA0000CI000500
S28925262A6K27GA0000CIB000500IWM   0000736800Y
S28925264XBK27GA00014X000100
S28925264XBK27GA00014Y000100
S28925266ABK27GA00014ZS000100TWM   0000702000Y
S28925272X6K27GA0000CI000500
S28925272A6K27GA0000CIB000500IWM   0000736400Y
S28925282X6K27GA0000CI000500
S28925282A6K27GA0000CIB000500IWM   0000736800Y
S28925293X6K27GA0000CI000500
S28925293A6K27GA0000CIB000500IWM   0000736400Y
S28925302X6K27GA0000CI000500
S28925302A6K27GA0000CIB000500IWM   0000736800Y
S28925312X6K27GA0000CI000500
S28925312A6K27GA0000CIB000500IWM   0000736400Y
S28925322X6K27GA0000CI000500
S28925322A6K27GA0000CIB000500IWM   0000736800Y
S28925333X6K27GA0000CI000500
S28925333A6K27GA0000CIB000500IWM   0000736400Y
S28925343X6K27GA0000CI000500
S28925343A6K27GA0000CIB000500IWM   0000736800Y
S28925347X3K27G60000B0002000
S28925352X3K27G60000B4002000
S28925352X6K27GA0000CI000500
S28925352A6K27GA0000CIB000500IWM   0000736400Y
S28925363X6K27GA0000CI000500
S28925363A6K27GA0000CIB000500IWM   0000736800Y
S28925374X6K27GA0000CI000500
S28925374A6K27GA0000CIB000500IWM   0000736400Y
S28925383X6K27GA0000CI000500
S28925383A6K27GA0000CIB000500IWM   0000736800Y
S28925393X6K27GA0000CI000500
S28925393A6K27GA0000CIB000500IWM   0000736400Y
S28925403X6K27GA0000CI000500
S28925403A6K27GA0000CIB000500IWM   0000736800Y
S28925407X7K27GA000070002000
S28925413X6K27GA0000CI000500
S28925413A6K27GA0000CIB000500IWM   0000736400Y
S28925421X5K27GA00007J002000
S28925423XBK27GA00014G002000
S28925441XCK27GA000059002000
S28925443X1K27GA0000BH002000
S28925450X1K27GA0000BF002000
S28925459X1K27GA0000BG002000
S28925469X2K27G60000AZ002000
S28925472X2K27G60000AY002000
S28925475X2K27G60000B1002000
S28925486X2K27G60000B2002000
S28925488X2K27G60000B5002000
S28925493A5K27GA00007LS002000FNM   0001412200Y
S28925498X2K27G600009U002000
S28925507X2K27G60000B4002000
S28925515A2K27G60000B7B002000BMY   0000068200Y
S28925518ABK27GA000150B002000TGT   0000521100Y
S28925527ABK27GA000151S002000UTX   0001574100Y
S28925537A7K27GA000071B002000LMT   0000369100Y
S28925539ACK27GA00005AB002000WYE   0000142500Y
S28925556A1K27GA0000BIB002000AFL   0000224200Y
S28925558ABK27GA000152B002000UTX   0000243100Y
S28925568ABK27GA000153S002000UTX   0001573300Y
S28925573A1K27GA0000BJS002000AFL   0001561900Y
S28925581A1K27GA0000BKB002000ABT   0000183900Y
S28925590A2K27G60000B8B002000BBT   0000109800Y
S28925618A2K27G60000B9S002000CAH   0000570500Y
S28925618A2K27G60000BAB002000CAG   0000072200Y
S28925625A2K27G60000BBB002000CAT   0000820200Y
S28925627A3K27G60000BBB002000CHS   0000060900Y
S28925644A3K27G60000BCS002000CHS   0000090900Y
S28925645A2K27G60000BCS002000CAT   0000867300Y
S28925663A3K27G60000BDB002000CL    0000692100Y
S28925663A3K27G60000BEB002000CCE   0000193600Y
S28925689A3K27G60000BFS002000CCE   0000240100Y
S28925863X6K27GA000097000100
S28925863X6K27GA000098000100
S28925864XBK27GA0000RT000100
S28926276X4K27GA0000DX000200
S28926276A4K27GA0000DXB000200DIA   0001298900Y
S28926276XAK27GA00019P001000
S28926277AAK27GA0001A6S001000SPY   0001426200Y
S28926277AAK27GA0001A7S001000SPY   0001426300Y
S28926278AAK27GA0001A8S000500SPY   0001426000Y
S28926278A4K27GA0000J4S000100DXD   0000500000Y
S28926279A3K27G60000BGB000100DDM   0000801300Y
S28926278AAK27GA0001A9S002500SPY   0001426000Y
S28926279XAK27GA0001A3005000
S28926279XAK27GA0001A4002500
S28926279AAK27GA0001AAS005000SPY   0001426200Y
S28926289A6K27GA0000CNS002000IWM   0000737300Y
S28926299XAK27GA0001A6001000
S28926299XAK27GA00019T003000
S28926299XAK27GA00019S003000
S28926300XAK27GA0001A5001000
S28926300AAK27GA0001ABB001000SPY   0001425500Y
S28926301XAK27GA0000F2000500
S28926301AAK27GA0000F2B000500SPY   0001425800Y
S28926301AAK27GA0001ACS003000SPY   0001426600Y
S28926301AAK27GA0001ADS003000SPY   0001426600Y
S28926301XAK27GA0001A9002500
S28926301XAK27GA0001A8000500
S28926301XBK27GA00011E001000
S28926301ABK27GA000154B001000SSO   0000764700Y
S28926303ABK27GA000155B001000SSO   0000764500Y
S28926313X4K27GA0000DX000200
S28926313A4K27GA0000DXB000200DIA   0001298600Y
S28926313XAK27GA0000F2000500
S28926313AAK27GA0000F2B000500SPY   0001425400Y
S28926314XBK27GA000155001000
S28926315X4K27GA0000J4000100
S28926315X3K27G60000BG000100
S28926315X6K27GA0000CI000500
S28926315A6K27GA0000CIB000500IWM   0000736800Y
S28926318ABK27GA000156B000100UWM   0000542800Y
S28926318XBK27GA00014Z000100
S28926318ABK27GA000157S000100TWM   0000701800Y
S28926318XBK27GA000154001000
S28926317X6K27GA0000CN002000
S28926318XAK27GA0001AD003000
S28926318XAK27GA0001AC003000
S28926318AAK27GA0001AES003000SPY   0001426000Y
S28926319AAK27GA0001AFS003000SPY   0001426000Y
S28926318X6K27GA0000CI000500
S28926318A6K27GA0000CIB000500IWM   0000736400Y
S28926320ABK27GA000158B001000SSO   0000764600Y
S28926321XBK27GA000156000100
S28926322XBK27GA000157000100
S28926321X6K27GA0000CI000500
S28926321A6K27GA0000CIB000500IWM   0000736800Y
S28926323ABK27GA000159S000100TWM   0000702000Y
S28926324X9K27G60000F8003200
S28926324A9K27G60000F8S003200QQQQ  0000496500Y
S28926324ABK27GA00015AB000100UWM   0000542800Y
S28926324ABK27GA00015BS000100TWM   0000701800Y
S28926324XBK27GA000159000100
S28926326X4K27GA0000DX000200
S28926326A4K27GA0000DXB000200DIA   0001298900Y
S28926326X9K27G60000G3002000
S28926326A9K27G60000G3S002000QQQQ  0000496400Y
S28926326AAK27GA0001AGS001000SPY   0001426200Y
S28926328X9K27G60000S1001000
S28926328A9K27G60000S5B001000QLD   0000889600Y
S28926328A3K27G60000BHB000100DDM   0000801300Y
S28926328A4K27GA0000J5S000100DXD   0000500000Y
S28926329XAK27GA0001AB001000
S28926329X9K27G60000F8003200
S28926329A9K27G60000F8S003200QQQQ  0000496000Y
S28926329XAK27GA0001A2003000
S28926329XAK27GA0001A1003000
S28926330A9K27G60000S6B001000QQQQ  0000495500Y
S28926330A9K27G60000S7B001000QQQQ  0000495400Y
S28926330X9K27G60000S5001000
S28926332A9K27G60000S8B001000QLD   0000889500Y
S28926332AAK27GA0001AHB003000SPY   0001425000Y
S28926332AAK27GA0001AIB003000SPY   0001425000Y
S28926334X9K27G60000S6001000
S28926334X9K27G60000S7001000
S28926332X6K27GA0000CI000500
S28926332A6K27GA0000CIB000500IWM   0000736400Y
S28926343X6K27GA0000CI000500
S28926343A6K27GA0000CIB000500IWM   0000736800Y
S28926348X6K27GA0000CI000500
S28926348A6K27GA0000CIB000500IWM   0000736400Y
S28926354A3K27G60000BIB002000CELG  0000497800Y
S28926354XBK27GA00015A000100
S28926354XBK27GA00015B000100
S28926355AAK27GA0001AJB001000SPY   0001425500Y
S28926356ABK27GA00015CS000100TWM   0000702000Y
S28926356X6K27GA0000CI000500
S28926356A6K27GA0000CIB000500IWM   0000736800Y
S28926358ABK27GA00015DB000100UWM   0000542800Y
S28926358XBK27GA00015C000100
S28926358ABK27GA00015ES000100TWM   0000701800Y
S28926362X6K27GA0000CI000500
S28926362A6K27GA0000CIB000500IWM   0000736400Y
S28926374XBK27GA00015D000100
S28926374XBK27GA00015E000100
S28926373X6K27GA0000CI000500
S28926373A6K27GA0000CIB000500IWM   0000736800Y
S28926376ABK27GA00015FS000100TWM   0000702000Y
S28926377ABK27GA00015GB000100UWM   0000542800Y
S28926377XBK27GA00015F000100
S28926377ABK27GA00015HS000100TWM   0000701800Y
S28926377X6K27GA0000CI000500
S28926377A6K27GA0000CIB000500IWM   0000736400Y
S28926385XBK27GA00015G000100
S28926385XBK27GA00015H000100
S28926387ABK27GA00015IS000100TWM   0000702000Y
S28926387X6K27GA0000CI000500
S28926387A6K27GA0000CIB000500IWM   0000736800Y
S28926390ABK27GA00015JB000100UWM   0000542800Y
S28926390ABK27GA00015KS000100TWM   0000701800Y
S28926390XBK27GA00015I000100
S28926392X6K27GA0000CI000500
S28926392A6K27GA0000CIB000500IWM   0000736400Y
S28926395X4K27GA0000H5002000
S28926398X7K27GA000071002000
S28926403X6K27GA0000CI000500
S28926403A6K27GA0000CIB000500IWM   0000736800Y
S28926405XBK27GA00015J000100
S28926405XBK27GA00015K000100
S28926407ABK27GA00015LS000100TWM   0000701800Y
S28926407ABK27GA00015MB000100UWM   0000542800Y
S28926407X6K27GA0000CI000500
S28926407A6K27GA0000CIB000500IWM   0000736400Y
S28926410XBK27GA00015M000100
S28926410XBK27GA00015L000100
S28926412ABK27GA00015NS000100TWM   0000702000Y
S28926413X5K27GA00007L002000
S28926417X6K27GA0000CI000500
S28926417A6K27GA0000CIB000500IWM   0000736800Y
S28926419XBK27GA000152002000
S28926424ABK27GA00015OB000100UWM   0000542800Y
S28926424XBK27GA00015N000100
S28926424ABK27GA00015PS000100TWM   0000701800Y
S28926424X6K27GA0000CI000500
S28926424A6K27GA0000CIB000500IWM   0000736400Y
S28926428A3K27G60000BJB002000CTSH  0000099700Y
S28926428XBK27GA000151002000
S28926428XBK27GA000153002000
S28926430XCK27GA00005A002000
S28926434XBK27GA00015O000100
S28926434XBK27GA00015P000100
S28926435X1K27GA0000BK002000
S28926436ABK27GA00015QS000100TWM   0000702000Y
S28926445X1K27GA0000BI002000
S28926446X2K27G60000B0002000
S28926454X2K27G60000B3002000
S28926457X1K27GA0000BJ002000
S28926468X2K27G600007N002000
S28926468X9K27G60000G3002000
S28926468A9K27G60000G3S002000QQQQ  0000496000Y
S28926469A9K27G60000S9S002000QQQQ  0000496000Y
S28926472X2K27G60000A0002000
S28926475A5K27GA00007MS002000FNM   0001406600Y
S28926487AAK27GA0001AKS000500SPY   0001426000Y
S28926489A6K27GA0000COS002000IWM   0000737200Y
S28926491A6K27GA0000CPS002000IWM   0000737300Y
S28926495A7K27GA000072B002000LMT   0000371300Y
S28926502ACK27GA00005BB002000WYE   0000144500Y
S28926509ABK27GA00015RB002000UTX   0000244300Y
S28926519A1K27GA0000BLB002000AFL   0000226800Y
S28926527A1K27GA0000BMB002000ABT   0000184600Y
S28926537A1K27GA0000BNS002000AFL   0001557500Y
S28926554A2K27G60000BDS002000BA    0001616500Y
S28926554A2K27G60000BES002000BA    0001615700Y
S28926569A2K27G60000BFS002000BBT   0001427700Y
S28926587A2K27G60000BGS002000BBT   0001426900Y
S28926604A2K27G60000BHB002000BDX   0000775900Y
S28926604A2K27G60000BIS002000CAG   0001390600Y
S28926620A2K27G60000BJS002000CAG   0001389800Y
S28926624A3K27G60000BKS002000CL    0000747400Y
S28926634A3K27G60000BLB002000CCL   0000381100Y
S28926645A3K27G60000BMB002000CNX   0000929700Y
S28926652A3K27G60000BNS002000CCL   0000401400Y
S28926726AAK27GA0001ALS002500SPY   0001426000Y
S28927283X9K27G60000S9002000
S28927295X6K27GA0000CO002000
S28927347A9K27G60000SAS002000QQQQ  0000496000Y
S28927348XAK27GA00019B002000
S28927386AAK27GA0001AMS001000SPY   0001426100Y
S28927386XAK27GA0001AG001000
S28927390X5K27GA00006G002000
S28927391X2K27G60000B7002000
S28927400XAK27GA000175001000
S28927406X7K27GA000072002000
S28927413X5K27GA00007M002000
S28927416XBK27GA00013O002000
S28927416XBK27GA00015R002000
S28927424XBK27GA00013P002000
S28927444XCK27GA00005B002000
S28927453X1K27GA0000BM002000
S28927463X1K27GA0000BL002000
S28927468X1K27GA0000BN002000
S28927477X2K27G60000BE002000
S28927485X2K27G60000BG002000
S28927487X1K27GA00008N002000
S28927501X2K27G60000BJ002000
S28927501X2K27G60000BD002000
S28927508X2K27G60000B8002000
S28927517X2K27G60000BF002000
S28927524X2K27G60000BA002000
S28927523A7K27GA000073B002000LMT   0000375100Y
S28927526X2K27G60000BI002000
S28927549ABK27GA00015SB002000UTX   0000247100Y
S28927551A4K27GA0000J6B002000EMR   0000555400Y
S28927558A5K27GA00007NS002000FNM   0001402700Y
S28927561ABK27GA00015TS002000UTX   0001566300Y
S28927599A1K27GA0000BOB002000ABT   0000186900Y
S28927605A2K27G60000BKB002000BBT   0000112500Y
S28927615A2K27G60000BLB002000CAG   0000074300Y
S28927636A3K27G60000BOB002000CCU   0000337000Y
S28927639ABK27GA00015US002000UTX   0001567100Y
S28927647ACK27GA00005CB002000WYE   0000144900Y
S28927656A3K27G60000BPB002000CFC   0000038100Y
S28927656A1K27GA0000BPB002000AFL   0000227900Y
S28927667A1K27GA0000BQS002000AFL   0001554700Y
S28927673A3K27G60000BQS002000CFC   0000058800Y
S28927681A2K27G60000BMB002000AZN   0000421300Y
S28927687A2K27G60000BNB002000BDX   0000775300Y
S28927694A3K27G60000BRB002000CHS   0000061700Y
S28927709A3K27G60000BSS002000CNX   0000994800Y
S28927713A3K27G60000BTS002000CHS   0000090100Y
S28927723A3K27G60000BUB002000COH   0000117400Y
S28927754A3K27G60000BVS002000COH   0001432000Y
S28927767A3K27G60000BWB002000COP   0000915200Y
S28927775A3K27G60000BXS002000COP   0000939700Y
S28927851XAK27GA00018Y001000
S28927888X4K27GA0000DX000200
S28927888A4K27GA0000DXB000200DIA   0001298600Y
S28927891X4K27GA0000J5000100
S28927891X3K27G60000BH000100
S28928298X4K27GA0000DX000200
S28928298A4K27GA0000DXB000200DIA   0001298900Y
S28928298XAK27GA0001AM001000
S28928298XAK27GA0001AI003000
S28928298XAK27GA0001AH003000
S28928298XAK27GA0001AF003000
S28928298XAK27GA0000F2000500
S28928298AAK27GA0000F2B000500SPY   0001425800Y
S28928298XAK27GA0001AE003000
S28928298AAK27GA0001ANB003000SPY   0001425700Y
S28928298AAK27GA0001AOB003000SPY   0001425700Y
S28928298AAK27GA0001APS001000SPY   0001426200Y
S28928298AAK27GA0001AQB001000SPY   0001425600Y
S28928298XAK27GA0000E4001000
S28928298AAK27GA0000E4B001000SPY   0001425800Y
S28928299XBK27GA000158001000
S28928299ABK27GA00015VB001000SSO   0000764700Y
S28928300AAK27GA0001ARS001000SPY   0001426200Y
S28928300A4K27GA0000J7S000100DXD   0000500000Y
S28928301A3K27G60000BYB000100DDM   0000801300Y
S28928300AAK27GA0001ASS003000SPY   0001426600Y
S28928300AAK27GA0001ATS003000SPY   0001426600Y
S28928300AAK27GA0001AUS005000SPY   0001426100Y
S28928301ABK27GA00015WB001000SSO   0000764500Y
S28928301XAK27GA0001AA005000
S28928301XAK27GA0001AL002500
S28928302AAK27GA0001AVB002500SPY   0001425600Y
S28928302XAK27GA0001AK000500
S28928303AAK27GA0001AWB000500SPY   0001425600Y
S28928303XAK27GA000198000500
S28928310XAK27GA0001AQ001000
S28928311X6K27GA0000CI000500
S28928312A6K27GA0000CQB000500IWM   0000736800Y
S28928314ABK27GA00015XB000100UWM   0000542800Y
S28928314XBK27GA00015Q000100
S28928314ABK27GA00015YS000100TWM   0000701800Y
S28928318X4K27GA0000DX000200
S28928318A4K27GA0000DXB000200DIA   0001298600Y
S28928318XAK27GA0000E4001000
S28928318AAK27GA0000E4B001000SPY   0001425400Y
S28928318XAK27GA0001AO003000
S28928318XAK27GA0001AN003000
S28928318XAK27GA0000F2000500
S28928318AAK27GA0000F2B000500SPY   0001425400Y
S28928318X6K27GA0000CQ000500
S28928318A6K27GA0000CQB000500IWM   0000736400Y
S28928320X4K27GA0000J7000100
S28928320AAK27GA0001AXB003000SPY   0001425600Y
S28928320X3K27G60000BY000100
S28928320AAK27GA0001AYB003000SPY   0001425600Y
S28928320XAK27GA0001AR001000
S28928321XBK27GA00015W001000
S28928320XAK27GA0001AT003000
S28928320XAK27GA0001AS003000
S28928321XAK27GA0001AW000500
S28928321XAK27GA0001AV002500
S28928321AAK27GA0001AZS003000SPY   0001426000Y
S28928321AAK27GA0001B0S003000SPY   0001426000Y
S28928322XBK27GA00015X000100
S28928322XBK27GA00015Y000100
S28928324ABK27GA00015ZS000100TWM   0000702000Y
S28928322X6K27GA0000CQ000500
S28928322A6K27GA0000CQB000500IWM   0000736800Y
S28928325ABK27GA000160B000100UWM   0000542800Y
S28928325XBK27GA00015Z000100
S28928325ABK27GA000161S000100TWM   0000701800Y
S28928328XBK27GA00015V001000
S28928330ABK27GA000162B001000SSO   0000764600Y
S28928332X6K27GA0000CQ000500
S28928332A6K27GA0000CQB000500IWM   0000736400Y
S28928335X4K27GA0000DX000200
S28928335A4K27GA0000DXB000200DIA   0001298900Y
S28928336AAK27GA0001B1S001000SPY   0001426100Y
S28928336XAK27GA000174001000
S28928336XAK27GA0001AU005000
S28928336A4K27GA0000J8S000100DXD   0000500000Y
S28928337A3K27G60000BZB000100DDM   0000801300Y
S28928337XAK27GA0001AX003000
S28928337XAK27GA0001AY003000
S28928339A6K27GA0000CRS002000IWM   0000737200Y
S28928340AAK27GA0001B2B003000SPY   0001425000Y
S28928341AAK27GA0001B3B003000SPY   0001425000Y
S28928344XBK27GA000160000100
S28928344XBK27GA000161000100
S28928345A6K27GA0000CSB000100IWM   0000736300Y
S28928346ABK27GA000163S000100TWM   0000702000Y
S28928345X6K27GA0000CS000100
S28928350XAK27GA00019X002000
S28928354X6K27GA0000CQ000500
S28928354A6K27GA0000CQB000500IWM   0000736800Y
S28928356XAK27GA0001AJ001000
S28928355X6K27GA0000CR002000
S28928357ABK27GA000164B000100UWM   0000542800Y
S28928356X6K27GA0000CQ000500
S28928356A6K27GA0000CQB000500IWM   0000736400Y
S28928357XBK27GA000163000100
S28928357ABK27GA000165S000100TWM   0000701800Y
S28928358AAK27GA0001B4B001000SPY   0001425400Y
S28928359XBK27GA000165000100
S28928359XBK27GA000164000100
S28928361ABK27GA000166S000100TWM   0000702000Y
S28928363AAK27GA0001B5S001000SPY   0001426100Y
S28928362A6K27GA0000CTS002000IWM   0000737200Y
S28928363X4K27GA0000DX000200
S28928363A4K27GA0000DXB000200DIA   0001298600Y
S28928364ABK27GA000167B000100UWM   0000542800Y
S28928364XBK27GA000166000100
S28928364ABK27GA000168S000100TWM   0000701800Y
S28928364XBK27GA000168000100
S28928364XBK27GA000167000100
S28928365X4K27GA0000J8000100
S28928366X3K27G60000BZ000100
S28928366ABK27GA000169S000100TWM   0000702000Y
S28928379AAK27GA0001B6B001000SPY   0001425500Y
S28928396XAK27GA0001B4001000
S28928401X5K27GA00007N002000
S28928401AAK27GA0001B7B002000SHLD  0000775100Y
S28928402A2K27G60000BOB002000BMY   0000070100Y
S28928404X5K27GA000078002000
S28928419XBK27GA00015U002000
S28928423XCK27GA00005C002000
S28928439X1K27GA0000BP002000
S28928439X1K27GA0000BQ002000
S28928444X1K27GA00008R002000
S28928449X2K27G60000AS002000
S28928458A5K27GA00007OS002000FNM   0001397100Y
S28928474X7K27GA000073002000
S28928493X3K27G60000BV002000
S28928497ABK27GA00016AS002000TGT   0000619500Y
S28928506A5K27GA00007PS002000GM    0000228000Y
S28928514XBK27GA00015S002000
S28928515A7K27GA000074B002000LMT   0000377300Y
S28928516AAK27GA0001B8B000500SPY   0001425400Y
S28928526XBK27GA00015T002000
S28928527ABK27GA00016BS002000TGT   0000620300Y
S28928535ABK27GA00016CB002000UTX   0000248300Y
S28928546ACK27GA00005DB002000WYE   0000146900Y
S28928560X1K27GA0000BO002000
S28928585A1K27GA0000BRB002000AFL   0000230500Y
S28928596A1K27GA0000BSS002000AFL   0001550300Y
S28928604A1K27GA0000BTB002000ABT   0000187600Y
S28928615X2K27G60000AT002000
S28928623A1K27GA0000BUS002000ACN   0000408100Y
S28928634A2K27G60000BPS002000BA    0001609500Y
S28928644A2K27G60000BQS002000BA    0001610300Y
S28928652A2K27G60000BRS002000BBT   0001417800Y
S28928663A2K27G60000BSB002000BBT   0000112600Y
S28928670A2K27G60000BTS002000CAG   0001380100Y
S28928680A2K27G60000BUS002000BBT   0001418600Y
S28928699A2K27G60000BVB002000CAG   0000074100Y
S28928707A2K27G60000BWS002000CAG   0001380900Y
S28928718AAK27GA0001B9S005000SPY   0001426200Y
S28928719AAK27GA0001BAS000500SPY   0001426000Y
S28928719AAK27GA0001BBS002500SPY   0001426000Y
S28929238XAK27GA0001A7001000
S28929239AAK27GA0001BCS001000SPY   0001425900Y
S28929343X6K27GA0000BO002000
S28929398X7K27GA000074002000
S28929398X5K27GA00007O002000
S28929415X1K27GA0000AR002000
S28929418XBK27GA00016C002000
S28929432XCK27GA00005D002000
S28929434X3K27G60000BJ002000
S28929444X1K27GA0000BT002000
S28929447AAK27GA0001BDB002000SOHU  0000797200Y
S28929459X2K27G60000BQ002000
S28929475X2K27G60000BU002000
S28929481X1K27GA0000BR002000
S28929495X2K27G600008A002000
S28929497X1K27GA0000BS002000
S28929499X2K27G60000BW002000
S28929503X2K27G60000BP002000
S28929513X3K27G60000BU002000
S28929513AAK27GA0001BEB002000SPLS  0000071800Y
S28929515X2K27G60000BK002000
S28929525X2K27G60000BR002000
S28929531A5K27GA00007QS002000FNM   0001393200Y
S28929540X2K27G60000BL002000
S28929549X2K27G60000BT002000
S28929581A7K27GA000075B002000LMT   0000381100Y
S28929591ABK27GA00016DB002000UTX   0000251100Y
S28929596A5K27GA00007RB002000GM    0000179700Y
S28929598ABK27GA00016ES002000UTX   0001559400Y
S28929606A1K27GA0000BVB002000ABT   0000190000Y
S28929623A2K27G60000BXB002000AXP   0000419500Y
S28929626ABK27GA00016FS002000UTX   0001560200Y
S28929645ACK27GA00005EB002000WYE   0000147300Y
S28929656A3K27G60000C0B002000CL    0000692900Y
S28929656A1K27GA0000BWB002000AFL   0000231600Y
S28929663A1K27GA0000BXS002000AFL   0001547600Y
S28929672A3K27G60000C1S002000CL    0000746600Y
S28929674A1K27GA0000BYS002000ALL   0000524900Y
S28929683A2K27G60000BYB002000AXP   0000418700Y
S28929690A3K27G60000C2B002000CNX   0000930500Y
S28929705A3K27G60000C3S002000CNX   0000994000Y
S28929724A3K27G60000C4B002000COH   0000120200Y
S28929741A3K27G60000C5S002000COH   0001422200Y
S28929971AAK27GA0001BFB002500SPY   0001425500Y
S28929972XAK27GA0001B8000500
S28929972AAK27GA0001BGB005000SPY   0001425500Y
S28929973XAK27GA000163005000
S28929979X6K27GA0000CQ000500
S28929979A6K27GA0000CQB000500IWM   0000736800Y
S28929980X6K27GA0000CT002000
S28929983ABK27GA00016GB000100UWM   0000542800Y
S28929983XBK27GA000169000100
S28929983ABK27GA00016HS000100TWM   0000701800Y
S28929982X6K27GA0000CQ000500
S28929982A6K27GA0000CQB000500IWM   0000736400Y
S28929987XAK27GA0001BC001000
S28929992X6K27GA0000CQ000500
S28929992A6K27GA0000CQB000500IWM   0000736800Y
S28929994XBK27GA00016G000100
S28929994AAK27GA0001BHS001000SPY   0001426300Y
S28929994XBK27GA00016H000100
S28929996ABK27GA00016IB000100UWM   0000542800Y
S28929996ABK27GA00016JS000100TWM   0000701800Y
S28930002X6K27GA0000CQ000500
S28930002A6K27GA0000CQB000500IWM   0000736400Y
S28930012X6K27GA0000CQ000500
S28930012A6K27GA0000CQB000500IWM   0000736800Y
S28930014XBK27GA00016I000100
S28930014XBK27GA00016J000100
S28930016ABK27GA00016KS000100TWM   0000701800Y
S28930016ABK27GA00016LB000100UWM   0000542800Y
S28930022X6K27GA0000CQ000500
S28930022A6K27GA0000CQB000500IWM   0000736400Y
S28930032X6K27GA0000CQ000500
S28930032A6K27GA0000CQB000500IWM   0000736800Y
S28930034XBK27GA00016L000100
S28930034XBK27GA00016K000100
S28930037ABK27GA00016MS000100TWM   0000701800Y
S28930037ABK27GA00016NB000100UWM   0000542800Y
S28930042X6K27GA0000CQ000500
S28930042A6K27GA0000CQB000500IWM   0000736400Y
S28930052X6K27GA0000CQ000500
S28930052A6K27GA0000CQB000500IWM   0000736800Y
S28930054XBK27GA00016N000100
S28930054XBK27GA00016M000100
S28930056ABK27GA00016OB000100UWM   0000542800Y
S28930054A6K27GA0000CUB000100IWM   0000736300Y
S28930056ABK27GA00016PS000100TWM   0000701800Y
S28930055X6K27GA0000CU000100
S28930062X6K27GA0000CQ000500
S28930062A6K27GA0000CQB000500IWM   0000736400Y
S28930072X6K27GA0000CQ000500
S28930072A6K27GA0000CQB000500IWM   0000736800Y
S28930074XBK27GA00016O000100
S28930074XBK27GA00016P000100
S28930076ABK27GA00016QS000100TWM   0000701800Y
S28930076ABK27GA00016RB000100UWM   0000542800Y
S28930082X6K27GA0000CQ000500
S28930082A6K27GA0000CQB000500IWM   0000736400Y
S28930092X6K27GA0000CQ000500
S28930092A6K27GA0000CQB000500IWM   0000736800Y
S28930094XBK27GA00016R000100
S28930094XBK27GA00016Q000100
S28930096ABK27GA00016SB000100UWM   0000542800Y
S28930096ABK27GA00016TS000100TWM   0000701800Y
S28930102X6K27GA0000CQ000500
S28930102A6K27GA0000CQB000500IWM   0000736400Y
S28930112X6K27GA0000CQ000500
S28930112A6K27GA0000CQB000500IWM   0000736800Y
S28930114XBK27GA00016S000100
S28930114XBK27GA00016T000100
S28930116ABK27GA00016US000100TWM   0000702000Y
S28930122X6K27GA0000CQ000500
S28930122A6K27GA0000CQB000500IWM   0000736400Y
S28930132X6K27GA0000CQ000500
S28930132A6K27GA0000CQB000500IWM   0000736800Y
S28930142X6K27GA0000CQ000500
S28930142A6K27GA0000CQB000500IWM   0000736400Y
S28930152X6K27GA0000CQ000500
S28930152A6K27GA0000CQB000500IWM   0000736800Y
S28930163X6K27GA0000CQ000500
S28930163A6K27GA0000CQB000500IWM   0000736400Y
S28930172X6K27GA0000CQ000500
S28930172A6K27GA0000CQB000500IWM   0000736800Y
S28930182X6K27GA0000CQ000500
S28930182A6K27GA0000CQB000500IWM   0000736400Y
S28930192X6K27GA0000CQ000500
S28930192A6K27GA0000CQB000500IWM   0000736800Y
S28930202X6K27GA0000CQ000500
S28930202A6K27GA0000CQB000500IWM   0000736400Y
S28930212X6K27GA0000CQ000500
S28930212A6K27GA0000CQB000500IWM   0000736800Y
S28930222X6K27GA0000CQ000500
S28930222A6K27GA0000CQB000500IWM   0000736400Y
S28930233X6K27GA0000CQ000500
S28930233A6K27GA0000CQB000500IWM   0000736800Y
S28930242X6K27GA0000CQ000500
S28930242A6K27GA0000CQB000500IWM   0000736400Y
S28930252X6K27GA0000CQ000500
S28930252A6K27GA0000CQB000500IWM   0000736800Y
S28930262X6K27GA0000CQ000500
S28930262A6K27GA0000CQB000500IWM   0000736400Y
S28930272X6K27GA0000CQ000500
S28930272A6K27GA0000CQB000500IWM   0000736800Y
S28930282X6K27GA0000CQ000500
S28930282A6K27GA0000CQB000500IWM   0000736400Y
S28930292X6K27GA0000CQ000500
S28930292A6K27GA0000CQB000500IWM   0000736800Y
S28930302X6K27GA0000CQ000500
S28930302A6K27GA0000CQB000500IWM   0000736400Y
S28930312X6K27GA0000CQ000500
S28930312A6K27GA0000CQB000500IWM   0000736800Y
S28930322X6K27GA0000CQ000500
S28930322A6K27GA0000CQB000500IWM   0000736400Y
S28930332X6K27GA0000CQ000500
S28930332A6K27GA0000CQB000500IWM   0000736800Y
S28930342X6K27GA0000CQ000500
S28930342A6K27GA0000CQB000500IWM   0000736400Y
S28930349X5K27GA00007Q002000
S28930352X6K27GA0000CQ000500
S28930352A6K27GA0000CQB000500IWM   0000736800Y
S28930362X6K27GA0000CQ000500
S28930362A6K27GA0000CQB000500IWM   0000736400Y
S28930373X6K27GA0000CQ000500
S28930373A6K27GA0000CQB000500IWM   0000736800Y
S28930392X6K27GA0000CQ000500
S28930392A6K27GA0000CQB000500IWM   0000736400Y
S28930394X9K27G60000SA002000
S28930395A9K27G60000SBB002000QQQQ  0000495600Y
S28930402X6K27GA0000CQ000500
S28930402A6K27GA0000CQB000500IWM   0000736800Y
S28930413X2K27G60000BO002000
S28930414A6K27GA0000CVS002000IMCL  0000510600Y
S28930418XBK27GA00016F002000
S28930422X6K27GA0000CQ000500
S28930422A6K27GA0000CQB000500IWM   0000736400Y
S28930432X6K27GA0000CQ000500
S28930432A6K27GA0000CQB000500IWM   0000736800Y
S28930442XCK27GA00005E002000
S28930442X6K27GA0000CQ000500
S28930442A6K27GA0000CQB000500IWM   0000736400Y
S28930446X7K27GA000075002000
S28930446X1K27GA0000BW002000
S28930447X1K27GA0000BX002000
S28930449XBK27GA00016D002000
S28930460XBK27GA00016E002000
S28930461X2K27G60000BS002000
S28930460A1K27GA0000BZS002000APOL  0000529600Y
S28930460X1K27GA0000BV002000
S28930464X2K27G600008B002000
S28930492X2K27G600008I002000
S28930492X2K27G60000BV002000
S28930497X3K27G60000C5002000
S28930502A5K27GA00007SS002000FNM   0001387600Y
S28930514A3K27G60000C6B002000CTSH  0000103100Y
S28930531A7K27GA000076B002000LMT   0000383300Y
S28930559ACK27GA00005FB002000WYE   0000149300Y
S28930561ABK27GA00016VB002000UTX   0000252300Y
S28930597A1K27GA0000C0B002000ABT   0000190700Y
S28930621A1K27GA0000C1B002000AFL   0000234300Y
S28930629A2K27G60000BZS002000BA    0001604100Y
S28930642A1K27GA0000C2S002000AFL   0001543200Y
S28930646A2K27G60000C0S002000BBT   0001409400Y
S28930658A2K27G60000C1S002000BA    0001603300Y
S28930665A2K27G60000C2B002000BK    0000428900Y
S28930676A2K27G60000C3B002000BBT   0000115300Y
S28930678A2K27G60000C4S002000CAG   0001371100Y
S28930693A2K27G60000C5S002000BBT   0001408600Y
S28930695A3K27G60000C7B002000COH   0000120400Y
S28930709A3K27G60000C8S002000COH   0001418500Y
S28930713A2K27G60000C6B002000CAG   0000076200Y
S28930736A2K27G60000C7S002000CAG   0001370300Y
S28931064X6K27GA0000CQ000500
S28931064A6K27GA0000CWB000500IWM   0000736800Y
S28931067XBK27GA00016U000100
S28931067ABK27GA00016WS000100TWM   0000701800Y
S28931067ABK27GA00016XB000100UWM   0000542800Y
S28931068X6K27GA0000CP002000
S28931069X6K27GA0000CW000500
S28931069A6K27GA0000CWB000500IWM   0000736400Y
S28931073X6K27GA0000CW000500
S28931073A6K27GA0000CWB000500IWM   0000736800Y
S28931083X6K27GA0000CW000500
S28931083A6K27GA0000CWB000500IWM   0000736400Y
S28931093X6K27GA0000CW000500
S28931093A6K27GA0000CWB000500IWM   0000736800Y
S28931103X6K27GA0000CW000500
S28931103A6K27GA0000CWB000500IWM   0000736400Y
S28931113X6K27GA0000CW000500
S28931113A6K27GA0000CWB000500IWM   0000736800Y
S28931123X6K27GA0000CW000500
S28931123A6K27GA0000CWB000500IWM   0000736400Y
S28931133X6K27GA0000CW000500
S28931133A6K27GA0000CWB000500IWM   0000736800Y
S28931143X6K27GA0000CW000500
S28931143A6K27GA0000CWB000500IWM   0000736400Y
S28931153X6K27GA0000CW000500
S28931153A6K27GA0000CWB000500IWM   0000736800Y
S28931163X6K27GA0000CW000500
S28931163A6K27GA0000CWB000500IWM   0000736400Y
S28931173X6K27GA0000CW000500
S28931173A6K27GA0000CWB000500IWM   0000736800Y
S28931183X6K27GA0000CW000500
S28931183A6K27GA0000CWB000500IWM   0000736400Y
S28931186XBK27GA00016X000100
S28931186XBK27GA00016W000100
S28931186X6K27GA0000CW000500
S28931186A6K27GA0000CWB000500IWM   0000736800Y
S28931188ABK27GA00016YS000100TWM   0000702000Y
S28931188X6K27GA0000CW000500
S28931188A6K27GA0000CWB000500IWM   0000736400Y
S28931193X6K27GA0000CW000500
S28931193A6K27GA0000CWB000500IWM   0000736800Y
S28931203X6K27GA0000CW000500
S28931203A6K27GA0000CWB000500IWM   0000736400Y
S28931213X6K27GA0000CW000500
S28931213A6K27GA0000CWB000500IWM   0000736800Y
S28931223X6K27GA0000CW000500
S28931223A6K27GA0000CWB000500IWM   0000736400Y
S28931233X6K27GA0000CW000500
S28931233A6K27GA0000CWB000500IWM   0000736800Y
S28931243X6K27GA0000CW000500
S28931243A6K27GA0000CWB000500IWM   0000736400Y
S28931253X6K27GA0000CW000500
S28931253A6K27GA0000CWB000500IWM   0000736800Y
S28931263X6K27GA0000CW000500
S28931263A6K27GA0000CWB000500IWM   0000736400Y
S28931273X6K27GA0000CW000500
S28931273A6K27GA0000CWB000500IWM   0000736800Y
S28931283X6K27GA0000CW000500
S28931283A6K27GA0000CWB000500IWM   0000736400Y
S28931293X6K27GA0000CW000500
S28931293A6K27GA0000CWB000500IWM   0000736800Y
S28931303X6K27GA0000CW000500
S28931303A6K27GA0000CWB000500IWM   0000736400Y
S28931313X6K27GA0000CW000500
S28931313A6K27GA0000CWB000500IWM   0000736800Y
S28931323X6K27GA0000CW000500
S28931323A6K27GA0000CWB000500IWM   0000736400Y
S28931333X6K27GA0000CW000500
S28931333A6K27GA0000CWB000500IWM   0000736800Y
S28931343X6K27GA0000CW000500
S28931343A6K27GA0000CWB000500IWM   0000736400Y
S28931353X6K27GA0000CW000500
S28931353A6K27GA0000CWB000500IWM   0000736800Y
S28931359X5K27GA00007S002000
S28931363X6K27GA0000CW000500
S28931363A6K27GA0000CWB000500IWM   0000736400Y
S28931372X6K27GA0000CW000500
S28931372A6K27GA0000CWB000500IWM   0000736800Y
S28931382X6K27GA0000CW000500
S28931382A6K27GA0000CWB000500IWM   0000736400Y
S28931392X6K27GA0000CW000500
S28931392A6K27GA0000CWB000500IWM   0000736800Y
S28931395X7K27GA00005Q002000
S28931398X7K27GA000076002000
S28931400XBK27GA00016V002000
S28931403X6K27GA0000CW000500
S28931403A6K27GA0000CWB000500IWM   0000736400Y
S28931407A2K27G60000C8B002000BMY   0000071900Y
S28931413X6K27GA0000CW000500
S28931413A6K27GA0000CWB000500IWM   0000736800Y
S28931423X6K27GA0000CW000500
S28931423A6K27GA0000CWB000500IWM   0000736400Y
S28931424X1K27GA0000C0002000
S28931432X6K27GA0000CW000500
S28931432A6K27GA0000CWB000500IWM   0000736800Y
S28931437X2K27G60000BZ002000
S28931443X6K27GA0000CW000500
S28931443A6K27GA0000CWB000500IWM   0000736400Y
S28931448A7K27GA000077B002000LMT   0000387100Y
S28931450X2K27G60000C0002000
S28931452X6K27GA0000CW000500
S28931452A6K27GA0000CWB000500IWM   0000736800Y
S28931464X2K27G60000C4002000
S28931462X6K27GA0000CW000500
S28931462A6K27GA0000CWB000500IWM   0000736400Y
S28931466X3K27G60000C8002000
S28931482X6K27GA0000CW000500
S28931482A6K27GA0000CWB000500IWM   0000736800Y
S28931484XCK27GA00004R002000
S28931485A5K27GA00007TS002000FNM   0001383600Y
S28931493X6K27GA0000CW000500
S28931493A6K27GA0000CWB000500IWM   0000736400Y
S28931498XCK27GA00005F002000
S28931502X6K27GA0000CW000500
S28931502A6K27GA0000CWB000500IWM   0000736800Y
S28931506XCK27GA00004U002000
S28931513X6K27GA0000CW000500
S28931513A6K27GA0000CWB000500IWM   0000736400Y
S28931523X6K27GA0000CW000500
S28931523A6K27GA0000CWB000500IWM   0000736800Y
S28931525ABK27GA00016ZS002000UTX   0001553300Y
S28931525ABK27GA000170B002000UTX   0000255100Y
S28931533X6K27GA0000CW000500
S28931533A6K27GA0000CWB000500IWM   0000736400Y
S28931535X1K27GA0000C1002000
S28931535X6K27GA0000CW000500
S28931535A6K27GA0000CWB000500IWM   0000736800Y
S28931535ACK27GA00005GB002000WYE   0000149700Y
S28931543X6K27GA0000CW000500
S28931543A6K27GA0000CWB000500IWM   0000736400Y
S28931546A1K27GA0000C3B002000AFL   0000235300Y
S28931552X1K27GA0000C2002000
S28931555A1K27GA0000C4S002000AFL   0001540400Y
S28931561ABK27GA000171S002000UTX   0001552500Y
S28931585A2K27G60000C9B002000BBT   0000115400Y
S28931592A2K27G60000CAS002000BK    0000476600Y
S28931596A2K27G60000CBB002000BNI   0001062200Y
S28931600X1K27GA0000AP002000
S28931601A2K27G60000CCB002000CAG   0000076100Y
S28931610X2K27G60000C1002000
S28931619P7K27GA000078B000100MDT   0000495000000I000HV2MT
S28931623X2K27G60000C5002000
S28931631X2K27G60000C7002000
S28931639A1K27GA0000C5B002000ABT   0000193100Y
S28931646X3K27G60000C4002000
S28931698A3K27G60000C9S002000COH   0001413200Y
S28931701A3K27G60000CAB002000CTX   0000217400Y
S28931711A3K27G60000CBB002000COP   0000916000Y
S28931741A3K27G60000CCS002000COP   0000938900Y
S28931752A3K27G60000CDB002000CTX   0000218200Y
S28931762A3K27G60000CES002000CTX   0000239700Y
S28931771A3K27G60000CFB002000CVC   0000231000Y
S28932346X1K27GA0000BB002000
S28932365X3K27G60000BI002000
S28932365X5K27GA00007T002000
S28932381XAK27GA0001B7002000
S28932385X5K27GA00006E002000
S28932400X3K27G60000AW002000
S28932421A5K27GA00007US002000FNM   0001378100Y
S28932437XBK27GA00016Z002000
S28932437X4K27GA0000DX000200
S28932437A4K27GA0000DXB000200DIA   0001298900Y
S28932439A4K27GA0000J9S000100DXD   0000500000Y
S28932440A3K27G60000CGB000100DDM   0000801300Y
S28932445XCK27GA00005G002000
S28932449X3K27G6000097002000
S28932453X1K27GA0000C3002000
S28932458X1K27GA0000C4002000
S28932481X7K27GA000077002000
S28932483X3K27G60000C7002000
S28932496XBK27GA000170002000
S28932513A7K27GA000079S002000KSS   0000505300Y
S28932515XBK27GA000171002000
S28932521A7K27GA00007AB002000LMT   0000389300Y
S28932533ABK27GA000172B002000UTX   0000256300Y
S28932542ACK27GA00005HB002000WMT   0000542000Y
S28932560A1K27GA0000C6B002000ABT   0000193700Y
S28932593X6K27GA0000CW000500
S28932593ACK27GA00005IB002000WYE   0000151800Y
S28932593A6K27GA0000CXB000500IWM   0000736800Y
S28932595ABK27GA000173B000100UWM   0000542800Y
S28932595XBK27GA00016Y000100
S28932596ABK27GA000174S000100TWM   0000701800Y
S28932603ACK27GA00005JS002000WYE   0000471400Y
S28932609X1K27GA0000C5002000
S28932609A6K27GA0000CYB002000IWM   0000736800Y
S28932609X6K27GA00009S002000
S28932616X8K27G600005S000500
S28932616X8K27G600005T000100
S28932618X6K27GA000028000500
S28932618A6K27GA000028S000500IWM   0000737400Y
S28932624XBK27GA0000I0000100
S28932624XBK27GA0000YH000100
S28932624XBK27GA0000VX000100
S28932623A6K27GA0000CZS002000IWM   0000737400Y
S28932630ABK27GA000175B000100TWM   0000700300Y
S28932638A1K27GA0000C7B002000AFL   0000238000Y
S28932643A2K27G60000CDS002000BA    0001597900Y
S28932658A1K27GA0000C8S002000AFL   0001536000Y
S28932665A2K27G60000CES002000BBT   0001400200Y
S28932676A1K27GA0000C9B002000ARO   0000300500Y
S28932690A2K27G60000CFS002000CAG   0001361400Y
S28932699A2K27G60000CGS002000BA    0001597100Y
S28932702A3K27G60000CHS002000COH   0001409500Y
S28932710X2K27G60000C3002000
S28932728A3K27G60000CIS002000CTX   0000240500Y
S28932734A2K27G60000CHS002000BBT   0001399400Y
S28932743X2K27G60000BH002000
S28932755A3K27G60000CJB002000CVC   0000230200Y
S28932755X2K27G60000C6002000
S28932767X3K27G60000C9002000
S28933356A1K27GA0000CAS002000AMGN  0000477500Y
S28933361X2K27G60000C8002000
S28933413X7K27GA00007A002000
S28933420XBK27GA00016B002000
S28933422X5K27GA00007U002000
S28933435XBK27GA000172002000
S28933436X6K27GA0000BD002000
S28933439A3K27G60000CKB002000CELG  0000500300Y
S28933466XBK27GA00016A002000
S28933473X1K27GA0000C6002000
S28933480XAK27GA0001BE002000
S28933494X3K27G60000C6002000
S28933503X9K27G60000S4002000
S28933507XAK27GA00019Y002000
S28933510XCK27GA00005I002000
S28933524AAK27GA0001BIB002000SHLD  0000778000Y
S28933525X2K27G60000CD002000
S28933538A7K27GA00007BB002000LMT   0000393100Y
S28933542X2K27G60000C9002000
S28933551X2K27G60000CE002000
S28933560X2K27G60000BN002000
S28933566X2K27G60000CC002000
S28933595X2K27G60000CF002000
S28933595X3K27G60000CH002000
S28933599A5K27GA00007VS002000FNM   0001374100Y
S28933602A3K27G60000CLS002000CMCSK 0000270100Y
S28933611A5K27GA00007WS002000GG    0000435400Y
S28933620A3K27G60000CMB002000COST  0000699400Y
S28933627X1K27GA0000C7002000
S28933640X1K27GA0000C8002000
S28933647X2K27G60000CG002000
S28933647ABK27GA000176S002000UTX   0001546400Y
S28933663ACK27GA00005KB002000WYE   0000152200Y
S28933666ABK27GA000177B002000UTX   0000259100Y
S28933671A1K27GA0000CBB002000AFL   0000239000Y
S28933679X2K27G60000CH002000
S28933687A1K27GA0000CCS002000AFL   0001533200Y
S28933692ABK27GA000178S002000UTX   0001545600Y
S28933699A1K27GA0000CDB002000ABT   0000196100Y
S28933715A2K27G60000CIB002000BBT   0000118100Y
S28933719A3K27G60000CNB002000COH   0000123300Y
S28933736A2K27G60000CJB002000BDX   0000777300Y
S28933758A2K27G60000CKB002000CAG   0000078200Y
S28933765A3K27G60000COS002000CVC   0000260900Y
S28933778A2K27G60000CLS002000CAG   0001355700Y
S28933787A3K27G60000CPB002000CVS   0000148500Y
S28933814A3K27G60000CQB002000COH   0000124100Y
S28933818A3K27G60000CRS002000CVS   0001429100Y
S28933832A3K27G60000CSS002000COH   0001404100Y
S28933861A3K27G60000CTS002000CVC   0000260100Y
S28934350X4K27GA0000FR002000
S28934385X5K27GA00007V002000
S28934388X7K27GA00007B002000
S28934410XBK27GA0000XT002000
S28934410AAK27GA0001BJB002000SPLS  0000075000Y
S28934412XBK27GA000176002000
S28934420XCK27GA00005K002000
S28934436X1K27GA0000CB002000
S28934436X1K27GA0000CC002000
S28934436XBK27GA000177002000
S28934449XBK27GA000178002000
S28934452X1K27GA0000B0002000
S28934456A3K27G60000CUB002000CTSH  0000106600Y
S28934458X1K27GA0000CD002000
S28934461X2K27G60000BY002000
S28934503A9K27G60000SCB002000PDLI  0000035800Y
S28934504A2K27G60000CMB002000BMY   0000073700Y
S28934513X3K27G60000CP002000
S28934529X3K27G60000CR002000
S28934528AAK27GA0001BKB002000SNDK  0000243500Y
S28934542A5K27GA00007XS002000FNM   0001368600Y
S28934560A7K27GA00007CB002000LMT   0000395300Y
S28934589X2K27G60000BX002000
S28934593X2K27G60000CL002000
S28934599X3K27G60000CS002000
S28934604ABK27GA000179S002000TGT   0000618700Y
S28934606A6K27GA0000D0B002000JNJ   0000644200Y
S28934610ABK27GA00017AB002000UTX   0000260300Y
S28934625ABK27GA00017BS002000TGT   0000617900Y
S28934654A1K27GA0000CEB002000ABT   0000196800Y
S28934656ACK27GA00005LB002000WYE   0000154200Y
S28934682A1K27GA0000CFB002000AFL   0000241700Y
S28934684A2K27G60000CNS002000BA    0001591700Y
S28934698A1K27GA0000CGS002000AFL   0001528800Y
S28934701A2K27G60000COB002000BBT   0000118300Y
S28934715A2K27G60000CPS002000BBT   0001391100Y
S28934717A2K27G60000CQS002000BA    0001590900Y
S28934732A2K27G60000CRB002000BDX   0000776700Y
S28934732A2K27G60000CSS002000BBT   0001390300Y
S28934735A2K27G60000CTB002000CAG   0000078000Y
S28934747A2K27G60000CUS002000CAG   0001351600Y
S28935065X5K27GA00003P000100
S28935065A5K27GA00003PS000100GOOG  0005792000Y
S28935135X4K27GA0000IP000100
S28935353X1K27GA000072002000
S28935356X5K27GA00007X002000
S28935405X6K27GA0000BE002000
S28935408X7K27GA00007C002000
S28935410A4K27GA0000JAS002000EBAY  0000328000Y
S28935419X7K27GA00006A002000
S28935434XBK27GA00017A002000
S28935460XCK27GA00005L002000
S28935462X1K27GA0000CE002000
S28935476X2K27G60000CN002000
S28935478X1K27GA0000CF002000
S28935488X1K27GA0000CG002000
S28935491X2K27G60000CP002000
S28935500X2K27G60000CQ002000
S28935511X2K27G60000CI002000
S28935518X2K27G60000CS002000
S28935521X2K27G60000CU002000
S28935524X3K27G60000CN002000
S28935528X2K27G60000CK002000
S28935532X3K27G60000CQ002000
S28935540A5K27GA00007YS002000FNM   0001364600Y
S28935544A7K27GA00007DB002000LMT   0000399100Y
S28935560ABK27GA00017CS002000UTX   0001539500Y
S28935560ABK27GA00017DB002000TGT   0000522400Y
S28935589ACK27GA00005MB002000WYE   0000154600Y
S28935597A1K27GA0000CHB002000AFL   0000242700Y
S28935600A1K27GA0000CIS002000AFL   0001526100Y
S28935612A1K27GA0000CJB002000ARO   0000299900Y
S28935618ABK27GA00017EB002000UTX   0000263100Y
S28935620A2K27G60000CVB002000AXP   0000420000Y
S28935630ABK27GA00017FS002000UTX   0001538700Y
S28935639A1K27GA0000CKB002000ABT   0000199200Y
S28935643A3K27G60000CVS002000COH   0001395900Y
S28935653A2K27G60000CWB002000AXP   0000420800Y
S28935670A2K27G60000CXS002000CAG   0001345900Y
S28935670A3K27G60000CWB002000CVS   0000150900Y
S28935681A3K27G60000CXS002000CVS   0001420500Y
S28935687A3K27G60000CYS002000COH   0001395100Y
S28935695A3K27G60000CZB002000DAL   0000017300Y
S28935702A3K27G60000D0B002000CVS   0000151700Y
S28935712A3K27G60000D1S002000DAL   0000085300Y
S28935723A3K27G60000D2S002000CVS   0001419700Y
S28935744A3K27G60000D3B002000DAL   0000018100Y
S28936288ABK27GA00017GB001000SSO   0000764700Y
S28936288XBK27GA000162001000
S28936350A1K27GA0000CLB002000AMZN  0000802100Y
S28936394X5K27GA00007Y002000
S28936400X2K27G60000CM002000
S28936409X7K27GA000062002000
S28936409X4K27GA0000IN002000
S28936413XBK27GA00017C002000
S28936421XCK27GA00005M002000
S28936436X1K27GA0000CH002000
S28936437A5K27GA00007ZS002000FNM   0001359100Y
S28936437X1K27GA0000CI002000
S28936440X2K27G60000CO002000
S28936439X1K27GA00008S002000
S28936447X2K27G60000CT002000
S28936452X3K27G60000CV002000
S28936452A6K27GA0000D1S002000JNJ   0000688400Y
S28936462X3K27G60000CW002000
S28936464X3K27G60000CX002000
S28936478X7K27GA00007D002000
S28936487XBK27GA00017E002000
S28936492A7K27GA00007EB002000LMT   0000401300Y
S28936505XBK27GA00017F002000
S28936505A7K27GA00007FB002000KSS   0000459100Y
S28936512ABK27GA00017HB002000UTX   0000264300Y
S28936536X1K27GA0000CK002000
S28936542A1K27GA0000CMB002000ABT   0000199900Y
S28936550ACK27GA00005NB002000WYE   0000156600Y
S28936605A1K27GA0000CNB002000AFL   0000245400Y
S28936610A2K27G60000CYS002000BA    0001585500Y
S28936626A1K27GA0000COS002000AFL   0001521700Y
S28936645A2K27G60000CZS002000BA    0001584700Y
S28936645A2K27G60000D0S002000BBT   0001381900Y
S28936675A2K27G60000D1B002000BBT   0000121000Y
S28936683A2K27G60000D2S002000CAG   0001341900Y
S28936690X2K27G60000CX002000
S28936696A3K27G60000D4B002000COH   0000126300Y
S28936703X3K27G60000CY002000
S28936710X3K27G60000D0002000
S28936719X3K27G60000D2002000
S28936732A2K27G60000D3S002000BBT   0001381100Y
S28937259X4K27GA0000IK000100
S28937259A4K27GA0000JBS000100DRYS  0001073400Y
S28937263A4K27GA0000JCB000100DRYS  0001070100Y
S28937346XAK27GA0001BI002000
S28937388X3K27G60000CU002000
S28937395X5K27GA00007Z002000
S28937412X5K27GA000070002000
S28937430X7K27GA00007E002000
S28937441XBK27GA00017H002000
S28937446XCK27GA00005N002000
S28937462X1K27GA0000CM002000
S28937464X1K27GA0000CN002000
S28937478X1K27GA0000CO002000
S28937485X2K27G60000CY002000
S28937487X2K27G600009B002000
S28937498X2K27G60000CZ002000
S28937499X2K27G60000D0002000
S28937502X2K27G60000D3002000
S28937510X2K27G60000D2002000
S28937521A2K27G60000D4B002000BMY   0000075600Y
S28937525A5K27GA000080S002000FNM   0001355100Y
S28937537A4K27GA0000JDB002000EMR   0000556600Y
S28937543A7K27GA00007GS002000MMM   0000815400Y
S28937555ABK27GA00017IS002000UTX   0001532600Y
S28937557A7K27GA00007HB002000LMT   0000405100Y
S28937570ACK27GA00005OB002000WYE   0000157000Y
S28937578A1K27GA0000CPB002000AFL   0000246400Y
S28937581A1K27GA0000CQS002000AFL   0001518900Y
S28937587A1K27GA0000CRB002000ANF   0000723100Y
S28937594ABK27GA00017JB002000UTX   0000267100Y
S28937596A2K27G60000D5B002000BBT   0000121100Y
S28937606A2K27G60000D6B002000CAG   0000080000Y
S28937607ABK27GA00017KS002000UTX   0001531800Y
S28937616A1K27GA0000CSB002000ABT   0000202200Y
S28937616A3K27G60000D5S002000COH   0001386900Y
S28937627A2K27G60000D7B002000CAG   0000080800Y
S28937632A3K27G60000D6B002000CVS   0000153200Y
S28937640A3K27G60000D7S002000CVS   0001411800Y
S28937645A2K27G60000D8S002000CAG   0001336200Y
S28937658A3K27G60000D8B002000COH   0000128100Y
S28937668A3K27G60000D9B002000DD    0000462000Y
S28937675A3K27G60000DAS002000COH   0001386100Y
S28937688A3K27G60000DBS002000DD    0001434800Y
S28937690A3K27G60000DCB002000CVS   0000154000Y
S28937709A3K27G60000DDS002000CVS   0001411000Y
S28938256AAK27GA0001BLS005000SPY   0001426100Y
S28938256XAK27GA0001B9005000
S28938351X6K27GA0000BZ002000
S28938354XAK27GA0001BJ002000
S28938401AAK27GA0001BMB002000SHLD  0000780900Y
S28938413X5K27GA000080002000
S28938430A5K27GA000081S002000FNM   0001349600Y
S28938430XBK27GA00017I002000
S28938438XCK27GA00005O002000
S28938446X1K27GA0000CP002000
S28938463X1K27GA0000CQ002000
S28938464A3K27G60000DEB002000CTSH  0000110000Y
S28938479X3K27G60000D4002000
S28938481X7K27GA00007H002000
S28938496XBK27GA00017J002000
S28938501X3K27G60000D5002000
S28938505A5K27GA000082S002000GM    0000226800Y
S28938512X3K27G60000D6002000
S28938519X3K27G60000D7002000
S28938521XBK27GA00017K002000
S28938531X3K27G60000DB002000
S28938556A7K27GA00007IB002000LMT   0000407300Y
S28938561X1K27GA0000CS002000
S28938597ACK27GA00005PB002000WYE   0000159000Y
S28938612A1K27GA0000CTB002000AFL   0000249100Y
S28938619ABK27GA00017LB002000UTX   0000268300Y
S28938632X1K27GA0000A9002000
S28938657A1K27GA0000CUS002000AFL   0001514500Y
S28938661A1K27GA0000CVB002000ABT   0000202900Y
S28938678A2K27G60000D9B002000AZN   0000422700Y
S28938694X2K27G60000D1002000
S28938700A2K27G60000DAS002000BA    0001579300Y
S28938710A2K27G60000DBS002000BA    0001578500Y
S28938716A2K27G60000DCS002000BBT   0001372700Y
S28938720X2K27G60000D8002000
S28938731X3K27G60000DA002000
S28938738A2K27G60000DDS002000CAG   0001332100Y
S28938745X3K27G60000DC002000
S28938750A2K27G60000DES002000BBT   0001371900Y
S28938759X3K27G60000DD002000
S28938782A3K27G60000DFS002000DAL   0000084500Y
S28938788A3K27G60000DGB002000DE    0000793600Y
S28939194XAK27GA0000E4001000
S28939194AAK27GA0000E4B001000SPY   0001425800Y
S28939194XAK27GA0001B2003000
S28939194XAK27GA0000F2000500
S28939194AAK27GA0000F2B000500SPY   0001425800Y
S28939194X4K27GA0000I9000200
S28939194AAK27GA0001BNB003000SPY   0001425700Y
S28939194XAK27GA0001AZ003000
S28939194XAK27GA0001B3003000
S28939194XAK27GA0000FD000500
S28939194AAK27GA0000FDB000500SPY   0001425800Y
S28939194XAK27GA0000E5001000
S28939194AAK27GA0000E5S001000SPY   0001426400Y
S28939194XAK27GA0000O6000500
S28939194AAK27GA0000O6S000500SPY   0001426400Y
S28939194XAK27GA0001B0003000
S28939194AAK27GA0001BOB003000SPY   0001425700Y
S28939194XAK27GA00015B001000
S28939194XAK27GA0001B5001000
S28939194XAK27GA0001B1001000
S28939195AAK27GA0001BPB002000SPY   0001425600Y
S28939195AAK27GA0001BQS000500SPY   0001426300Y
S28939195X9K27G60000G6002000
S28939195A9K27G60000G6B002000QQQQ  0000495800Y
S28939195X9K27G60000G3002000
S28939195A9K27G60000G3S002000QQQQ  0000496400Y
S28939196AAK27GA0001BRS003000SPY   0001426600Y
S28939196X4K27GA0000ID000200
S28939196A4K27GA0000IDS000200DIA   0001299400Y
S28939196AAK27GA0001BSS003000SPY   0001426600Y
S28939196ABK27GA00017MB001000SSO   0000764500Y
S28939196AAK27GA0001BTS001000SPY   0001426400Y
S28939196AAK27GA0001BUS001000SPY   0001426200Y
S28939197AAK27GA0001BVS000500SPY   0001426400Y
S28939197XAK27GA0001BB002500
S28939198XAK27GA0001BA000500
S28939198AAK27GA0001BWB000500SPY   0001425600Y
S28939198AAK27GA0001BXB002500SPY   0001425600Y
S28939198XAK27GA0001BF002500
S28939198XAK27GA0001BL005000
S28939198AAK27GA0001BYS000500SPY   0001426100Y
S28939199XAK27GA0000E5001000
S28939199AAK27GA0000E5S001000SPY   0001426000Y
S28939199AAK27GA0001BZS005000SPY   0001426200Y
S28939200X4K27GA0000DB000100
S28939200A4K27GA0000JES000200DIA   0001299500Y
S28939201X3K27G60000AS000100
S28939202A4K27GA0000JFB000100DXD   0000499000Y
S28939202A3K27G60000DHS000100DDM   0000802800Y
S28939206A6K27GA0000D2B002000IWM   0000736800Y
S28939206X6K27GA00008L002000
S28939224X6K27GA00005F000500
S28939224A6K27GA00005FB000500IWM   0000736900Y
S28939224X6K27GA0000BI002000
S28939227XBK27GA0000VR000100
S28939227ABK27GA00017NB000100UWM   0000543000Y
S28939227XBK27GA000174000100
S28939227ABK27GA00017OS000100TWM   0000701600Y
S28939227AAK27GA0001C0B002000SPY   0001425600Y
S28939228A9K27G60000SDB002000QQQQ  0000495600Y
S28939228XAK27GA0000F7000500
S28939228AAK27GA0000F7B000500SPY   0001425800Y
S28939228XAK27GA0001BY000500
S28939228AAK27GA0001BYS000500SPY   0001426500Y
S28939228XAK27GA0000E5001000
S28939228AAK27GA0000E5S001000SPY   0001426400Y
S28939229XAK27GA00016S001000
S28939228X6K27GA00009H002000
S28939228A6K27GA0000D3S002000IWM   0000737900Y
S28939230X9K27G60000S8001000
S28939230A9K27G60000SEB001000QLD   0000889600Y
S28939229X6K27GA00005F000500
S28939229A6K27GA00005FB000500IWM   0000736500Y
S28939230XAK27GA00015A001000
S28939230XAK27GA0001BY000500
S28939230AAK27GA0001BYS000500SPY   0001426100Y
S28939230AAK27GA0001C1B001000SPY   0001425800Y
S28939232XBK27GA00017G001000
S28939231XAK27GA0000QA001000
S28939231AAK27GA0001C2S001000SDS   0000548600Y
S28939232ABK27GA00017PB001000SSO   0000764800Y
S28939232XBK27GA00017N000100
S28939232XBK27GA00017O000100
S28939232A9K27G60000SFB001000QQQQ  0000495400Y
S28939232A9K27G60000SGB001000QQQQ  0000495500Y
S28939233X9K27G60000SF001000
S28939233X9K27G60000SG001000
S28939234ABK27GA00017QS000100TWM   0000701800Y
S28939232X6K27GA00005F000500
S28939232A6K27GA00005FB000500IWM   0000736900Y
S28939234ABK27GA00017RB000100UWM   0000543000Y
S28939235XBK27GA00017Q000100
S28939235ABK27GA00017SS000100TWM   0000701600Y
S28939239X9K27G60000SE001000
S28939239XBK27GA0000YC001000
S28939239A9K27G60000SHB001000QLD   0000889700Y
S28939239A9K27G60000SIS000100QID   0000382000Y
S28939239A9K27G60000SJB001000QQQQ  0000495500Y
S28939239XAK27GA00016V000100
S28939239A9K27G60000SKB001000QQQQ  0000495400Y
S28939239XAK27GA00016W001000
S28939240XAK27GA0001BU001000
S28939241ABK27GA00017TS001000SSO   0000765700Y
S28939241AAK27GA0001C3B001000SDS   0000547300Y
S28939243X9K27G60000SJ001000
S28939243X9K27G60000SK001000
S28939242X6K27GA00005F000500
S28939242A6K27GA00005FB000500IWM   0000736500Y
S28939250X9K27G60000PE002000
S28939250X9K27G60000F8003200
S28939250A9K27G60000F8S003200QQQQ  0000496500Y
S28939249X6K27GA00005F000500
S28939249A6K27GA00005FB000500IWM   0000736900Y
S28939251A9K27G60000SLB002000QQQQ  0000495900Y
S28939252X9K27G60000RD001000
S28939250X6K27GA00005F000500
S28939250A6K27GA00005FB000500IWM   0000736500Y
S28939252A9K27G60000SMB001000QLD   0000889600Y
S28939254A9K27G60000SNB001000QQQQ  0000495400Y
S28939252X6K27GA00005F000500
S28939252A6K27GA00005FB000500IWM   0000736900Y
S28939254X9K27G60000SN001000
S28939256A9K27G60000SOB001000QQQQ  0000495400Y
S28939255X6K27GA00005F000500
S28939255A6K27GA00005FB000500IWM   0000736500Y
S28939262XAK27GA0001AP001000
S28939262AAK27GA0001C4S001000SPY   0001426300Y
S28939261X6K27GA00005F000500
S28939261A6K27GA00005FB000500IWM   0000736900Y
S28939261X6K27GA00002A000500
S28939261A6K27GA00002AS000500IWM   0000737500Y
S28939263X9K27G60000SO001000
S28939264AAK27GA0001C5S001000SPY   0001426300Y
S28939263X6K27GA00002A000500
S28939263A6K27GA00002AS000500IWM   0000737100Y
S28939270X6K27GA00003L000100
S28939271ABK27GA00017US000100UWM   0000544000Y
S28939278XBK27GA00017M001000
S28939278ABK27GA00017VB001000SSO   0000764600Y
S28939292A8K27G600005US000500MZZ   0000493600Y
S28939292X8K27G600005F000100
S28939292A8K27G600005VB000100MVV   0000806700Y
S28939336XAK27GA0000F7000500
S28939336AAK27GA0000F7B000500SPY   0001425900Y
S28939336XAK27GA0001C1001000
S28939336AAK27GA0001C1B001000SPY   0001425900Y
S28939344X6K27GA00002A000500
S28939344A6K27GA00002AS000500IWM   0000737500Y
S28939349X3K27G60000CK002000
S28939354X9K27G60000R1002000
S28939384XBK27GA00017U000100
S28939384XBK27GA000175000100
S28939383A6K27GA0000D4S002000IWM   0000737500Y
S28939386ABK27GA00017WS000100UWM   0000544100Y
S28939384A6K27GA0000D5S000100IWM   0000737700Y
S28939389X6K27GA0000D5000100
S28939400X4K27GA0000IE000200
S28939400A4K27GA0000IEB000200DIA   0001299000Y
S28939399A6K27GA0000D6B002000IWM   0000736900Y
S28939400X6K27GA00009O002000
S28939401A4K27GA0000JGS000100DOG   0000598200Y
S28939401A4K27GA0000JHS000100DXD   0000499900Y
S28939401X4K27GA0000DW000100
S28939402X3K27G600009W000100
S28939402A3K27G60000DIB000100DDM   0000801500Y
S28939409A6K27GA0000D7B002000IMCL  0000352100Y
S28939424X2K27G60000D4002000
S28939439X7K27GA00007I002000
S28939440A8K27G600005WS000500MZZ   0000493500Y
S28939440X8K27G600005M000100
S28939440X8K27G600003O000500
S28939440A8K27G600005XB000100MVV   0000806800Y
S28939444X5K27GA000081002000
S28939452XBK27GA000179002000
S28939456XBK27GA00017B002000
S28939463AAK27GA0001C6B002000SPLS  0000078100Y
S28939466XBK27GA00017L002000
S28939483AAK27GA0001C7B000500SPY   0001425700Y
S28939483XAK27GA0001BW000500
S28939484XCK27GA00004B002000
S28939490XCK27GA00005P002000
S28939509X1K27GA0000CV002000
S28939529X2K27G60000DA002000
S28939532X1K27GA0000A4002000
S28939539X2K27G60000D5002000
S28939546X2K27G60000DC002000
S28939548X1K27GA0000CT002000
S28939554X2K27G60000D6002000
S28939558X2K27G60000DD002000
S28939558X1K27GA0000CU002000
S28939564X2K27G600009O002000
S28939589X2K27G60000DB002000
S28939589X2K27G60000DE002000
S28939589X2K27G60000CJ002000
S28939595X2K27G60000D7002000
S28939607X3K27G60000D8002000
S28939607AAK27GA0001C8B002500SPY   0001425700Y
S28939607AAK27GA0001C9B005000SPY   0001425700Y
S28939608XAK27GA0001BX002500
S28939608XAK27GA0001BG005000
S28939623A5K27GA000083S002000FNM   0001345600Y
S28939622A7K27GA00007JB002000LMT   0000411100Y
S28939640X5K27GA00006S000100
S28939642A5K27GA000084B000100FXP   0000652100Y
S28939643ABK27GA00017XB002000UTX   0000271100Y
S28939645ABK27GA00017YS002000UTX   0001525600Y
S28939651ABK27GA00017ZS002000UTX   0001524800Y
S28939666ACK27GA00005QB002000WYE   0000159400Y
S28939671A1K27GA0000CWB002000ABT   0000205300Y
S28939675A1K27GA0000CXB002000AFL   0000250200Y
S28939682A1K27GA0000CYS002000ALL   0000523700Y
S28939686A1K27GA0000CZS002000AFL   0001511700Y
S28939704A2K27G60000DFB002000BBT   0000123800Y
S28939716A3K27G60000DJB002000COH   0000129300Y
S28939724A2K27G60000DGS002000CAG   0001326400Y
S28939730A3K27G60000DKS002000COH   0001377900Y
S28939731AAK27GA0001CAS000500SPY   0001426200Y
S28939736A3K27G60000DLS002000COH   0001377100Y
S28939742A3K27G60000DMB002000CVS   0000155600Y
S28939750A3K27G60000DNB002000CVS   0000156400Y
S28939753A3K27G60000DOS002000CVS   0001403100Y
S28939762A3K27G60000DPS002000CVS   0001402300Y
S28939769A3K27G60000DQS002000DD    0001426500Y
S28939784A3K27G60000DRS002000DE    0000837600Y
S28939784A3K27G60000DSB002000DD    0000463000Y
S28939883XAK27GA0001C3001000
S28939883XBK27GA00017T001000
S28939885AAK27GA0001CBB001000SDS   0000547200Y
S28939885ABK27GA000180S001000SSO   0000765800Y
S28940046AAK27GA0001CCS002500SPY   0001426200Y
S28940060X5K27GA000084000100
S28940062A5K27GA000085B000100FXP   0000651800Y
S28940347X9K27G60000F8003200
S28940347A9K27G60000F8S003200QQQQ  0000496000Y
S28940351X6K27GA0000CV002000
S28940356X1K27GA0000AJ002000
S28940362A3K27G60000DTB002000CELG  0000502800Y
S28940378A2K27G60000DHB002000BMY   0000077400Y
S28940377X5K27GA000083002000
S28940430A9K27G60000SPB002000PETM  0000210200Y
S28940453X5K27GA00007K002000
S28940459XBK27GA00017Y002000
S28940465XCK27GA00005Q002000
S28940469XCK27GA000054002000
S28940473X1K27GA0000CX002000
S28940476X7K27GA00006B002000
S28940476X1K27GA0000CZ002000
S28940489X7K27GA00007J002000
S28940492X2K27G60000CV002000
S28940496X2K27G60000CR002000
S28940495A5K27GA000086S002000FNM   0001340100Y
S28940496X3K27G60000DK002000
S28940503X3K27G60000DM002000
S28940512X3K27G60000DO002000
S28940516X3K27G60000DQ002000
S28940521A7K27GA00007KB002000LMT   0000413300Y
S28940524ABK27GA000181S002000TGT   0000616400Y
S28940531XBK27GA00017X002000
S28940533ABK27GA000182S002000TGT   0000617200Y
S28940542ABK27GA000183B002000UTX   0000272300Y
S28940544X5K27GA000085000100
S28940545XBK27GA00017Z002000
S28940546A5K27GA000087B000100FXP   0000651000Y
S28940561ACK27GA00005RS002000WMT   0000580900Y
S28940590A1K27GA0000D0B002000ABT   0000206000Y
S28940595AAK27GA0001CDS002500SPY   0001426100Y
S28940596XAK27GA0001CC002500
S28940608ACK27GA00005SB002000WYE   0000161400Y
S28940617X1K27GA0000CW002000
S28940621A2K27G60000DIS002000BA    0001573100Y
S28940634A2K27G60000DJB002000BBT   0000124000Y
S28940640A1K27GA0000D1S002000ACN   0000406800Y
S28940648A2K27G60000DKS002000BBT   0001363600Y
S28940661A2K27G60000DLB002000CAG   0000081900Y
S28940661A1K27GA0000D2B002000AFL   0000252800Y
S28940667A2K27G60000DMS002000CAG   0001322400Y
S28940682A2K27G60000DNB002000CAT   0000820100Y
S28940681A1K27GA0000D3S002000AFL   0001507300Y
S28940689X2K27G60000CW002000
S28940734A2K27G60000DOS002000BA    0001572300Y
S28940742A2K27G60000DPS002000BBT   0001362800Y
S28940745X2K27G60000DG002000
S28940750X3K27G60000DL002000
S28940754X3K27G60000DN002000
S28940759X3K27G60000DP002000
S28940810A9K27G60000SQB001000QQQQ  0000495400Y
S28940810A9K27G60000SRB001000QQQQ  0000495500Y
S28941034ABK27GA000184B000500TSEM  0000011500Y
S28941251X4K27GA0000JB000100
S28941251A4K27GA0000JIS000100DRYS  0001074900Y
S28941277X4K27GA0000JI000100
S28941277P4K27GA0000JKB000100DRYS  0001074000000A101NJERG
S28941361A6K27GA0000D8S002000IMCL  0000508200Y
S28941367X5K27GA000086002000
S28941416A5K27GA000088S002000FNM   0001336100Y
S28941426X3K27G6000098002000
S28941431X5K27GA00006H002000
S28941433A5K27GA000089B002000GM    0000181400Y
S28941434X7K27GA00007K002000
S28941437X3K27G60000DE002000
S28941456XBK27GA000183002000
S28941470X1K27GA0000D0002000
S28941471A1K27GA0000D4B002000APOL  0000414500Y
S28941492A7K27GA00007LS002000KSS   0000504200Y
S28941497X2K27G600007P002000
S28941509X2K27G60000DI002000
S28941516X2K27G60000DK002000
S28941519X2K27G6000084002000
S28941525X2K27G60000DM002000
S28941536A7K27GA00007MB002000LMT   0000417100Y
S28941553XCK27GA00005S002000
S28941556X3K27G60000DJ002000
S28941582X3K27G60000CZ002000
S28941592ABK27GA000185S002000UTX   0001518700Y
S28941601ACK27GA00005TB002000WYE   0000161800Y
S28941607ABK27GA000186B002000UTX   0000275100Y
S28941609ACK27GA00005US002000WYE   0000471700Y
S28941615X1K27GA0000D2002000
S28941621A1K27GA0000D5B002000AFL   0000253900Y
S28941621X1K27GA0000D3002000
S28941632A1K27GA0000D6S002000AFL   0001504600Y
S28941637ABK27GA000187S002000UTX   0001517900Y
S28941646A2K27G60000DQB002000AXP   0000421300Y
S28941645A1K27GA0000D7B002000ABT   0000208400Y
S28941656X2K27G60000DO002000
S28941662X2K27G60000DF002000
S28941665A2K27G60000DRB002000BDX   0000778100Y
S28941674X2K27G60000DP002000
S28941689A3K27G60000DUS002000COH   0001368800Y
S28941691A2K27G60000DSB002000AXP   0000422100Y
S28941697X2K27G60000A8002000
S28941703A3K27G60000DVB002000CVS   0000157900Y
S28941711A2K27G60000DTB002000BDX   0000778900Y
S28941711XAK27GA00018B000800
S28941716A3K27G60000DWS002000CVS   0001394500Y
S28941716AAK27GA0001CEB000700SPY   0001419900Y
S28941730A3K27G60000DXS002000DD    0001418100Y
S28941730A2K27G60000DUB002000CAG   0000083400Y
S28941752A3K27G60000DYB002000DHI   0000137800Y
S28941753A2K27G60000DVS002000CAG   0001316700Y
S28941768A3K27G60000DZB002000COH   0000132100Y
S28941797X3K27G60000D3002000
S28941806A3K27G60000E0S002000COH   0001368000Y
S28941845A1K27GA0000D8B000100AAPL  0001828700Y
S28942347X1K27GA0000CA002000
S28942363XAK27GA0001BM002000
S28942366X2K27G60000DH002000
S28942368X9K27G60000HG001000
S28942380X1K27GA0000BZ002000
S28942380X5K27GA00006Y002000
S28942416X5K27GA000088002000
S28942415X7K27GA00006V002000
S28942423X7K27GA00007M002000
S28942449XBK27GA000185002000
S28942455XBK27GA000186002000
S28942476A3K27G60000E1S002000COST  0000743600Y
S28942476XBK27GA000187002000
S28942475XCK27GA000057002000
S28942482XCK27GA00005T002000
S28942499X1K27GA0000D7002000
S28942501X1K27GA0000D5002000
S28942510X1K27GA0000D6002000
S28942523A3K27G60000E2B002000CTSH  0000113500Y
S28942524X2K27G60000DJ002000
S28942535A5K27GA00008AS002000FNM   0001330500Y
S28942537X2K27G600008J002000
S28942547X2K27G60000DL002000
S28942554X3K27G60000DU002000
S28942564X3K27G60000DV002000
S28942608ACK27GA00005VB002000WYE   0000163800Y
S28942628X3K27G60000DW002000
S28942630A1K27GA0000D9B002000AFL   0000256500Y
S28942632X3K27G60000DX002000
S28942644X2K27G60000A7002000
S28942653A5K27GA00008BB002000GS    0001819700Y
S28942659A7K27GA00007NB002000LMT   0000419300Y
S28942667X2K27G60000AC002000
S28942675X2K27G60000DV002000
S28942682A1K27GA0000DAS002000AFL   0001500200Y
S28942684ABK27GA000188B002000UTX   0000276300Y
S28942688X3K27G60000E0002000
S28942711A1K27GA0000DBB002000ABT   0000209000Y
S28942712A2K27G60000DWS002000BA    0001566100Y
S28942727A2K27G60000DXB002000BBT   0000126700Y
S28942739A2K27G60000DYB002000BA    0000855000Y
S28942750A2K27G60000DZS002000BBT   0001353600Y
S28942750A2K27G60000E0S002000BA    0001566900Y
S28942762A2K27G60000E1S002000BBT   0001354400Y
S28942762A2K27G60000E2S002000BK    0000475200Y
S28942775A2K27G60000E3S002000BDX   0000900000Y
S28942776A3K27G60000E3B002000CVS   0000159900Y
S28942789A2K27G60000E4S002000CAG   0001312600Y
S28942797A3K27G60000E4S002000CVS   0001389300Y
S28942801A3K27G60000E5B002000COH   0000132300Y
S28943361XAK27GA0001C6002000
S28943362X5K27GA00008A002000
S28943396X7K27GA00007N002000
S28943404A2K27G60000E5B002000BMY   0000079200Y
S28943405XBK27GA000188002000
S28943424X1K27GA00007S002000
S28943427X1K27GA0000DB002000
S28943437XAK27GA0001BK002000
S28943446X2K27G60000E0002000
S28943455A1K27GA0000DCS002000AMGN  0000475000Y
S28943463X2K27G60000E1002000
S28943483A5K27GA00008CS002000GG    0000434300Y
S28943490X2K27G60000E4002000
S28943491AAK27GA0001CFS000500SPY   0001426100Y
S28943491XAK27GA0001CA000500
S28943492AAK27GA0001CGB002000SHLD  0000783800Y
S28943492XCK27GA00005V002000
S28943503A5K27GA00008DS002000FNM   0001326600Y
S28943509X9K27G60000F8003200
S28943509A9K27G60000F8S003200QQQQ  0000496500Y
S28943510X9K27G60000EU002000
S28943510A9K27G60000EUB002000QQQQ  0000495900Y
S28943528A1K27GA0000DDS002000APOL  0000527400Y
S28943529A7K27GA00007OB002000LMT   0000423100Y
S28943540X1K27GA0000D9002000
S28943554X1K27GA0000DA002000
S28943562A7K27GA00007PB002000LPNT  0000209200Y
S28943581X2K27G60000DW002000
S28943596X2K27G60000DZ002000
S28943595ABK27GA000189B002000UTX   0000279100Y
S28943597ABK27GA00018AS002000UTX   0001511800Y
S28943598ABK27GA00018BS002000UTX   0001511000Y
S28943618ACK27GA00005WB002000WMT   0000541900Y
S28943634ACK27GA00005XB002000WYE   0000164200Y
S28943635A1K27GA0000DEB002000ABT   0000211400Y
S28943653X2K27G60000DU002000
S28943664A1K27GA0000DFB002000AFL   0000257600Y
S28943675A1K27GA0000DGS002000AFL   0001497400Y
S28943685X3K27G60000DZ002000
S28943697A2K27G60000E6B002000BK    0000430400Y
S28943717A2K27G60000E7B002000BBT   0000126800Y
S28943722X3K27G60000E3002000
S28943731X3K27G60000E4002000
S28943732A4K27GA0000JLB000100DXD   0000499300Y
S28943739A2K27G60000E8B002000BNI   0001063600Y
S28943741A2K27G60000E9S002000BNI   0001128700Y
S28943743A2K27G60000EAB002000CAG   0000083900Y
S28943754A3K27G60000E6S002000COH   0001359800Y
S28943755A2K27G60000EBS002000CAG   0001306900Y
S28943770A3K27G60000E7S002000COH   0001359000Y
S28943770A3K27G60000E8B002000CVS   0000160300Y
S28943785A3K27G60000E9S002000CVS   0001385800Y
S28943785A3K27G60000EAB002000DAL   0000019700Y
S28943835ABK27GA00018CS001000SSO   0000765700Y
S28943835XBK27GA000180001000
S28943835AAK27GA0001CHB001000SDS   0000547300Y
S28943835XAK27GA0001CB001000
S28943840E4K27GA0000HI00010000004AQ0000A
S28943840E4K27GA0000JC00010000004AQ0000B
S28943841A4K27GA0000JNS000100DRYS  0001074900Y
S28944359X5K27GA00008D002000
S28944402XAK27GA000125002000
S28944403A5K27GA00008ES002000FNM   0001321000Y
S28944406X4K27GA0000GO002000
S28944417X5K27GA00007R002000
S28944426X9K27G60000SC002000
S28944428XBK27GA000182002000
S28944429X7K27GA00007O002000
S28944433XBK27GA00018A002000
S28944448XCK27GA00005X002000
S28944449XBK27GA000181002000
S28944449AAK27GA0001CIB002000SPLS  0000081300Y
S28944453X1K27GA0000DF002000
S28944462X1K27GA0000DG002000
S28944465XBK27GA000189002000
S28944480XAK27GA0001B6001000
S28944480AAK27GA0001CJB001000SPY   0001425700Y
S28944485XBK27GA00018B002000
S28944488X3K27G60000E5002000
S28944489A1K27GA0000DHB002000APPX  0000097900Y
S28944499X3K27G60000E6002000
S28944516X3K27G60000E8002000
S28944519X3K27G60000E9002000
S28944533A7K27GA00007QB002000LMT   0000425300Y
S28944532ACK27GA00005YB002000WYE   0000166300Y
S28944540AAK27GA0001CKB002000SNDK  0000245900Y
S28944547X1K27GA0000DE002000
S28944586A1K27GA0000DIB002000AFL   0000260200Y
S28944593X2K27G60000DX002000
S28944599X2K27G60000EB002000
S28944603X3K27G60000E7002000
S28944610A1K27GA0000DJS002000AFL   0001493000Y
S28944620A2K27G60000ECS002000BA    0001559900Y
S28944629A2K27G60000EDS002000BBT   0001344400Y
S28944640A2K27G60000EEB002000CAG   0000085300Y
S28944649A3K27G60000EBB002000COH   0000135100Y
S28944653P4K27GA0000JOS000100DXD   0000499800000I000HV2O9
S28944658A3K27G60000ECB002000CVS   0000162300Y
S28944665A3K27G60000EDS002000CVS   0001380700Y
S28944675ABK27GA00018DB002000UTX   0000280300Y
S28944697A1K27GA0000DKB002000ABT   0000212100Y
S28944723A2K27G60000EFS002000BA    0001560700Y
S28944733A2K27G60000EGS002000BBT   0001345200Y
S28944745A2K27G60000EHS002000CAG   0001302900Y
S28944764A3K27G60000EEB002000DAL   0000019100Y
S28944775A3K27G60000EFS002000DD    0001405600Y
S28944782A3K27G60000EGS002000DHI   0000159900Y
S28945112XAK27GA0000EB001000
S28945112AAK27GA0000EBB001000SPY   0001425900Y
S28945112XAK27GA0001BY000500
S28945112AAK27GA0001BYS000500SPY   0001426500Y
S28945112XAK27GA000176002000
S28945113XAK27GA0001CH001000
S28945113XBK27GA00018C001000
S28945113XAK27GA0001BY000500
S28945113AAK27GA0001BYS000500SPY   0001426100Y
S28945114XAK27GA0001BZ005000
S28945114AAK27GA0001CLS005000SPY   0001426400Y
S28945114AAK27GA0001CMB001000SDS   0000547200Y
S28945114XAK27GA0001CF000500
S28945115ABK27GA00018ES001000SSO   0000765800Y
S28945115XAK27GA0001CD002500
S28945115AAK27GA0001CNS000500SPY   0001426200Y
S28945115XAK27GA0001BY000500
S28945115AAK27GA0001BYS000500SPY   0001426500Y
S28945115AAK27GA0001COS002500SPY   0001426200Y
S28945116XAK27GA0001C8002500
S28945127A6K27GA0000D9B002000IWM   0000736900Y
S28945127X6K27GA0000B7002000
S28945136X9K27G60000OM005000
S28945136X9K27G60000OL005000
S28945136A9K27G60000SSB005000QQQQ  0000495900Y
S28945136A9K27G60000STB005000QQQQ  0000495900Y
S28945136X4K27GA0000BT000100
S28945136X4K27GA0000JL000100
S28945137X3K27G60000DH000100
S28945142XAK27GA00010S003000
S28945142XAK27GA00013L002000
S28945142AAK27GA00013LB002000SPY   0001425900Y
S28945142XAK27GA0000O8000500
S28945142AAK27GA0000O8S000500SPY   0001426500Y
S28945143XAK27GA0000E6001000
S28945143AAK27GA0000E6S001000SPY   0001426500Y
S28945143XAK27GA0000FG000500
S28945143AAK27GA0000FGB000500SPY   0001425900Y
S28945143XAK27GA0000Q5003000
S28945143X9K27G60000G5002000
S28945143A9K27G60000G5S002000QQQQ  0000496500Y
S28945143XAK27GA0000F5000500
S28945143AAK27GA0000F5B000500SPY   0001426000Y
S28945143XAK27GA0000FI000500
S28945143AAK27GA0000FIB000500SPY   0001426000Y
S28945143XAK27GA0000QB000500
S28945143AAK27GA0000QBS000500SPY   0001426600Y
S28945143XAK27GA0000NY000500
S28945143AAK27GA0000NYS000500SPY   0001426600Y
S28945143XAK27GA00010T003000
S28945143XAK27GA00015R000400
S28945143XAK27GA0000E8001000
S28945143AAK27GA0000E8B001000SPY   0001426000Y
S28945143XAK27GA00015S001000
S28945143XAK27GA00013T002000
S28945143AAK27GA00013TB002000SPY   0001426000Y
S28945143AAK27GA0001CPB001000SPY   0001426000Y
S28945143AAK27GA0001CQB003000SPY   0001425900Y
S28945143XAK27GA0000Q3003000
S28945143AAK27GA0001CRB003000SPY   0001425900Y
S28945143AAK27GA0001CSS002000SPY   0001427500Y
S28945144AAK27GA0001CTS003000SPY   0001426800Y
S28945145XAK27GA0001CO002500
S28945145XAK27GA0001CN000500
S28945145XAK27GA00015V001000
S28945145AAK27GA0001CUS003000SPY   0001426800Y
S28945145AAK27GA0001CVS001000SPY   0001426500Y
S28945146A3K27G60000EHS000100DDM   0000803000Y
S28945146X8K27G600005P000500
S28945145XAK27GA0001C5001000
S28945145XAK27GA0000PX000100
S28945146XBK27GA00017P001000
S28945146X8K27G600005Q000100
S28945145X4K27GA0000ID000200
S28945146X4K27GA00007C000200
S28945146A4K27GA00007CB000200DIA   0001299000Y
S28945146X4K27GA0000J2000200
S28945146ABK27GA00018FB001000SSO   0000764900Y
S28945146XAK27GA0001BP001000
S28945146XAK27GA0001C4001000
S28945146AAK27GA0001CWB002000SPY   0001425800Y
S28945146AAK27GA0001CXS000100SH    0000618700Y
S28945147AAK27GA0001CYS001000SPY   0001426600Y
S28945148X3K27G60000AN000100
S28945146X6K27GA0000B6000500
S28945146A6K27GA0000B6B000500IWM   0000737000Y
S28945148A3K27G60000EIB000100DDM   0000801600Y
S28945147XAK27GA0000E9001000
S28945147AAK27GA0000E9S001000SPY   0001426600Y
S28945147AAK27GA0001CZS001000SPY   0001426400Y
S28945148A8K27G600005YB000500MZZ   0000491200Y
S28945148XBK27GA00017V001000
S28945148ABK27GA00018GB001000SSO   0000764700Y
S28945148AAK27GA0001D0S001000SPY   0001426400Y
S28945149A8K27G600005ZS000100MVV   0000809900Y
S28945148A4K27GA0000JPS000200DIA   0001299600Y
S28945149XBK27GA0000X0000100
S28945149ABK27GA00018HB000100UWM   0000543100Y
S28945149XBK27GA00017S000100
S28945149ABK27GA00018IS000100TWM   0000701400Y
S28945150X4K27GA000093000100
S28945150X3K27G60000EH000100
S28945150A4K27GA0000JQS000200DIA   0001299700Y
S28945152A3K27G60000EJS000100DDM   0000803100Y
S28945152A4K27GA0000JRB000100DXD   0000498900Y
S28945152X6K27GA0000B6000500
S28945152A6K27GA0000B6B000500IWM   0000736600Y
S28945154X6K27GA0000B6000500
S28945154A6K27GA0000B6B000500IWM   0000737000Y
S28945157X4K27GA00007C000200
S28945157A4K27GA00007CB000200DIA   0001299100Y
S28945173X9K27G60000G4002000
S28945173A9K27G60000G4B002000QQQQ  0000495900Y
S28945174X9K27G60000M5002000
S28945174X9K27G60000EN002000
S28945174A9K27G60000ENS002000QQQQ  0000496300Y
S28945175A9K27G60000SUB004000QQQQ  0000495700Y
S28945175X9K27G60000JH002000
S28945173X6K27GA0000CZ002000
S28945175X9K27G60000JI002000
S28945175AAK27GA0001D1B002000SPY   0001425900Y
S28945180X4K27GA0000BF000100
S28945180X4K27GA0000IR000100
S28945180X3K27G60000EJ000100
S28945181A4K27GA0000JSB000100DOG   0000596700Y
S28945181A4K27GA0000JTB000100DXD   0000498800Y
S28945182A3K27G60000EKS000100DDM   0000803200Y
S28945200X6K27GA00002B000500
S28945200A6K27GA00002BS000500IWM   0000737600Y
S28945202XAK27GA0001CZ001000
S28945202XAK27GA0001D0001000
S28945204A8K27G6000060B000100MVV   0000807000Y
S28945204X8K27G600005O000100
S28945204AAK27GA0001D2S001000SPY   0001426500Y
S28945205X6K27GA00009R002000
S28945206X4K27GA0000DX000200
S28945206A4K27GA0000DXB000200DIA   0001299200Y
S28945205A6K27GA0000DAS002000IWM   0000738000Y
S28945208A4K27GA0000JUS000100DXD   0000499800Y
S28945208X3K27G60000AQ000100
S28945208X4K27GA0000GW000100
S28945208A3K27G60000ELB000100DDM   0000801700Y
S28945213XBK27GA00017W000100
S28945213A6K27GA0000DBB002000IWM   0000737000Y
S28945213X6K27GA0000BG002000
S28945215ABK27GA00018JS000100UWM   0000544300Y
S28945222X8K27G600005Z000100
S28945223A8K27G6000061S000100MVV   0000810000Y
S28945263XAK27GA0001D2001000
S28945264AAK27GA0001D3S001000SPY   0001426600Y
S28945265AAK27GA0001D4S001000SPY   0001426600Y
S28945276X4K27GA0000IE000200
S28945276A4K27GA0000IEB000200DIA   0001299300Y
S28945278A4K27GA0000JVS000100DXD   0000499800Y
S28945278A4K27GA0000JWS000100DOG   0000598100Y
S28945278X4K27GA00008V000100
S28945279A3K27G60000EMB000100DDM   0000801800Y
S28945279X3K27G60000CG000100
S28945278X4K27GA0000H1000100
S28945280E4K27GA0000IE00007600004AQ0000C
S28945286X9K27G60000F0005000
S28945296A9K27G60000SVS005000QQQQ  0000496400Y
S28945310X9K27G60000FM005000
S28945310X9K27G60000F3003200
S28945310A9K27G60000F3B003200QQQQ  0000495900Y
S28945311X9K27G60000P9002000
S28945312A9K27G60000SWS005000QQQQ  0000496400Y
S28945315AAK27GA0001D5B000500SPY   0001425900Y
S28945315XAK27GA0001C7000500
S28945320X6K27GA00007U000500
S28945320A6K27GA00007UB000500IWM   0000737100Y
S28945324XBK27GA00018I000100
S28945324ABK27GA00018KB000100UWM   0000543300Y
S28945324XBK27GA0000Y9000100
S28945324ABK27GA00018LS000100TWM   0000701200Y
S28945325X4K27GA0000JV000100
S28945325A4K27GA0000JVS000100DXD   0000499700Y
S28945352AAK27GA0001D6S002000SINA  0000555400Y
S28945359XAK27GA00015U001000
S28945359XAK27GA00016U000100
S28945359XAK27GA0001CM001000
S28945360XBK27GA00018E001000
S28945360AAK27GA0001D7B001000SPY   0001426000Y
S28945359A6K27GA0000DCB002000IWM   0000737000Y
S28945359X6K27GA00009J002000
S28945361XAK27GA0000QF001000
S28945362X2K27G60000E5002000
S28945361AAK27GA0001D8S001000SDS   0000548500Y
S28945361XBK27GA00018F001000
S28945361AAK27GA0001D9B000100SH    0000618000Y
S28945361ABK27GA00018MB001000SSO   0000765000Y
S28945361AAK27GA0001DAB001000SDS   0000547100Y
S28945362ABK27GA00018NS001000SSO   0000766000Y
S28945374X3K27G60000E2002000
S28945394X8K27G600005C000500
S28945394A8K27G6000062S000500MZZ   0000493400Y
S28945395X8K27G600005R000100
S28945395A8K27G6000063B000100MVV   0000807100Y
S28945406XAK27GA0001D7001000
S28945406AAK27GA0001D7B001000SPY   0001426100Y
S28945408XBK27GA00018G001000
S28945408ABK27GA00018OB001000SSO   0000764800Y
S28945410X7K27GA00007Q002000
S28945419X7K27GA000061002000
S28945426XBK27GA00018D002000
S28945441A4K27GA0000JYB002000FITB  0000182300Y
S28945442X5K27GA00008E002000
S28945458X1K27GA0000DK002000
S28945470A7K27GA00007RB002000LMT   0000429100Y
S28945472X1K27GA00008W002000
S28945482X2K27G60000EF002000
S28945497X2K27G60000E7002000
S28945499A9K27G60000SXB002000PDLI  0000038100Y
S28945506X2K27G60000EG002000
S28945517AAK27GA0001DBS000500SPY   0001426400Y
S28945519X2K27G60000EA002000
S28945518AAK27GA0001DCS005000SPY   0001426300Y
S28945518XAK27GA0001CL005000
S28945519AAK27GA0001DDB002500SPY   0001426000Y
S28945527ABK27GA00018PS002000TGT   0000615000Y
S28945531X2K27G60000EH002000
S28945553X3K27G60000EF002000
S28945566ABK27GA00018QB002000UTX   0000283100Y
S28945566A5K27GA00008FS002000FNM   0001317100Y
S28945594XCK27GA00005Y002000
S28945603X1K27GA0000DI002000
S28945607X1K27GA0000DJ002000
S28945613X2K27G60000EC002000
S28945623X2K27G60000ED002000
S28945633ABK27GA00018RS002000UTX   0001504100Y
S28945641A1K27GA0000DLB002000ABT   0000214500Y
S28945643A5K27GA00008GB002000GM    0000180900Y
S28945656A2K27G60000EIB002000BBT   0000129500Y
S28945660X3K27G60000EC002000
S28945659ABK27GA00018SS002000TGT   0000615800Y
S28945669X3K27G60000ED002000
S28945673ABK27GA00018TS002000UTX   0001504900Y
S28945683A2K27G60000EJS002000CAG   0001297200Y
S28945683ACK27GA00005ZB002000WYE   0000166600Y
S28945694A1K27GA0000DMB002000AFL   0000261300Y
S28945701A3K27G60000ENS002000COH   0001350000Y
S28945703A1K27GA0000DNS002000AFL   0001490200Y
S28945732A3K27G60000EOS002000DD    0001400700Y
S28945732A3K27G60000EPB002000COH   0000135200Y
S28945743A3K27G60000EQS002000COH   0001350800Y
S28945751A3K27G60000ERB002000DE    0000794500Y
S28945760A3K27G60000ESB002000CVS   0000162700Y
S28945770A3K27G60000ETS002000DE    0000836300Y
S28945772A3K27G60000EUS002000CVS   0001377100Y
S28945785A3K27G60000EVB002000DHR   0000762500Y
S28945840P4K27GA0000JZS000100DIS   0000345700000I000HV2OE
S28946025AAK27GA0001DES002500SPY   0001426400Y
S28946142P9K27G60000SYB000400PTR   0001430000000I000HV2OK
S28946326X1K27GA0000D8000100
S28946326A1K27GA0000D8B000100AAPL  0001830100Y
S28946348X3K27G60000DT002000
S28946355A3K27G60000EWB002000CTSH  0000116900Y
S28946373X5K27GA00008F002000
S28946381X7K27GA00007R002000
S28946431XBK27GA00018T002000
S28946433XCK27GA00005Z002000
S28946436XBK27GA00018Q002000
S28946437X1K27GA0000DM002000
S28946439X1K27GA0000DN002000
S28946442XBK27GA00018R002000
S28946446X2K27G60000DQ002000
S28946449A2K27G60000EKB002000BMY   0000081100Y
S28946449X2K27G60000BM002000
S28946457X1K27GA0000DL002000
S28946462X3K27G60000B1002000
S28946465X3K27G60000EQ002000
S28946472X3K27G60000ES002000
S28946476X3K27G60000EU002000
S28946477AAK27GA0001DFB000500SPY   0001426000Y
S28946477XAK27GA0001D5000500
S28946483A7K27GA00007SB002000LMT   0000431300Y
S28946485A5K27GA00008HS002000FNM   0001311500Y
S28946492A7K27GA00007TB002000MMM   0000765200Y
S28946502ABK27GA00018UB002000UTX   0000284300Y
S28946532X2K27G60000DS002000
S28946537A1K27GA0000DOB002000ABT   0000215200Y
S28946548ACK27GA000060B002000WYE   0000168700Y
S28946592A1K27GA0000DPB002000AFL   0000263900Y
S28946600X2K27G60000EE002000
S28946609X2K27G60000EJ002000
S28946614X3K27G60000EB002000
S28946620X3K27G60000EN002000
S28946623A1K27GA0000DQS002000ANF   0000772300Y
S28946633A2K27G60000ELS002000BA    0001554500Y
S28946640A1K27GA0000DRS002000AFL   0001485800Y
S28946648A2K27G60000EMB002000BBT   0000129700Y
S28946661X3K27G60000EO002000
S28946664A2K27G60000ENS002000BBT   0001336100Y
S28946679A2K27G60000EOS002000BA    0001553700Y
S28946696A2K27G60000EPS002000BBT   0001335300Y
S28946696A2K27G60000EQB002000CAG   0000085800Y
S28946711A2K27G60000ERS002000CAG   0001293100Y
S28946711A3K27G60000EXB002000CVS   0000164600Y
S28946729A3K27G60000EYS002000CVS   0001372000Y
S28947350A3K27G60000EZB002000CELG  0000505300Y
S28947381XAK27GA0001CG002000
S28947383X5K27GA00008H002000
S28947384X7K27GA00007S002000
S28947430XBK27GA000150002000
S28947434XBK27GA00018U002000
S28947453XCK27GA000060002000
S28947459X1K27GA0000DO002000
S28947473X2K27G60000EL002000
S28947473X1K27GA0000DP002000
S28947479X1K27GA0000DR002000
S28947484X2K27G600007S002000
S28947490X2K27G60000EN002000
S28947495X2K27G60000DR002000
S28947497X2K27G60000EO002000
S28947500X2K27G60000ER002000
S28947511X2K27G60000EI002000
S28947512X3K27G60000EP002000
S28947512X2K27G60000EP002000
S28947513X2K27G60000DT002000
S28947518A5K27GA00008IS002000FNM   0001307600Y
S28947527X2K27G60000BB002000
S28947541A7K27GA00007UB002000LMT   0000435100Y
S28947552ABK27GA00018VS002000UTX   0001498000Y
S28947559ABK27GA00018WB002000UTX   0000287100Y
S28947560ACK27GA000061B002000WYE   0000169100Y
S28947581ABK27GA00018XS002000UTX   0001497200Y
S28947584X3K27G60000EX002000
S28947590X3K27G60000EY002000
S28947595A1K27GA0000DSB002000ABT   0000217500Y
S28947601A2K27G60000ESB002000AXP   0000423400Y
S28947626A2K27G60000ETB002000CAG   0000087300Y
S28947637A2K27G60000EUS002000CAG   0001287400Y
S28947645A3K27G60000F0B002000COH   0000138000Y
S28947654A1K27GA0000DTB002000AFL   0000265000Y
S28947661A1K27GA0000DUS002000AFL   0001483100Y
S28947662A3K27G60000F1S002000COH   0001340900Y
S28947669A2K27G60000EVB002000AXP   0000422600Y
S28947676A2K27G60000EWB002000AZN   0000422400Y
S28947680A3K27G60000F2S002000DD    0001392300Y
S28947680X6K27GA0000D4002000
S28947689A3K27G60000F3B002000CCE   0000193700Y
S28947693X9K27G60000SU002000
S28947696A3K27G60000F4S002000COH   0001341700Y
S28947699A3K27G60000F5B002000DHI   0000138600Y
S28947709A3K27G60000F6B002000CVS   0000165000Y
S28947727A3K27G60000F7S002000CVS   0001368500Y
S28947750A3K27G60000F8S002000DD    0001393100Y
S28947765A3K27G60000F9S002000DHR   0000814800Y
S28947837A9K27G60000SZB002000QQQQ  0000495700Y
S28948367X2K27G60000EK002000
S28948367XAK27GA0001CI002000
S28948384X2K27G60000AG002000
S28948395X5K27GA00008I002000
S28948409AAK27GA0001DGB002000SHLD  0000786700Y
S28948410X7K27GA00007U002000
S28948414XBK27GA00018V002000
S28948421XCK27GA000061002000
S28948429XBK27GA00018W002000
S28948452A5K27GA00008JS002000FNM   0001302000Y
S28948454X1K27GA0000DT002000
S28948465X1K27GA0000DU002000
S28948471X2K27G60000EM002000
S28948471XBK27GA00018X002000
S28948477X2K27G60000EQ002000
S28948484X3K27G60000F4002000
S28948494X3K27G60000F6002000
S28948496X3K27G60000F7002000
S28948499X3K27G60000F8002000
S28948512ACK27GA000062B002000WYE   0000171100Y
S28948518A7K27GA00007VB002000LMT   0000437300Y
S28948518X1K27GA0000DS002000
S28948528ABK27GA00018YB002000TGT   0000522200Y
S28948540ABK27GA00018ZB002000UTX   0000288300Y
S28948553A1K27GA0000DVB002000AFL   0000267700Y
S28948621X1K27GA0000AB002000
S28948625X1K27GA0000C9002000
S28948629A1K27GA0000DWS002000AFL   0001478700Y
S28948639A2K27G60000EXS002000BA    0001547500Y
S28948647A2K27G60000EYB002000BBT   0000132400Y
S28948658A1K27GA0000DXB002000ABT   0000218200Y
S28948672A4K27GA0000K0B000100DRYS  0001070100Y
S28948672A4K27GA0000K1B000100DRYS  0001070100Y
S28948684A2K27G60000EZS002000BBT   0001326100Y
S28948688A2K27G60000F0S002000BA    0001548300Y
S28948699A2K27G60000F1B002000BDX   0000780300Y
S28948702A2K27G60000F2S002000BAX   0000638000Y
S28948707X2K27G60000EU002000
S28948718A2K27G60000F3S002000BBT   0001326900Y
S28948734A2K27G60000F4B002000BDX   0000779500Y
S28948740A2K27G60000F5B002000CAT   0000821300Y
S28948746X3K27G60000F1002000
S28948753A2K27G60000F6S002000CAG   0001283400Y
S28948771A3K27G60000FAB002000COH   0000138200Y
S28948776X3K27G60000F2002000
S28948780A3K27G60000FBB002000CVS   0000167000Y
S28949081X9K27G60000HI000500
S28949081X9K27G60000HJ000500
S28949081X9K27G60000HH001000
S28949083A9K27G60000T0S001000QQQQ  0000496500Y
S28949350X3K27G60000EW002000
S28949395X6K27GA0000CG002000
S28949396AAK27GA0001DHB002000SPLS  0000084400Y
S28949408X5K27GA00008J002000
S28949409X6K27GA0000CH002000
S28949416X7K27GA00007V002000
S28949429XBK27GA00018Z002000
S28949433XCK27GA000062002000
S28949452X1K27GA0000DX002000
S28949454X1K27GA0000DV002000
S28949459X1K27GA0000DW002000
S28949471X2K27G60000F0002000
S28949473X2K27G60000EX002000
S28949480XAK27GA0001DC005000
S28949481AAK27GA0001DIB005000SPY   0001425900Y
S28949481XAK27GA0000E7001000
S28949481AAK27GA0000E7B001000SPY   0001426100Y
S28949481XAK27GA0001C9005000
S28949489X2K27G60000F3002000
S28949489X2K27G60000EZ002000
S28949491X2K27G60000ET002000
S28949492X2K27G600008X002000
S28949496X2K27G60000F6002000
S28949495X6K27GA00009X002000
S28949496A6K27GA0000DDS002000IWM   0000738100Y
S28949499X3K27G60000F0002000
S28949515X3K27G60000FB002000
S28949519A2K27G60000F7B002000BRL   0000376300Y
S28949519X3K27G60000EA002000
S28949526A2K27G60000F8B002000BMY   0000082900Y
S28949537A5K27GA00008KS002000FNM   0001298100Y
S28949550A7K27GA00007WB002000LMT   0000441100Y
S28949559ABK27GA000190S002000UTX   0001491100Y
S28949601X8K27G600005V000100
S28949601A8K27G6000064B000100MVV   0000807200Y
S28949602ABK27GA000191B002000UTX   0000291100Y
S28949609ABK27GA000192S002000UTX   0001490300Y
S28949613A1K27GA0000DYB002000ABT   0000220600Y
S28949623A1K27GA0000DZB002000ANF   0000724300Y
S28949633A1K27GA0000E0B002000ARO   0000301700Y
S28949640ACK27GA000063B002000WYE   0000171500Y
S28949655A1K27GA0000E1B002000AFL   0000268700Y
S28949656A2K27G60000F9S002000CAG   0001277700Y
S28949665A1K27GA0000E2S002000AFL   0001475900Y
S28949671A3K27G60000FCS002000COH   0001331900Y
S28949684A2K27G60000FAB002000BBT   0000132500Y
S28949691A3K27G60000FDS002000CVS   0001359000Y
S28949698A2K27G60000FBB002000CAG   0000087800Y
S28949706A3K27G60000FES002000COH   0001332700Y
S28949729A3K27G60000FFB002000CVS   0000167400Y
S28949742A3K27G60000FGS002000CVS   0001359800Y
S28949756A3K27G60000FHS002000DD    0001384800Y
S28949884AAK27GA0001DJS005000SPY   0001426400Y
S28950352A3K27G60000FIB002000CTSH  0000120400Y
S28950403X5K27GA00008K002000
S28950405X7K27GA00006Z002000
S28950407X7K27GA00007W002000
S28950422X7K27GA00006H002000
S28950424XBK27GA00018S002000
S28950426XBK27GA000190002000
S28950428XCK27GA000063002000
S28950433X1K27GA0000E1002000
S28950435X1K27GA0000E2002000
S28950439XBK27GA00018P002000
S28950445X1K27GA0000CJ002000
S28950455XBK27GA000191002000
S28950458XBK27GA000192002000
S28950462X2K27G60000A2002000
S28950463XCK27GA00005H002000
S28950468X3K27G60000FA002000
S28950472X3K27G60000FE002000
S28950470XCK27GA00004S002000
S28950479X3K27G60000FF002000
S28950486X1K27GA0000DY002000
S28950489X3K27G60000FG002000
S28950496X2K27G60000EY002000
S28950502X3K27G60000EE002000
S28950505X3K27G60000FH002000
S28950513X2K27G60000F9002000
S28950516X3K27G60000BE002000
S28950519E4K27GA0000K000010000004AQ0000D
S28950519E4K27GA0000K100010000004AQ0000E
S28950531X3K27G60000FC002000
S28950533A6K27GA0000DEB002000JNJ   0000644100Y
S28950536P4K27GA0000K3S000100DRYS  0001070700000I000HV2PK
S28950537P4K27GA0000K3S000100DRYS  0001070600000I000HV2PL
S28950557X3K27G60000FD002000
S28950555A6K27GA0000DFS002000JNJ   0000688600Y
S28950584A5K27GA00008LS002000FNM   0001292500Y
S28950597A7K27GA00007XB002000LMT   0000443300Y
S28950606ACK27GA000064B002000WYE   0000173500Y
S28950608X8K27G6000061000100
S28950608X8K27G600005Y000500
S28950609ABK27GA000193B002000UTX   0000292300Y
S28950610A8K27G6000065S000100MVV   0000810100Y
S28950610A8K27G6000066B000500MZZ   0000491100Y
S28950612X8K27G6000065000100
S28950614A8K27G6000067S000100MVV   0000810200Y
S28950632A1K27GA0000E3B002000AFL   0000271400Y
S28950641A1K27GA0000E4B002000ABT   0000221300Y
S28950647A1K27GA0000E5S002000AFL   0001471500Y
S28950662A2K27G60000FCS002000BA    0001541300Y
S28950665A2K27G60000FDS002000BA    0001542100Y
S28950675A2K27G60000FES002000BBT   0001316900Y
S28950679A2K27G60000FFS002000BBT   0001317700Y
S28950688A2K27G60000FGB002000CAG   0000089200Y
S28950695A2K27G60000FHS002000BSX   0000152100Y
S28950702A2K27G60000FIS002000CAG   0001273600Y
S28950705A3K27G60000FJB002000COH   0000141000Y
S28950731A3K27G60000FKB002000CVS   0000169400Y
S28950738A3K27G60000FLB002000DAL   0000021100Y
S28950744A3K27G60000FMS002000DD    0001379800Y
S28950759A3K27G60000FNS002000DHI   0000159100Y
S28951181XAK27GA0000EX000500
S28951181AAK27GA0000EXB000500SPY   0001426100Y
S28951181XAK27GA0000FE000500
S28951181AAK27GA0000FEB000500SPY   0001426100Y
S28951184XAK27GA0001DJ005000
S28951184AAK27GA0001DKS005000SPY   0001426600Y
S28951190X6K27GA000026000500
S28951190A6K27GA000026S000500IWM   0000737700Y
S28951193A6K27GA0000DGB002000IWM   0000737100Y
S28951193X6K27GA0000AR002000
S28951196XAK27GA0001BP001000
S28951196AAK27GA0001DLB001000SPY   0001425900Y
S28951196XAK27GA0001CJ001000
S28951210A6K27GA0000DHB002000IWM   0000737100Y
S28951210X6K27GA0000BL002000
S28951234XBK27GA00018J000100
S28951235ABK27GA000194S000100UWM   0000544400Y
S28951299X8K27G600005E000500
S28951299X8K27G6000062000500
S28951299X8K27G6000063000100
S28951299X8K27G6000060000100
S28951299X8K27G6000064000100
S28951301A8K27G6000068S000500MZZ   0000493400Y
S28951301A8K27G6000069B000100MVV   0000807100Y
S28951345X1K27GA0000DC002000
S28951352X6K27GA0000D8002000
S28951370X2K27G60000F8002000
S28951410A5K27GA00008MS002000FNM   0001288600Y
S28951413X5K27GA00008L002000
S28951436X7K27GA00007X002000
S28951439XBK27GA000193002000
S28951439A7K27GA00007YB002000LMT   0000447100Y
S28951445X1K27GA0000E4002000
S28951450X1K27GA00008L002000
S28951460X2K27G60000FD002000
S28951469X2K27G60000FA002000
S28951470A7K27GA00007ZS002000MMM   0000814200Y
S28951477X2K27G60000FF002000
S28951483X2K27G60000C2002000
S28951486X2K27G60000CB002000
S28951490X2K27G60000FB002000
S28951497X2K27G60000FI002000
S28951507A8K27G600006AB000100MVV   0000807200Y
S28951513X3K27G60000D9002000
S28951513ABK27GA000195S002000TGT   0000613400Y
S28951516A7K27GA000080B002000KSS   0000458900Y
S28951527ABK27GA000196S002000TGT   0000614200Y
S28951527ABK27GA000197B002000UTX   0000295100Y
S28951541ABK27GA000198S002000UTX   0001484100Y
S28951542XCK27GA000064002000
S28951548XCK27GA00005J002000
S28951555ACK27GA000065B002000WYE   0000173900Y
S28951557ABK27GA000199S002000UTX   0001483300Y
S28951562A1K27GA0000E6B002000AFL   0000272400Y
S28951589A1K27GA0000E7S002000AFL   0001468700Y
S28951593A1K27GA0000E8B002000ARO   0000301000Y
S28951612A2K27G60000FJS002000CAT   0000867200Y
S28951615A3K27G60000FOB002000COH   0000141200Y
S28951616ACK27GA000066B002000WMT   0000543100Y
S28951623X1K27GA0000E3002000
S28951629X1K27GA0000E5002000
S28951635A3K27G60000FPS002000COH   0001323700Y
S28951635X2K27G600009E002000
S28951653X2K27G60000FC002000
S28951658A3K27G60000FQB002000CVS   0000169700Y
S28951671A3K27G60000FRS002000CVS   0001351100Y
S28951671ACK27GA000067S002000WMT   0000579800Y
S28951679X2K27G60000FE002000
S28951708A1K27GA0000E9B002000ABT   0000223700Y
S28951716A2K27G60000FKB002000BBT   0000135200Y
S28951722X3K27G60000FK002000
S28951726X3K27G60000FM002000
S28951732A2K27G60000FLS002000CAG   0001267900Y
S28951740A3K27G60000FSB002000CCE   0000194700Y
S28952058A8K27G600006BB000100MVV   0000807300Y
S28952058A8K27G600006CS000500MZZ   0000493300Y
S28952202A5K27GA00008NS000100FXP   0000656800Y
S28952210X5K27GA00008N000100
S28952399XAK27GA0001DG002000
S28952410X2K27G60000AX002000
S28952412X7K27GA00007Y002000
S28952413X3K27G60000CL002000
S28952423X8K27G6000053002000
S28952425X5K27GA00008M002000
S28952426XBK27GA000197002000
S28952439A1K27GA0000EAS002000AMGN  0000472700Y
S28952442XBK27GA000199002000
S28952457X1K27GA0000E9002000
S28952473X2K27G60000ES002000
S28952474A6K27GA0000DIS002000IMCL  0000505700Y
S28952488X2K27G60000FG002000
S28952491XBK27GA000198002000
S28952502X2K27G60000FL002000
S28952512XCK27GA000065002000
S28952516X3K27G60000FJ002000
S28952528X1K27GA0000BU002000
S28952530X1K27GA0000E6002000
S28952532X1K27GA0000E7002000
S28952533A2K27G60000FMB002000BMY   0000084800Y
S28952537X2K27G60000EV002000
S28952545X3K27G60000FP002000
S28952555X3K27G60000FQ002000
S28952560X3K27G60000FR002000
S28952563A5K27GA00008OS002000FNM   0001283000Y
S28952583A7K27GA000081B002000LMT   0000449300Y
S28952589ABK27GA00019AB002000UTX   0000296300Y
S28952607A1K27GA0000EBB002000ABT   0000224300Y
S28952609ACK27GA000068B002000WYE   0000175900Y
S28952620A1K27GA0000ECB002000ACF   0000120600Y
S28952623ACK27GA000069S002000WYE   0000470300Y
S28952644A2K27G60000FNS002000BA    0001536000Y
S28952646A1K27GA0000EDB002000AFL   0000275100Y
S28952658A1K27GA0000EES002000AFL   0001464300Y
S28952660A2K27G60000FOB002000BBT   0000135400Y
S28952670A2K27G60000FPB002000BA    0000856100Y
S28952687A2K27G60000FQS002000BBT   0001308600Y
S28952695A2K27G60000FRS002000BA    0001535200Y
S28952701A2K27G60000FSB002000BK    0000430000Y
S28952707A2K27G60000FTB002000BNI   0001063300Y
S28952710A2K27G60000FUS002000BBT   0001307800Y
S28952710A2K27G60000FVB002000CAG   0000089700Y
S28952720A3K27G60000FTS002000COH   0001318400Y
S28952720A2K27G60000FWS002000CAG   0001263900Y
S28952736A3K27G60000FUB002000CVS   0000171700Y
S28952740A3K27G60000FVB002000DAL   0000020700Y
S28952746A3K27G60000FWB002000DD    0000463200Y
S28952753A3K27G60000FXS002000DD    0001372300Y
S28952771X9K27G60000NA002000
S28952771A9K27G60000T1S002000QQQQ  0000496300Y
S28952773A9K27G60000T2S002000QQQQ  0000496300Y
S28952845AAK27GA0001DMB001000SDS   0000547200Y
S28952846XBK27GA00018N001000
S28952846ABK27GA00019BS001000SSO   0000765900Y
S28952901X6K27GA0000BB002000
S28952910X6K27GA0000AW002000
S28953142A4K27GA0000K4B000100DRYS  0001070100Y
S28953360X3K27G60000EZ002000
S28953362X5K27GA00008O002000
S28953412X7K27GA000081002000
S28953413X5K27GA000071002000
S28953420XAK27GA0001DH002000
S28953442X8K27G600004Z002000
S28953443X3K27G60000FI002000
S28953446XBK27GA00019A002000
S28953454X4K27GA0000GK002000
S28953455XCK27GA000068002000
S28953462XAK27GA0001CK002000
S28953468X1K27GA0000ED002000
S28953473AAK27GA0001DNB002000SHLD  0000789600Y
S28953474X1K27GA0000EB002000
S28953488X1K27GA0000EE002000
S28953489X2K27G60000FN002000
S28953495X2K27G60000FQ002000
S28953508X2K27G60000CA002000
S28953518X2K27G60000FW002000
S28953533A3K27G60000FYS002000CMCSK 0000267900Y
S28953533X3K27G60000B2002000
S28953543X3K27G60000FO002000
S28953550A7K27GA000082B002000LMT   0000453100Y
S28953581A8K27G600006DB002000NVTL  0000082000Y
S28953594X2K27G60000FR002000
S28953599X2K27G60000FK002000
S28953603X2K27G60000FU002000
S28953610X3K27G60000FX002000
S28953616ABK27GA00019CB002000UTX   0000299100Y
S28953622A2K27G60000FXS002000BRL   0000422700Y
S28953630ABK27GA00019DS002000UTX   0001476400Y
S28953635A5K27GA00008PS002000FNM   0001279100Y
S28953648A1K27GA0000EFB002000ABT   0000226700Y
S28953673X3K27G60000FT002000
S28953673ABK27GA00019ES002000UTX   0001477200Y
S28953684X3K27G60000FU002000
S28953686A2K27G60000FYB002000AXP   0000424700Y
S28953693ACK27GA00006AB002000WYE   0000176300Y
S28953711A1K27GA0000EGS002000ACN   0000407000Y
S28953711X3K27G60000DS002000
S28953719A1K27GA0000EHB002000AFL   0000276100Y
S28953724A2K27G60000FZB002000CAG   0000091200Y
S28953730A1K27GA0000EIS002000AFL   0001461600Y
S28953742A2K27G60000G0S002000CAG   0001258200Y
S28953745A2K27G60000G1B002000AXP   0000423900Y
S28953754A3K27G60000FZB002000COH   0000144000Y
S28953761A3K27G60000G0S002000COH   0001314700Y
S28953774A3K27G60000G1B002000CVS   0000172100Y
S28953778A3K27G60000G2S002000CVS   0001341700Y
S28953785A3K27G60000G3S002000CVS   0001342500Y
S28953829X6K27GA0000DH002000
S28954319X4K27GA0000K4000100
S28954324P4K27GA0000K4B000100DRYS  0001070100000N4AQ0000F
S28954344E1K27GA0000D8000005000N1AQ00006
S28954351A3K27G60000G4B002000CELG  0000507800Y
S28954405X5K27GA00008P002000
S28954407X2K27G60000FM002000
S28954433XBK27GA00019E002000
S28954443XCK27GA00006A002000
S28954460AAK27GA0001DOB002000SPLS  0000087500Y
S28954461A5K27GA00008QS002000FNM   0001273500Y
S28954467X1K27GA0000EH002000
S28954483X1K27GA0000EI002000
S28954486A5K27GA00008RB002000GS    0001820800Y
S28954498X1K27GA0000BY002000
S28954498X1K27GA000091002000
S28954507A3K27G60000G5B002000CTSH  0000123800Y
S28954519X2K27G60000FO002000
S28954529X7K27GA000082002000
S28954537X2K27G60000F4002000
S28954538X2K27G60000FV002000
S28954544A4K27GA0000K5B002000FFIV  0000267600Y
S28954545X3K27G60000G0002000
S28954562X3K27G60000G1002000
S28954576X7K27GA00006G002000
S28954591XBK27GA00019C002000
S28954591XBK27GA00019D002000
S28954593X3K27G60000G3002000
S28954602A9K27G60000T3S002000QQQQ  0000496100Y
S28954606AAK27GA0001DPB002000SNDK  0000248400Y
S28954610X3K27G60000DR002000
S28954617ACK27GA00006BB002000WYE   0000178300Y
S28954624A7K27GA000083B002000LMT   0000455300Y
S28954636X1K27GA0000EF002000
S28954643A1K27GA0000EJB002000AFL   0000278800Y
S28954651A8K27G600006ES002000NEM   0000503700Y
S28954658A1K27GA0000EKS002000AFL   0001457200Y
S28954664ABK27GA00019FB002000UTX   0000300300Y
S28954670A2K27G60000G2S002000BA    0001529000Y
S28954688A2K27G60000G3B002000BBT   0000138000Y
S28954688A1K27GA0000ELB002000ABT   0000227400Y
S28954702A2K27G60000G4S002000BA    0001529800Y
S28954709A2K27G60000G5S002000BBT   0001298600Y
S28954713A2K27G60000G6S002000BBT   0001299400Y
S28954722X2K27G60000F1002000
S28954727A2K27G60000G7S002000BK    0000475500Y
S28954734X2K27G600009V002000
S28954743X2K27G60000AD002000
S28954751A2K27G60000G8S002000CAG   0001254100Y
S28954755X2K27G60000G0002000
S28954763A3K27G60000G6S002000COH   0001309300Y
S28954780A3K27G60000G7S002000CCE   0000239900Y
S28954782A3K27G60000G8B002000CVS   0000174100Y
S28954787A3K27G60000G9B002000COH   0000144200Y
S28954799X3K27G60000G2002000
S28954819A3K27G60000GAB002000DD    0000464200Y
S28954838A3K27G60000GBS002000DD    0001363200Y
S28954845A3K27G60000GCS002000DD    0001364000Y
S28954857A4K27GA0000K6B002000DIS   0000331800Y
S28955356X1K27GA0000DD002000
S28955378X9K27G60000T3002000
S28955399X4K27GA0000J6002000
S28955404A5K27GA00008SS002000FNM   0001269500Y
S28955413X9K27G60000SX002000
S28955415X5K27GA00008Q002000
S28955425XAK27GA0001DL001000
S28955426AAK27GA0001DQS001000SPY   0001426500Y
S28955434X7K27GA000083002000
S28955437XAK27GA0001DQ001000
S28955449AAK27GA0001DRS005000SPY   0001426400Y
S28955449XAK27GA0001DK005000
S28955454XBK27GA00019F002000
S28955457XAK27GA0001DR005000
S28955465XCK27GA00006B002000
S28955469X1K27GA0000EL002000
S28955471X1K27GA0000EJ002000
S28955480X1K27GA0000EK002000
S28955490X2K27G60000G4002000
S28955494X2K27G60000G6002000
S28955504X2K27G60000G2002000
S28955509X2K27G60000G8002000
S28955511X2K27G60000G5002000
S28955526X2K27G60000FZ002000
S28955527X3K27G60000GC002000
S28955537X3K27G60000FZ002000
S28955543X3K27G60000G6002000
S28955547X3K27G60000G8002000
S28955555X3K27G60000GB002000
S28955565A2K27G60000G9B002000BMY   0000086600Y
S28955594A7K27GA000084B002000LMT   0000459100Y
S28955602A7K27GA000085B002000MMM   0000766200Y
S28955616ABK27GA00019GS002000UTX   0001470300Y
S28955628ACK27GA00006CB002000WYE   0000178700Y
S28955630ABK27GA00019HB002000UTX   0000303100Y
S28955643ABK27GA00019IS002000UTX   0001469500Y
S28955649A1K27GA0000EMB002000AFL   0000279900Y
S28955658A1K27GA0000ENB002000ABT   0000229800Y
S28955663A1K27GA0000EOS002000AFL   0001454400Y
S28955685A1K27GA0000EPS002000ALL   0000523800Y
S28955691A1K27GA0000EQB002000APC   0000765400Y
S28955697A2K27G60000GAB002000BDX   0000781700Y
S28955709A2K27G60000GBB002000BBT   0000138200Y
S28955717A2K27G60000GCS002000BDX   0000898800Y
S28955731A2K27G60000GDB002000BDX   0000780900Y
S28955736A2K27G60000GEB002000CAG   0000091700Y
S28955740A2K27G60000GFS002000BNI   0001127500Y
S28955747A3K27G60000GDS002000COH   0001305600Y
S28955762A2K27G60000GGS002000CAG   0001248400Y
S28955761A3K27G60000GEB002000CVS   0000174500Y
S28955853AAK27GA0001DSS005000SPY   0001426600Y
S28956082EBK27GA00006Z0001000000BAQ00001
S28956082ABK27GA00019LS000100UYG   0000322000Y
S28956083XAK27GA0000FB000100
S28956083PBK27GA00019JS000100UYG   0000320300000I000HV2QM
S28956084PBK27GA00019JS000200UYG   0000320300000I000HV2QN
S28956084ABK27GA00019MS000100UYG   0000321900Y
S28956083A6K27GA0000DJS000100IYF   0000859400Y
S28956084X6K27GA00002D000100
S28956084A6K27GA0000DKS000100IYF   0000859300Y
S28956084X6K27GA000021000100
S28956086ABK27GA00019NB000100UYG   0000319700Y
S28956085A6K27GA0000DLS000100IYF   0000859200Y
S28956085X6K27GA0000DJ000100
S28956090XBK27GA00019N000100
S28956089X6K27GA00002E000100
S28956090AAK27GA0001DTB000100SKF   0001027400Y
S28956089A6K27GA0000DMS000100IYF   0000857000Y
S28956090A6K27GA0000DNS000100IYF   0000857900Y
S28956352X6K27GA0000D7002000
S28956405X5K27GA00008S002000
S28956405X5K27GA000089002000
S28956413X5K27GA00007P002000
S28956422X7K27GA000084002000
S28956422A1K27GA0000ERS002000APOL  0000525100Y
S28956428XBK27GA000196002000
S28956431XBK27GA000195002000
S28956439XBK27GA00019G002000
S28956450XBK27GA00019H002000
S28956460XCK27GA00006C002000
S28956462XBK27GA00019I002000
S28956467X4K27GA0000JQ000200
S28956469A4K27GA0000K7S000123DIA   0001299400Y
S28956470X1K27GA0000EM002000
S28956483X1K27GA0000EN002000
S28956484A9K27G60000T4B002000PDLI  0000040400Y
S28956483X1K27GA0000EO002000
S28956498X1K27GA0000AE002000
S28956506X3K27G60000G9002000
S28956510X3K27G60000GD002000
S28956529X2K27G60000G3002000
S28956532X3K27G60000GE002000
S28956543X2K27G60000GG002000
S28956550X2K27G60000BC002000
S28956554A4K27GA0000K8B002000EMR   0000556500Y
S28956562X3K27G60000BF002000
S28956587X3K27G60000FL002000
S28956592A5K27GA00008TS002000FNM   0001264000Y
S28956607A7K27GA000086B002000LMT   0000461300Y
S28956614ACK27GA00006DB002000WYE   0000180800Y
S28956620ABK27GA00019OB002000UTX   0000304300Y
S28956633A1K27GA0000ESB002000AFL   0000282500Y
S28956636A1K27GA0000ETB002000ABT   0000230500Y
S28956646A1K27GA0000EUS002000AFL   0001450000Y
S28956664A2K27G60000GHS002000BA    0001522800Y
S28956665A2K27G60000GIS002000BA    0001523600Y
S28956677A2K27G60000GJS002000BBT   0001289400Y
S28956692A2K27G60000GKS002000BBT   0001290200Y
S28956693A2K27G60000GLB002000CAG   0000093100Y
S28956712A2K27G60000GMS002000CAG   0001244300Y
S28956711A3K27G60000GFB002000COH   0000147000Y
S28956725A3K27G60000GGS002000COH   0001300300Y
S28956732A3K27G60000GHS002000CVS   0001329500Y
S28956735A3K27G60000GIB002000CVS   0000176400Y
S28956754A3K27G60000GJS002000CVS   0001328700Y
S28956763A3K27G60000GKS002000DD    0001355600Y
S28956780X4K27GA0000IE000124
S28956781X4K27GA0000JW000100
S28956782X4K27GA0000JV000100
S28956782X3K27G60000EM000100
S28957041A4K27GA0000K9B000200DIA   0001299000Y
S28957173X6K27GA000026000500
S28957173A6K27GA000026S000500IWM   0000737300Y
S28957177ABK27GA00019PS000100UWM   0000544300Y
S28957176X6K27GA0000DG002000
S28957187X8K27G600006B000100
S28957187X8K27G600006C000500
S28957187X8K27G600005N000500
S28957187X8K27G600006A000100
S28957189A8K27G600006FB000100MVV   0000807200Y
S28957199P2K27G60000GNS000210BAC   0000359000000I000HV2QS
S28957344X5K27GA00005R002000
S28957357A6K27GA0000DOB002000IMCL  0000354400Y
S28957370X2K27G60000G9002000
S28957404XAK27GA0001DN002000
S28957407X5K27GA00008T002000
S28957413X3K27G60000G5002000
S28957414A5K27GA00008US002000FNM   0001260000Y
S28957438X5K27GA00006D002000
S28957439X7K27GA000086002000
S28957443X8K27G600004W002000
S28957443A5K27GA00008VB002000GM    0000182500Y
S28957464XBK27GA00019O002000
S28957467X1K27GA0000ET002000
S28957470X2K27G60000GI002000
S28957473X2K27G60000GB002000
S28957479A7K27GA000087B002000LMT   0000465100Y
S28957484X2K27G60000GK002000
S28957499X2K27G60000GE002000
S28957501AAK27GA0001DUB001000SPY   0001425900Y
S28957503X2K27G60000GM002000
S28957503XCK27GA00006D002000
S28957512ABK27GA00019QS002000TGT   0000611800Y
S28957517X3K27G60000GH002000
S28957520X3K27G60000GK002000
S28957536A5K27GA00008WS002000GM    0000226900Y
S28957540X1K27GA0000ES002000
S28957553X1K27GA0000EU002000
S28957555ABK27GA00019RB002000UTX   0000307100Y
S28957557ABK27GA00019SS002000TGT   0000612600Y
S28957591ABK27GA00019TS002000UTX   0001462600Y
S28957591X2K27G60000GH002000
S28957598A1K27GA0000EVB002000ABT   0000232800Y
S28957605X2K27G60000GJ002000
S28957614A1K27GA0000EWS002000ANF   0000771200Y
S28957624A2K27G60000GOB002000BBT   0000140900Y
S28957625X3K27G60000GG002000
S28957631X3K27G60000GI002000
S28957634X3K27G60000GJ002000
S28957656A2K27G60000GPS002000CAG   0001238700Y
S28957663A2K27G60000GQS002000CAT   0000866200Y
S28957670ABK27GA00019US002000UTX   0001463400Y
S28957679A3K27G60000GLS002000CCE   0000239000Y
S28957684ACK27GA00006EB002000WYE   0000181100Y
S28957699A1K27GA0000EXB002000AFL   0000283600Y
S28957711A1K27GA0000EYS002000AFL   0001447200Y
S28957729A3K27G60000GMB002000COH   0000147200Y
S28957734A3K27G60000GNS002000COH   0001296600Y
S28957741A3K27G60000GOB002000CVS   0000176800Y
S28957752A3K27G60000GPS002000DE    0000836300Y
S28957867X4K27GA0000IQ000100
S28957867X4K27GA0000JN000100
S28957867A4K27GA0000KAB000100DRYS  0001068100Y
S28958409X5K27GA00008U002000
S28958409A5K27GA00008XS002000IACI  0000263300Y
S28958410A2K27G60000GRB002000BMY   0000088400Y
S28958431XBK27GA00019U002000
S28958438XAK27GA0001DO002000
S28958444X6K27GA0000D0002000
S28958454XCK27GA00006E002000
S28958473X7K27GA000087002000
S28958475AAK27GA0001DVB002000SHLD  0000792500Y
S28958485X1K27GA0000EX002000
S28958488XBK27GA00017D002000
S28958490X1K27GA0000EY002000
S28958509X2K27G60000G1002000
S28958510XBK27GA00019R002000
S28958522A3K27G60000GQB002000CTSH  0000127300Y
S28958526XBK27GA00019T002000
S28958542A5K27GA00008YS002000FNM   0001254500Y
S28958544X3K27G60000GN002000
S28958550X3K27G60000GO002000
S28958562X3K27G60000FV002000
S28958575A5K27GA00008ZB002000GG    0000386700Y
S28958579A7K27GA000088B002000LMT   0000467300Y
S28958587A8K27G600006GS002000NBR   0000428100Y
S28958590ABK27GA00019VB002000UTX   0000308300Y
S28958597X1K27GA0000EV002000
S28958602A4K27GA0000KBS000100DRYS  0001071900Y
S28958602A4K27GA0000KCS000100DRYS  0001071900Y
S28958602A1K27GA0000EZB002000ABT   0000233500Y
S28958607ACK27GA00006FB002000WYE   0000183200Y
S28958630A2K27G60000GSS002000BA    0001517400Y
S28958639A1K27GA0000F0B002000AFL   0000286200Y
S28958646A2K27G60000GTB002000BBT   0000141000Y
S28958653X2K27G60000FY002000
S28958663X2K27G60000D9002000
S28958668A2K27G60000GUS002000BBT   0001281100Y
S28958672A1K27GA0000F1S002000AFL   0001442800Y
S28958686X2K27G600009J002000
S28958699A2K27G60000GVS002000BA    0001516600Y
S28958708A2K27G60000GWB002000CAG   0000093600Y
S28958720X2K27G60000GL002000
S28958725A2K27G60000GXS002000CAG   0001234600Y
S28958728X2K27G60000GP002000
S28958739A2K27G60000GYS002000BBT   0001280300Y
S28958744A3K27G60000GRS002000CVS   0001320800Y
S28958754X3K27G60000GF002000
S28958756A3K27G60000GSS002000DD    0001347300Y
S28958766A4K27GA0000KDS002000DIS   0000362400Y
S28958783A3K27G60000GTS002000COH   0001291300Y
S28958808A3K27G60000GUB002000CVS   0000178800Y
S28958815A3K27G60000GVS002000CVS   0001320000Y
S28958824A3K27G60000GWB002000DAL   0000022700Y
S28958828A3K27G60000GXS002000DD    0001346500Y
S28959351AAK27GA0001DWB002000SPLS  0000090700Y
S28959360XAK27GA00015J002000
S28959366X5K27GA00008Y002000
S28959392XBK27GA0000X9002000
S28959401X7K27GA000088002000
S28959426A6K27GA0000DPB002000JNJ   0000645300Y
S28959441XBK27GA00019V002000
S28959444X1K27GA0000EZ002000
S28959450X2K27G60000GS002000
S28959459X2K27G60000GU002000
S28959474X2K27G60000GX002000
S28959474A7K27GA000089B002000LMT   0000471100Y
S28959489X3K27G60000GM002000
S28959504X3K27G60000GR002000
S28959506ABK27GA00019WB002000TGT   0000523500Y
S28959511X3K27G60000GS002000
S28959516A5K27GA000090S002000FNM   0001250500Y
S28959533ABK27GA00019XB002000UTX   0000311100Y
S28959537XCK27GA00006F002000
S28959559ABK27GA00019YS002000UTX   0001455700Y
S28959569X1K27GA0000F0002000
S28959580X1K27GA0000F1002000
S28959586A1K27GA0000F2B002000ABT   0000235900Y
S28959606A2K27G60000GZB002000AXP   0000426100Y
S28959610X2K27G60000GV002000
S28959622X2K27G60000GO002000
S28959634X2K27G60000GY002000
S28959640ABK27GA00019ZS002000UTX   0001456500Y
S28959649X2K27G60000AU002000
S28959662X3K27G60000GT002000
S28959668ACK27GA00006GB002000WYE   0000183600Y
S28959675X3K27G60000GU002000
S28959684X3K27G60000GV002000
S28959690X3K27G60000GX002000
S28959696A2K27G60000H0B002000AZN   0000423800Y
S28959703XAK27GA0000EX000500
S28959703AAK27GA0000EXB000500SPY   0001425700Y
S28959703XAK27GA0000FE000500
S28959703AAK27GA0000FEB000500SPY   0001425700Y
S28959704XAK27GA0000E7001000
S28959704AAK27GA0000E7B001000SPY   0001425700Y
S28959705A1K27GA0000F3B002000AFL   0000287300Y
S28959715A2K27G60000H1S002000BAX   0000636900Y
S28959718A1K27GA0000F4S002000AFL   0001440100Y
S28959742A2K27G60000H2B002000AXP   0000425300Y
S28959756A3K27G60000GYS002000COH   0001287600Y
S28959761A3K27G60000GZB002000CVS   0000179200Y
S28960353X3K27G60000G4002000
S28960393X2K27G60000GR002000
S28960394X5K27GA000090002000
S28960437XAK27GA000124002000
S28960438X5K27GA00008G002000
S28960438X7K27GA000089002000
S28960441XBK27GA00019X002000
S28960456XBK27GA00019Z002000
S28960465XCK27GA00006G002000
S28960479AAK27GA0001DXS002000SEPR  0000228900Y
S28960486X1K27GA0000F3002000
S28960489XBK27GA00019Y002000
S28960497X1K27GA0000F4002000
S28960502X1K27GA0000F2002000
S28960515X1K27GA0000A2002000
S28960516X2K27G60000GT002000
S28960520XAK27GA00013T002000
S28960520XAK27GA0000FI000500
S28960520AAK27GA0000FIB000500SPY   0001425600Y
S28960520XAK27GA0000NY000500
S28960520AAK27GA0000NYS000500SPY   0001426200Y
S28960520XAK27GA0000E9001000
S28960520AAK27GA0000E9S001000SPY   0001426200Y
S28960520X4K27GA0000JP000200
S28960520XAK27GA0000QB000500
S28960520AAK27GA0000QBS000500SPY   0001426200Y
S28960520XAK27GA0001D1002000
S28960521X4K27GA0000DX000200
S28960521A4K27GA0000DXB000200DIA   0001298900Y
S28960521A4K27GA0000KES000123DIA   0001299300Y
S28960522XAK27GA0001DF000500
S28960523XAK27GA0000F5000500
S28960523AAK27GA0000F5B000500SPY   0001425600Y
S28960523XAK27GA0001DD002500
S28960523XAK27GA0001DI005000
S28960523A4K27GA0000KFB000100DOG   0000596800Y
S28960523AAK27GA0001DYB000500SPY   0001425900Y
S28960524X3K27G60000EK000100
S28960523A4K27GA0000KGB000100DXD   0000499100Y
S28960523AAK27GA0001DZB002500SPY   0001425900Y
S28960524A3K27G60000H0S000100DDM   0000803100Y
S28960523AAK27GA0001E0B005000SPY   0001425700Y
S28960524XAK27GA0001DS005000
S28960526ABK27GA0001A0S002000TEVA  0000485500Y
S28960527XBK27GA00018O001000
S28960535XAK27GA0001DU001000
S28960536XAK27GA00013L002000
S28960536XAK27GA0001CY001000
S28960537AAK27GA0001E1S001000SPY   0001426200Y
S28960538X2K27G60000GD002000
S28960540X3K27G60000EL000100
S28960539X4K27GA0000JU000100
S28960541XAK27GA0001CT003000
S28960541XAK27GA0001CQ003000
S28960541XAK27GA0001D7001000
S28960542AAK27GA0001E2S002000SPY   0001426200Y
S28960542X9K27G60000G4002000
S28960542A9K27G60000G4B002000QQQQ  0000495400Y
S28960542X9K27G60000G5002000
S28960542A9K27G60000G5S002000QQQQ  0000496000Y
S28960542XAK27GA0000F7000500
S28960542AAK27GA0000F7B000500SPY   0001425500Y
S28960542XAK27GA0000FG000500
S28960542AAK27GA0000FGB000500SPY   0001425500Y
S28960542XAK27GA0001CW001000
S28960542XAK27GA0001CR003000
S28960542XAK27GA0001CU003000
S28960542AAK27GA0001E3S002000SPY   0001426300Y
S28960542AAK27GA0001E4S003000SPY   0001426200Y
S28960542XAK27GA0000E8001000
S28960542AAK27GA0000E8B001000SPY   0001425600Y
S28960542AAK27GA0001E5S003000SPY   0001426200Y
S28960542X4K27GA00007C000200
S28960542A4K27GA00007CB000200DIA   0001298800Y
S28960543X2K27G60000GW002000
S28960543XAK27GA0001BY000500
S28960543AAK27GA0001BYS000500SPY   0001426200Y
S28960543AAK27GA0001E6B000100SH    0000618100Y
S28960543AAK27GA0001E7B000900SPY   0001425700Y
S28960543AAK27GA0001E8B003000SPY   0001425200Y
S28960543AAK27GA0001E9B003000SPY   0001425200Y
S28960544ABK27GA0001A1S001000SSO   0000765800Y
S28960544XBK27GA00019B001000
S28960543XAK27GA0000O8000500
S28960543AAK27GA0000O8S000500SPY   0001426200Y
S28960544XBK27GA00018M001000
S28960544ABK27GA0001A2B001000SSO   0000764700Y
S28960544XAK27GA0000E6001000
S28960544AAK27GA0000E6S001000SPY   0001426200Y
S28960546ABK27GA0001A3B001000SSO   0000764900Y
S28960545XAK27GA0001DZ002500
S28960546XAK27GA0001D8001000
S28960547XAK27GA0001CV001000
S28960547XAK27GA0001DY000500
S28960548AAK27GA0001EAS001000SPY   0001426200Y
S28960550XAK27GA0001CW001000
S28960550AAK27GA0001EBB001000SPY   0001425700Y
S28960552AAK27GA0001ECB001000SPY   0001425700Y
S28960556X3K27G60000GY002000
S28960556XBK27GA0001A2001000
S28960557A5K27GA000091S002000FNM   0001245000Y
S28960557X6K27GA00007U000500
S28960557A6K27GA00007UB000500IWM   0000736700Y
S28960559X3K27G60000GZ002000
S28960558A6K27GA0000DQS002000IWM   0000737500Y
S28960559XAK27GA0001EC001000
S28960559A6K27GA0000DRS002000IWM   0000737600Y
S28960563XBK27GA00018K000100
S28960563XBK27GA00018L000100
S28960564ABK27GA0001A4S000100TWM   0000701400Y
S28960574A7K27GA00008AB002000LMT   0000473300Y
S28960575AAK27GA0001EDS002000SPY   0001426200Y
S28960575X6K27GA0000DB002000
S28960577A8K27G600006HB000500MZZ   0000491200Y
S28960577A8K27G600006IS000100MVV   0000809900Y
S28960580X3K27G60000EI000100
S28960580ABK27GA0001A5B002000UTX   0000312300Y
S28960591A1K27GA0000F5B002000ABT   0000236600Y
S28960593ACK27GA00006HB002000WYE   0000185600Y
S28960595X9K27G60000SZ002000
S28960596XAK27GA0001ED002000
S28960605A2K27G60000H3S002000BA    0001511200Y
S28960605A1K27GA0000F6B002000AFL   0000289900Y
S28960606XAK27GA0001EB001000
S28960606AAK27GA0001EEB001000SPY   0001425600Y
S28960608X8K27G6000068000500
S28960608X8K27G6000069000100
S28960608X8K27G600006F000100
S28960608AAK27GA0001EFB001000SPY   0001425600Y
S28960610A8K27G600006JS000500MZZ   0000493400Y
S28960610A8K27G600006KB000100MVV   0000807100Y
S28960617A1K27GA0000F7S002000AFL   0001435700Y
S28960620A2K27G60000H4S002000BBT   0001271900Y
S28960621A9K27G60000T5B002000QQQQ  0000495700Y
S28960622X9K27G60000T5002000
S28960629A2K27G60000H5S002000BA    0001510400Y
S28960641A2K27G60000H6S002000CAG   0001224800Y
S28960643X9K27G60000F3003200
S28960643A9K27G60000F3B003200QQQQ  0000495400Y
S28960648XAK27GA0001BY000500
S28960648AAK27GA0001BYS000500SPY   0001426100Y
S28960648XAK27GA0000O8000500
S28960648AAK27GA0000O8S000500SPY   0001426100Y
S28960648XAK27GA0000E6001000
S28960648AAK27GA0000E6S001000SPY   0001426100Y
S28960648XAK27GA0001EA001000
S28960648AAK27GA0001EAS001000SPY   0001426100Y
S28960649X9K27G60000F3003200
S28960649A9K27G60000F3B003200QQQQ  0000495900Y
S28960649X4K27GA0000JE000200
S28960650A4K27GA0000KHS000123DIA   0001299200Y
S28960650A4K27GA0000KIB000100DXD   0000499200Y
S28960651A3K27G60000H1S000100DDM   0000803000Y
S28960650X6K27GA00002B000500
S28960650A6K27GA00002BS000500IWM   0000737200Y
S28960652AAK27GA0001EGS002000SPY   0001426200Y
S28960653ABK27GA0001A6S000100UWM   0000544100Y
S28960652X6K27GA0000DC002000
S28960656X2K27G60000GA002000
S28960667A3K27G60000H2B002000COH   0000150100Y
S28960666X6K27GA0000B6000500
S28960666A6K27GA0000B6B000500IWM   0000736600Y
S28960671A2K27G60000H7B002000BBT   0000143700Y
S28960673XBK27GA00018H000100
S28960671X6K27GA0000B6000500
S28960671A6K27GA0000B6B000500IWM   0000737000Y
S28960673XBK27GA0001A4000100
S28960675ABK27GA0001A7B000100UWM   0000543100Y
S28960675ABK27GA0001A8S000100TWM   0000701400Y
S28960678X6K27GA0000B6000500
S28960678A6K27GA0000B6B000500IWM   0000736600Y
S28960681XBK27GA0001A7000100
S28960682XBK27GA0001A8000100
S28960681X6K27GA0000B6000500
S28960681A6K27GA0000B6B000500IWM   0000737000Y
S28960683ABK27GA0001A9B000100UWM   0000543100Y
S28960683ABK27GA0001AAS000100TWM   0000701400Y
S28960682X6K27GA0000B6000500
S28960682A6K27GA0000B6B000500IWM   0000736600Y
S28960686XBK27GA0001A9000100
S28960686XBK27GA0001AA000100
S28960688ABK27GA0001ABS000100TWM   0000701600Y
S28960689A2K27G60000H8S002000BBT   0001271100Y
S28960689X6K27GA0000B6000500
S28960689A6K27GA0000B6B000500IWM   0000737000Y
S28960691A3K27G60000H3S002000CVS   0001312100Y
S28960691ABK27GA0001ACB000100UWM   0000543100Y
S28960691ABK27GA0001ADS000100TWM   0000701400Y
S28960691XBK27GA0001AB000100
S28960691X6K27GA0000B6000500
S28960691A6K27GA0000B6B000500IWM   0000736600Y
S28960702A3K27G60000H4B002000DAL   0000022300Y
S28960702XBK27GA0001AC000100
S28960701X6K27GA0000B6000500
S28960701A6K27GA0000B6B000500IWM   0000737000Y
S28960702XBK27GA0001AD000100
S28960704ABK27GA0001AES000100TWM   0000701400Y
S28960704ABK27GA0001AFB000100UWM   0000543100Y
S28960706X6K27GA0000B6000500
S28960706A6K27GA0000B6B000500IWM   0000736600Y
S28960709A3K27G60000H5S002000DD    0001339000Y
S28960709X6K27GA0000B6000500
S28960709A6K27GA0000B6B000500IWM   0000737000Y
S28960711A2K27G60000H9S002000BSX   0000151000Y
S28960710A6K27GA0000DSB002000IWM   0000736500Y
S28960711X6K27GA0000B6000500
S28960711A6K27GA0000B6B000500IWM   0000736600Y
S28960721X6K27GA0000B6000500
S28960721A6K27GA0000B6B000500IWM   0000737000Y
S28960722XBK27GA0001AF000100
S28960723XBK27GA0001AE000100
S28960724ABK27GA0001AGB000100UWM   0000543100Y
S28960723A6K27GA0000DTB000100IWM   0000736500Y
S28960723X6K27GA0000DT000100
S28960725ABK27GA0001AHS000100TWM   0000701400Y
S28960731X6K27GA0000B6000500
S28960731A6K27GA0000B6B000500IWM   0000736600Y
S28960733A2K27G60000HAB002000CAG   0000095700Y
S28960734XBK27GA0001AG000100
S28960734XBK27GA0001AH000100
S28960736ABK27GA0001AIS000100TWM   0000701600Y
S28960735X6K27GA0000B6000500
S28960735A6K27GA0000B6B000500IWM   0000737000Y
S28960737ABK27GA0001AJB000100UWM   0000543100Y
S28960738ABK27GA0001AKS000100TWM   0000701400Y
S28960738XBK27GA0001AI000100
S28960740A4K27GA0000KJB002000DOW   0000401200Y
S28960741X6K27GA0000B6000500
S28960741A6K27GA0000B6B000500IWM   0000736600Y
S28960744XBK27GA0001AJ000100
S28960745XBK27GA0001AK000100
S28960746ABK27GA0001ALS000100TWM   0000701600Y
S28960746X6K27GA0000B6000500
S28960746A6K27GA0000B6B000500IWM   0000737000Y
S28960751X6K27GA0000B6000500
S28960751A6K27GA0000B6B000500IWM   0000736600Y
S28960757AAK27GA0001EHB000500SPY   0001425700Y
S28960758XAK27GA0001DB000500
S28960758X9K27G60000F3003200
S28960758A9K27G60000F3B003200QQQQ  0000495400Y
S28960761X6K27GA0000B6000500
S28960761A6K27GA0000B6B000500IWM   0000737000Y
S28960762ABK27GA0001AMB000100UWM   0000543100Y
S28960763XBK27GA0001AL000100
S28960763ABK27GA0001ANS000100TWM   0000701400Y
S28960772XBK27GA0001AM000100
S28960771X6K27GA0000B6000500
S28960771A6K27GA0000B6B000500IWM   0000736600Y
S28960772XBK27GA0001AN000100
S28960773A6K27GA0000DUB000100IWM   0000736500Y
S28960774ABK27GA0001AOS000100TWM   0000701600Y
S28960773X6K27GA0000DU000100
S28960773X6K27GA0000B6000500
S28960773A6K27GA0000B6B000500IWM   0000737000Y
S28960781X6K27GA0000B6000500
S28960781A6K27GA0000B6B000500IWM   0000736600Y
S28960783ABK27GA0001APB000100UWM   0000543100Y
S28960783XBK27GA0001AP000100
S28960783XBK27GA0001AO000100
S28960783ABK27GA0001AQS000100TWM   0000701400Y
S28960783XBK27GA0001AQ000100
S28960785ABK27GA0001ARS000100TWM   0000701600Y
S28960789A2K27G60000HBS002000CAG   0001224000Y
S28960791X8K27G600006J000500
S28960791X8K27G600005U000500
S28960791X8K27G600005W000500
S28960791X8K27G600005X000100
S28960791X8K27G600006K000100
S28960793A8K27G600006LS000500MZZ   0000493500Y
S28960793A8K27G600006MB000100MVV   0000807000Y
S28960791X6K27GA0000B6000500
S28960791A6K27GA0000B6B000500IWM   0000737000Y
S28960793ABK27GA0001ASB000100UWM   0000543100Y
S28960793XBK27GA0001AR000100
S28960793ABK27GA0001ATS000100TWM   0000701400Y
S28960799A3K27G60000H6B002000COH   0000150900Y
S28960801X6K27GA0000B6000500
S28960801A6K27GA0000B6B000500IWM   0000736600Y
S28960803XBK27GA0001AS000100
S28960803XBK27GA0001AT000100
S28960804ABK27GA0001AUS000100TWM   0000701600Y
S28960811X6K27GA0000B6000500
S28960811A6K27GA0000B6B000500IWM   0000737000Y
S28960812ABK27GA0001AVB000100UWM   0000543100Y
S28960813XBK27GA0001AU000100
S28960813ABK27GA0001AWS000100TWM   0000701400Y
S28960821X6K27GA0000B6000500
S28960821A6K27GA0000B6B000500IWM   0000736600Y
S28960823XBK27GA0001AV000100
S28960823XBK27GA0001AW000100
S28960823A6K27GA0000DVB000100IWM   0000736500Y
S28960825ABK27GA0001AXS000100TWM   0000701600Y
S28960823X6K27GA0000DV000100
S28960824X6K27GA0000B6000500
S28960824A6K27GA0000B6B000500IWM   0000737000Y
S28960831X6K27GA0000B6000500
S28960831A6K27GA0000B6B000500IWM   0000736600Y
S28960841X6K27GA0000B6000500
S28960841A6K27GA0000B6B000500IWM   0000737000Y
S28960851X6K27GA0000B6000500
S28960851A6K27GA0000B6B000500IWM   0000736600Y
S28960857X9K27G60000F3003200
S28960857A9K27G60000F3B003200QQQQ  0000495900Y
S28960861X6K27GA0000B6000500
S28960861A6K27GA0000B6B000500IWM   0000737000Y
S28960871X6K27GA0000B6000500
S28960871A6K27GA0000B6B000500IWM   0000736600Y
S28960881X6K27GA0000B6000500
S28960881A6K27GA0000B6B000500IWM   0000737000Y
S28960891X6K27GA0000B6000500
S28960891A6K27GA0000B6B000500IWM   0000736600Y
S28960901X6K27GA0000B6000500
S28960901A6K27GA0000B6B000500IWM   0000737000Y
S28960911X6K27GA0000B6000500
S28960911A6K27GA0000B6B000500IWM   0000736600Y
S28960921X6K27GA0000B6000500
S28960921A6K27GA0000B6B000500IWM   0000737000Y
S28960931XAK27GA0001CP001000
S28960931X6K27GA0000B6000500
S28960931A6K27GA0000B6B000500IWM   0000736600Y
S28960933AAK27GA0001EIB000900SPY   0001425600Y
S28960933AAK27GA0001EJS005000SPY   0001426200Y
S28960933XBK27GA0001A3001000
S28960933ABK27GA0001AYB001000SSO   0000764600Y
S28960934AAK27GA0001EKB002500SPY   0001425700Y
S28960934XAK27GA0001DE002500
S28960935ABK27GA0001AZB001000SSO   0000764800Y
S28960936XAK27GA0001CX000100
S28960941X6K27GA0000B6000500
S28960941A6K27GA0000B6B000500IWM   0000737000Y
S28960949X9K27G60000F3003200
S28960949A9K27G60000F3B003200QQQQ  0000495400Y
S28960950XAK27GA0000EB001000
S28960950AAK27GA0000EBB001000SPY   0001425500Y
S28960951X6K27GA0000B6000500
S28960951A6K27GA0000B6B000500IWM   0000736600Y
S28960961AAK27GA0001ELS000500SPY   0001426100Y
S28960962XAK27GA0001BV000500
S28960962AAK27GA0001BVS000500SPY   0001426100Y
S28960961X6K27GA0000B6000500
S28960961A6K27GA0000B6B000500IWM   0000737000Y
S28960964AAK27GA0001EMB001000SDS   0000547300Y
S28960964XAK27GA0001DM001000
S28960964ABK27GA0001B0S001000SSO   0000765700Y
S28960964XBK27GA0001A1001000
S28960965XAK27GA0001BV000500
S28960965AAK27GA0001BVS000500SPY   0001426400Y
S28960966XAK27GA0001EM001000
S28960967XBK27GA0001B0001000
S28960968AAK27GA0001ENB001000SDS   0000547200Y
S28960969ABK27GA0001B1S001000SSO   0000765800Y
S28960972X6K27GA0000B6000500
S28960972A6K27GA0000B6B000500IWM   0000736600Y
S28960976XAK27GA0001BV000500
S28960976AAK27GA0001BVS000500SPY   0001426100Y
S28960977XAK27GA0001EN001000
S28960977AAK27GA0001EOB001000SDS   0000547300Y
S28960977ABK27GA0001B2S001000SSO   0000765700Y
S28960977XBK27GA0001B1001000
S28960981X6K27GA0000B6000500
S28960981A6K27GA0000B6B000500IWM   0000737000Y
S28960986XAK27GA0001BV000500
S28960986AAK27GA0001BVS000500SPY   0001426400Y
S28960986XAK27GA0001EO001000
S28960987XBK27GA0001B2001000
S28960988AAK27GA0001EPB001000SDS   0000547200Y
S28960989ABK27GA0001B3S001000SSO   0000765800Y
S28960989XAK27GA0001BV000500
S28960989AAK27GA0001BVS000500SPY   0001426100Y
S28960990XAK27GA0001EP001000
S28960990AAK27GA0001EQB001000SDS   0000547300Y
S28960990ABK27GA0001B4S001000SSO   0000765700Y
S28960990XBK27GA0001B3001000
S28960992X6K27GA0000B6000500
S28960992A6K27GA0000B6B000500IWM   0000736600Y
S28960996XAK27GA0001BV000500
S28960996AAK27GA0001BVS000500SPY   0001426400Y
S28960996XAK27GA0001EQ001000
S28960997XBK27GA0001B4001000
S28960999ABK27GA0001B5S001000SSO   0000765800Y
S28960999ABK27GA0001B6S001000SSO   0000766900Y
S28960998AAK27GA0001ERB001000SDS   0000547200Y
S28961002X6K27GA0000B6000500
S28961002A6K27GA0000B6B000500IWM   0000737000Y
S28961006XAK27GA0001BV000500
S28961006AAK27GA0001BVS000500SPY   0001426100Y
S28961007XAK27GA0001ER001000
S28961007AAK27GA0001ESB001000SDS   0000547300Y
S28961007XBK27GA0001B5001000
S28961007ABK27GA0001B7S001000SSO   0000765700Y
S28961012X6K27GA0000B6000500
S28961012A6K27GA0000B6B000500IWM   0000736600Y
S28961015XAK27GA0001BV000500
S28961015AAK27GA0001BVS000500SPY   0001426400Y
S28961016XAK27GA0001ES001000
S28961017XBK27GA0001B7001000
S28961018AAK27GA0001ETB001000SDS   0000547200Y
S28961019ABK27GA0001B8S001000SSO   0000765800Y
S28961021X6K27GA0000B6000500
S28961021A6K27GA0000B6B000500IWM   0000737000Y
S28961025XAK27GA0001BV000500
S28961025AAK27GA0001BVS000500SPY   0001426100Y
S28961026AAK27GA0001EUB001000SDS   0000547300Y
S28961027XAK27GA0001ET001000
S28961027XBK27GA0001B8001000
S28961027ABK27GA0001B9S001000SSO   0000765700Y
S28961035XAK27GA0001BV000500
S28961035AAK27GA0001BVS000500SPY   0001426400Y
S28961036XAK27GA0001EU001000
S28961037XBK27GA0001B9001000
S28961038AAK27GA0001EVB001000SDS   0000547200Y
S28961039ABK27GA0001BAS001000SSO   0000765800Y
S28961046XAK27GA0001BV000500
S28961046AAK27GA0001BVS000500SPY   0001426000Y
S28961047AAK27GA0001EWB001000SDS   0000547300Y
S28961047XBK27GA0001BA001000
S28961047ABK27GA0001BBS001000SSO   0000765700Y
S28961047XAK27GA0001EV001000
S28961055XAK27GA0001BV000500
S28961055AAK27GA0001BVS000500SPY   0001426400Y
S28961057XAK27GA0001EW001000
S28961058XBK27GA0001BB001000
S28961059X9K27G60000F3003200
S28961059A9K27G60000F3B003200QQQQ  0000495900Y
S28961059AAK27GA0001EXB001000SDS   0000547200Y
S28961059ABK27GA0001BCS001000SSO   0000765800Y
S28961066XAK27GA0001BV000500
S28961066AAK27GA0001BVS000500SPY   0001426000Y
S28961067XBK27GA0001BC001000
S28961067AAK27GA0001EYB001000SDS   0000547300Y
S28961067XAK27GA0001EX001000
S28961067ABK27GA0001BDS001000SSO   0000765700Y
S28961076XAK27GA0001BV000500
S28961076AAK27GA0001BVS000500SPY   0001426400Y
S28961078XAK27GA0001EY001000
S28961078XBK27GA0001BD001000
S28961080ABK27GA0001BES001000SSO   0000765800Y
S28961079AAK27GA0001EZB001000SDS   0000547200Y
S28961086XAK27GA0001BV000500
S28961086AAK27GA0001BVS000500SPY   0001426000Y
S28961088AAK27GA0001F0B001000SDS   0000547300Y
S28961088XAK27GA0001EZ001000
S28961088ABK27GA0001BFS001000SSO   0000765700Y
S28961088XBK27GA0001BE001000
S28961093XAK27GA0001BV000500
S28961093AAK27GA0001BVS000500SPY   0001426400Y
S28961095XAK27GA0001BV000500
S28961095AAK27GA0001BVS000500SPY   0001426000Y
S28961098XAK27GA0001F0001000
S28961098XBK27GA0001BF001000
S28961100ABK27GA0001BGS001000SSO   0000765700Y
S28961100AAK27GA0001F1B001000SDS   0000547300Y
S28961103XAK27GA0001BV000500
S28961103AAK27GA0001BVS000500SPY   0001426400Y
S28961105XAK27GA0001F1001000
S28961105XBK27GA0001BG001000
S28961106XAK27GA0001BV000500
S28961106AAK27GA0001BVS000500SPY   0001426000Y
S28961107ABK27GA0001BHS001000SSO   0000765800Y
S28961107AAK27GA0001F2B001000SDS   0000547200Y
S28961107XAK27GA0001F2001000
S28961107AAK27GA0001F3B001000SDS   0000547300Y
S28961108XBK27GA0001BH001000
S28961108ABK27GA0001BIS001000SSO   0000765700Y
S28961116XAK27GA0001BV000500
S28961116AAK27GA0001BVS000500SPY   0001426400Y
S28961117XAK27GA0001F3001000
S28961118XBK27GA0001BI001000
S28961119AAK27GA0001F4B001000SDS   0000547200Y
S28961120ABK27GA0001BJS001000SSO   0000765800Y
S28961123ABK27GA0001BKB000100UWM   0000543100Y
S28961123ABK27GA0001BLS000100TWM   0000701400Y
S28961123XBK27GA0001AX000100
S28961126XAK27GA0001BV000500
S28961126AAK27GA0001BVS000500SPY   0001426000Y
S28961127XAK27GA0001F4001000
S28961127AAK27GA0001F5B001000SDS   0000547300Y
S28961128XBK27GA0001BJ001000
S28961128ABK27GA0001BMS001000SSO   0000765700Y
S28961136XAK27GA0001BV000500
S28961136AAK27GA0001BVS000500SPY   0001426400Y
S28961137XAK27GA0001F5001000
S28961139AAK27GA0001F6B001000SDS   0000547200Y
S28961138XBK27GA0001BM001000
S28961140ABK27GA0001BNS001000SSO   0000765800Y
S28961146XAK27GA0001BV000500
S28961146AAK27GA0001BVS000500SPY   0001426000Y
S28961147AAK27GA0001F7B001000SDS   0000547300Y
S28961148XBK27GA0001BN001000
S28961147XAK27GA0001F6001000
S28961148ABK27GA0001BOS001000SSO   0000765700Y
S28961156XAK27GA0001BV000500
S28961156AAK27GA0001BVS000500SPY   0001426400Y
S28961158XAK27GA0001F7001000
S28961158XBK27GA0001BO001000
S28961159AAK27GA0001F8B001000SDS   0000547200Y
S28961160ABK27GA0001BPS001000SSO   0000765800Y
S28961166XAK27GA0001BV000500
S28961166AAK27GA0001BVS000500SPY   0001426000Y
S28961176XAK27GA0001BV000500
S28961176AAK27GA0001BVS000500SPY   0001426400Y
S28961186XAK27GA0001BV000500
S28961186AAK27GA0001BVS000500SPY   0001426000Y
S28961196XAK27GA0001BV000500
S28961196AAK27GA0001BVS000500SPY   0001426400Y
S28961205XAK27GA0001BV000500
S28961205AAK27GA0001BVS000500SPY   0001426000Y
S28961216XAK27GA0001BV000500
S28961216AAK27GA0001BVS000500SPY   0001426400Y
S28961226XAK27GA0001BV000500
S28961226AAK27GA0001BVS000500SPY   0001426000Y
S28961235XAK27GA0001BV000500
S28961235AAK27GA0001BVS000500SPY   0001426400Y
S28961245XAK27GA0001BV000500
S28961245AAK27GA0001BVS000500SPY   0001426000Y
S28961255XAK27GA0001BV000500
S28961255AAK27GA0001BVS000500SPY   0001426400Y
S28961265XAK27GA0001BV000500
S28961265AAK27GA0001BVS000500SPY   0001426000Y
S28961275XAK27GA0001BV000500
S28961275AAK27GA0001BVS000500SPY   0001426400Y
S28961286XAK27GA0001BV000500
S28961286AAK27GA0001BVS000500SPY   0001426000Y
S28961296XAK27GA0001BV000500
S28961296AAK27GA0001BVS000500SPY   0001426400Y
S28961306XAK27GA0001BV000500
S28961306AAK27GA0001BVS000500SPY   0001426000Y
S28961316XAK27GA0001BV000500
S28961316AAK27GA0001BVS000500SPY   0001426400Y
S28961325XAK27GA0001BV000500
S28961325AAK27GA0001BVS000500SPY   0001426000Y
S28961334AAK27GA0001F9S002500SPY   0001426100Y
S28961335XAK27GA0001BV000500
S28961335AAK27GA0001BVS000500SPY   0001426400Y
S28961346XAK27GA0001BV000500
S28961346AAK27GA0001BVS000500SPY   0001426000Y
S28961351X1K27GA0000EA002000
S28961355XAK27GA0001BV000500
S28961355AAK27GA0001BVS000500SPY   0001426400Y
S28961360X3K27G60000GQ002000
S28961365XAK27GA0001BV000500
S28961365AAK27GA0001BVS000500SPY   0001426000Y
S28961375XAK27GA0001BV000500
S28961375AAK27GA0001BVS000500SPY   0001426400Y
S28961385XAK27GA0001BV000500
S28961385AAK27GA0001BVS000500SPY   0001426000Y
S28961391X6K27GA0000B6000500
S28961394X7K27GA00008A002000
S28961394XBK27GA0001BK000100
S28961394XBK27GA0001BL000100
S28961396XAK27GA0001BV000500
S28961396AAK27GA0001BVS000500SPY   0001426400Y
S28961396ABK27GA0001BQS000100TWM   0000701600Y
S28961395A6K27GA0000DWB000500IWM   0000737000Y
S28961399XBK27GA0001BQ000100
S28961399ABK27GA0001BRB000100UWM   0000543100Y
S28961399ABK27GA0001BSS000100TWM   0000701400Y
S28961401X6K27GA0000DW000500
S28961401A6K27GA0000DWB000500IWM   0000736600Y
S28961404XBK27GA0001BR000100
S28961404XBK27GA0001BS000100
S28961405XAK27GA0001BV000500
S28961405AAK27GA0001BVS000500SPY   0001426000Y
S28961406ABK27GA0001BTS000100TWM   0000701600Y
S28961411X6K27GA0000DW000500
S28961411A6K27GA0000DWB000500IWM   0000737000Y
S28961413A2K27G60000HCB002000BMY   0000090300Y
S28961414XBK27GA0001BT000100
S28961414ABK27GA0001BUB000100UWM   0000543100Y
S28961414ABK27GA0001BVS000100TWM   0000701400Y
S28961415XBK27GA0001A5002000
S28961416XAK27GA0001BV000500
S28961416AAK27GA0001BVS000500SPY   0001426400Y
S28961421X6K27GA0000DW000500
S28961421A6K27GA0000DWB000500IWM   0000736600Y
S28961424XBK27GA0001BU000100
S28961424XBK27GA0001BV000100
S28961423XCK27GA00005U002000
S28961425XAK27GA0001BV000500
S28961425AAK27GA0001BVS000500SPY   0001426000Y
S28961426ABK27GA0001BWS000100TWM   0000701600Y
S28961425X6K27GA0000DW000500
S28961425A6K27GA0000DWB000500IWM   0000737000Y
S28961427A3K27G60000H7B002000CELG  0000510400Y
S28961426A6K27GA0000DXB000100IWM   0000736500Y
S28961426X6K27GA0000DX000100
S28961428ABK27GA0001BXB000100UWM   0000543100Y
S28961428XBK27GA0001BW000100
S28961428ABK27GA0001BYS000100TWM   0000701400Y
S28961431X6K27GA0000DW000500
S28961431A6K27GA0000DWB000500IWM   0000736600Y
S28961433X1K27GA0000F5002000
S28961434XBK27GA0001BX000100
S28961434XBK27GA0001BY000100
S28961436ABK27GA0001BZS000100TWM   0000701600Y
S28961439X6K27GA0000DW000500
S28961439A6K27GA0000DWB000500IWM   0000737000Y
S28961442X9K27G60000F3003200
S28961442A9K27G60000F3B003200QQQQ  0000495400Y
S28961441X6K27GA0000DW000500
S28961441A6K27GA0000DWB000500IWM   0000736600Y
S28961442ABK27GA0001C0B000100UWM   0000543100Y
S28961442XBK27GA0001BZ000100
S28961443ABK27GA0001C1S000100TWM   0000701400Y
S28961444XBK27GA0001C0000100
S28961444XBK27GA0001C1000100
S28961444A6K27GA0000DYB000100IWM   0000736500Y
S28961446ABK27GA0001C2S000100TWM   0000701600Y
S28961445X6K27GA0000DY000100
S28961445X6K27GA0000DW000500
S28961445A6K27GA0000DWB000500IWM   0000737000Y
S28961449ABK27GA0001C3B000100UWM   0000543100Y
S28961449XBK27GA0001C2000100
S28961449ABK27GA0001C4S000100TWM   0000701400Y
S28961451X6K27GA0000DW000500
S28961451A6K27GA0000DWB000500IWM   0000736600Y
S28961454XBK27GA0001C3000100
S28961454XBK27GA0001C4000100
S28961456X2K27G60000H3002000
S28961456ABK27GA0001C5S000100TWM   0000701600Y
S28961461X6K27GA0000DW000500
S28961461A6K27GA0000DWB000500IWM   0000737000Y
S28961464ABK27GA0001C6B000100UWM   0000543100Y
S28961465XBK27GA0001C5000100
S28961465ABK27GA0001C7S000100TWM   0000701400Y
S28961471X6K27GA0000DW000500
S28961471A6K27GA0000DWB000500IWM   0000736600Y
S28961474XBK27GA0001C6000100
S28961474XBK27GA0001C7000100
S28961474A6K27GA0000DZB000100IWM   0000736500Y
S28961476ABK27GA0001C8S000100TWM   0000701600Y
S28961475X6K27GA0000DZ000100
S28961476AAK27GA0001FAB002000SINA  0000511900Y
S28961475X6K27GA0000DW000500
S28961475A6K27GA0000DWB000500IWM   0000737000Y
S28961478ABK27GA0001C9B000100UWM   0000543100Y
S28961479ABK27GA0001CAS000100TWM   0000701400Y
S28961479XBK27GA0001C8000100
S28961479X5K27GA000091002000
S28961480X2K27G60000H4002000
S28961481X6K27GA0000DW000500
S28961481A6K27GA0000DWB000500IWM   0000736600Y
S28961484XBK27GA0001C9000100
S28961484XBK27GA0001CA000100
S28961486X2K27G60000H6002000
S28961484A6K27GA0000E0B000100IWM   0000736500Y
S28961486ABK27GA0001CBS000100TWM   0000701600Y
S28961485X6K27GA0000E0000100
S28961494X9K27G60000F3003200
S28961494A9K27G60000F3B003200QQQQ  0000495900Y
S28961498X2K27G60000DN002000
S28961497X6K27GA0000D1002000
S28961514X7K27GA00007F002000
S28961517X3K27G60000H3002000
S28961518XAK27GA0001F8001000
S28961518AAK27GA0001FBB001000SDS   0000547300Y
S28961518XBK27GA0001BP001000
S28961518ABK27GA0001CCS001000SSO   0000765700Y
S28961530X3K27G60000H5002000
S28961535A7K27GA00008BB002000LMT   0000477100Y
S28961542A5K27GA000092S002000FNM   0001241000Y
S28961561X9K27G60000F3003200
S28961561A9K27G60000F3B003200QQQQ  0000495400Y
S28961568ABK27GA0001CDB002000UTX   0000315100Y
S28961579ABK27GA0001CES002000UTX   0001448800Y
S28961586XCK27GA00006H002000
S28961592A5K27GA000093B002000GM    0000182000Y
S28961605A1K27GA0000F8B002000ABT   0000239000Y
S28961612A8K27G600006NB000500MZZ   0000491400Y
S28961612A8K27G600006OS000100MVV   0000809700Y
S28961623ABK27GA0001CFS002000UTX   0001449600Y
S28961623A1K27GA0000F9B002000ACF   0000121600Y
S28961637X1K27GA0000F6002000
S28961638ACK27GA00006IB002000WYE   0000186000Y
S28961648X1K27GA0000F7002000
S28961659X2K27G60000H5002000
S28961664A1K27GA0000FAB002000AFL   0000291000Y
S28961671X2K27G60000H8002000
S28961679A1K27GA0000FBS002000AFL   0001432900Y
S28961685A2K27G60000HDB002000BDX   0000783000Y
S28961698X2K27G60000HB002000
S28961700X3K27G60000H0000100
S28961716A3K27G60000H8S002000COH   0001277800Y
S28961721A2K27G60000HEB002000BBT   0000143900Y
S28961725X9K27G60000SV005000
S28961725X9K27G60000SW005000
S28961726A9K27G60000T6S005000QQQQ  0000496000Y
S28961726A9K27G60000T7S005000QQQQ  0000496000Y
S28961726X9K27G60000SU002000
S28961726A9K27G60000T8S002000QQQQ  0000496000Y
S28961734A2K27G60000HFB002000BDX   0000782200Y
S28961737A3K27G60000H9B002000CVS   0000182400Y
S28961738A2K27G60000HGB002000CAG   0000095600Y
S28961751A3K27G60000HAS002000COH   0001278600Y
S28961763A3K27G60000HBS002000CVS   0001307000Y
S28961768A3K27G60000HCB002000CVS   0000181600Y
S28961777X3K27G60000ET002000
S28962195X9K27G60000EN002000
S28962195A9K27G60000ENS002000QQQQ  0000496000Y
S28962358A1K27GA0000FCS002000AMGN  0000470100Y
S28962393X5K27GA000092002000
S28962402XBK27GA00019S002000
S28962404X7K27GA00008B002000
S28962404X6K27GA0000DI002000
S28962421XAK27GA0001DV002000
S28962421XBK27GA00019Q002000
S28962423XBK27GA0001CF002000
S28962430XCK27GA00006I002000
S28962437XBK27GA0001CD002000
S28962440A3K27G60000HDB002000CTSH  0000130700Y
S28962446XBK27GA0001CE002000
S28962449X1K27GA0000FA002000
S28962465X1K27GA0000FB002000
S28962477X1K27GA0000F8002000
S28962488X3K27G60000H2002000
S28962499X2K27G60000H7002000
S28962504A1K27GA0000FDB000100AAPL  0001830100Y
S28962506X3K27G60000HA002000
S28962510X1K27GA0000FD000100
S28962511A1K27GA0000FEB000020AAPL  0001831000Y
S28962517X2K27G60000HA002000
S28962528X3K27G60000HC002000
S28962528X3K27G60000H6002000
S28962531X3K27G60000H8002000
S28962531X3K27G60000H9002000
S28962535X3K27G60000HB002000
S28962537A7K27GA00008CB002000LMT   0000479300Y
S28962540X1K27GA0000FE000020
S28962540A1K27GA0000FEB000020AAPL  0001831100Y
S28962547A5K27GA000094S002000FNM   0001235500Y
S28962563A6K27GA0000E1S002000JNJ   0000687300Y
S28962564ABK27GA0001CGB002000UTX   0000316300Y
S28962573ACK27GA00006JS002000WYE   0000470500Y
S28962579A1K27GA0000FFB002000ABT   0000239600Y
S28962598A7K27GA00008DB002000KSS   0000460200Y
S28962608A2K27G60000HHS002000BA    0001505000Y
S28962629A2K27G60000HIS002000BBT   0001262700Y
S28962637ACK27GA00006KB002000WYE   0000188000Y
S28962650A2K27G60000HJS002000CAG   0001215100Y
S28962658A1K27GA0000FGB002000AFL   0000293600Y
S28962662A2K27G60000HKB002000CAT   0000821200Y
S28962671A1K27GA0000FHS002000AFL   0001428500Y
S28962680A3K27G60000HES002000CVS   0001303500Y
S28962686A2K27G60000HLS002000BA    0001504200Y
S28962698A3K27G60000HFS002000DD    0001330600Y
S28962702X9K27G60000T7005000
S28962702X9K27G60000T6005000
S28962702X9K27G60000F3003200
S28962702A9K27G60000F3B003200QQQQ  0000495900Y
S28962703A9K27G60000T9S005000QQQQ  0000496400Y
S28962704A9K27G60000TAS005000QQQQ  0000496400Y
S28962704A2K27G60000HMS002000BBT   0001261900Y
S28962705X9K27G60000EN002000
S28962705A9K27G60000ENS002000QQQQ  0000496300Y
S28962706X9K27G60000T8002000
S28962735A2K27G60000HNS002000CAG   0001214300Y
S28962753A3K27G60000HGS002000DD    0001329800Y
S28962808A9K27G60000TBB002000QQQQ  0000495700Y
S28963351A6K27GA0000E2S002000IMCL  0000503300Y
S28963363X2K27G60000HC002000
S28963374XAK27GA0001DW002000
S28963396X1K27GA000080002000
S28963399XAK27GA0001DP002000
S28963406X5K27GA000094002000
S28963408AAK27GA0001FCB002000SHLD  0000795400Y
S28963423X7K27GA00008C002000
S28963439XAK27GA0001DT000100
S28963438X6K27GA0000DM000100
S28963440XBK27GA0001CG002000
S28963441AAK27GA0001FDS000100SKF   0001028100Y
S28963440A6K27GA0000E3B000100IYF   0000856300Y
S28963440A6K27GA0000E4B000100IYF   0000856200Y
S28963440A6K27GA0000E5B000100IYF   0000856900Y
S28963440A6K27GA0000E6B000100IYF   0000856900Y
S28963440X6K27GA000022000100
S28963442ABK27GA0001CHS000100UYG   0000321200Y
S28963442XBK27GA00000T000100
S28963442A6K27GA0000E7S000100IYF   0000858300Y
S28963450XBK27GA0001CH000100
S28963448X6K27GA0000DN000100
S28963450X6K27GA0000E7000100
S28963452A6K27GA0000E8S000100IYF   0000858800Y
S28963452X6K27GA0000DK000100
S28963458X6K27GA0000E8000100
S28963458A6K27GA0000E9B002000IBM   0001242200Y
S28963461A6K27GA0000EAS000100IYF   0000859300Y
S28963472XCK27GA00005W002000
S28963479X1K27GA0000FF002000
S28963488X1K27GA00008X002000
S28963494X2K27G60000HH002000
S28963494A7K27GA00008EB002000LMT   0000483100Y
S28963502X2K27G60000HE002000
S28963512X2K27G60000HI002000
S28963516ABK27GA0001CIS002000TGT   0000610300Y
S28963520X2K27G60000HG002000
S28963519X6K27GA0000E5000100
S28963519A6K27GA0000E5B000100IYF   0000857000Y
S28963519X6K27GA0000E6000100
S28963519A6K27GA0000E6B000100IYF   0000857000Y
S28963526X2K27G60000HJ002000
S28963541X3K27G60000HE002000
S28963545X3K27G60000HF002000
S28963552ABK27GA0001CJB002000UTX   0000319100Y
S28963553A5K27GA000095S002000FNM   0001231500Y
S28963556XCK27GA00006K002000
S28963575ABK27GA0001CKS002000UTX   0001441800Y
S28963591X1K27GA0000D1002000
S28963594A6K27GA0000EBB002000IBM   0001241400Y
S28963597X1K27GA0000FG002000
S28963607X1K27GA0000FH002000
S28963618X1K27GA0000CY002000
S28963624ABK27GA0001CLS002000TGT   0000611100Y
S28963630X2K27G60000HL002000
S28963634A1K27GA0000FIB002000ABT   0000242000Y
S28963641ABK27GA0001CMS002000UTX   0001442600Y
S28963656ACK27GA00006LB002000WYE   0000188400Y
S28963659X2K27G60000HM002000
S28963665X2K27G60000E8002000
S28963679A2K27G60000HOB002000BBT   0000146600Y
S28963685A1K27GA0000FJB002000AFL   0000294700Y
S28963698A1K27GA0000FKS002000AFL   0001425700Y
S28963699X2K27G60000HN002000
S28963706A2K27G60000HPB002000CAG   0000097700Y
S28963734A3K27G60000HHB002000COH   0000153900Y